ERROR 2024-11-26 04:50:54,032 log Internal Server Error: /disposal/
Traceback (most recent call last):
  File "/home/pi/rasp/rfid/views_v2.py", line 40, in disposal
    uid = rfid_reader.tagging()
          ^^^^^^^^^^^^^^^^^^^^^
  File "/home/pi/rasp/rfid/rfid_reader.py", line 44, in tagging
    raise CustomException("태깅 시간 초과", status_code=404)
rfid.exceptions.CustomException: 태깅 시간 초과

During handling of the above exception, another exception occurred:

Traceback (most recent call last):
  File "/usr/local/lib/python3.11/dist-packages/django/core/handlers/exception.py", line 55, in inner
    response = get_response(request)
               ^^^^^^^^^^^^^^^^^^^^^
  File "/usr/local/lib/python3.11/dist-packages/django/core/handlers/base.py", line 197, in _get_response
    response = wrapped_callback(request, *callback_args, **callback_kwargs)
               ^^^^^^^^^^^^^^^^^^^^^^^^^^^^^^^^^^^^^^^^^^^^^^^^^^^^^^^^^^^^
  File "/home/pi/rasp/rfid/views_v2.py", line 54, in disposal
    raise CustomException("태깅 중 오류 발생", status_code=500)
rfid.exceptions.CustomException: 태깅 중 오류 발생
ERROR 2024-11-26 04:50:54,035 basehttp "POST /disposal/ HTTP/1.1" 500 1860
ERROR 2024-11-26 04:50:54,060 log Internal Server Error: /favicon.ico
ERROR 2024-11-26 04:50:54,061 basehttp "GET /favicon.ico HTTP/1.1" 500 1860
ERROR 2024-11-26 04:51:13,942 log Internal Server Error: /favicon.ico
ERROR 2024-11-26 04:51:13,943 basehttp "GET /favicon.ico HTTP/1.1" 500 1860
ERROR 2024-11-26 05:05:34,557 log Internal Server Error: /disposal/
Traceback (most recent call last):
  File "/home/pi/rasp/rfid/views_v2.py", line 40, in disposal
    uid = rfid_reader.tagging()
          ^^^^^^^^^^^^^^^^^^^^^
  File "/home/pi/rasp/rfid/rfid_reader.py", line 44, in tagging
    raise CustomException("태깅 시간 초과", status_code=404)
rfid.exceptions.CustomException: 태깅 시간 초과

During handling of the above exception, another exception occurred:

Traceback (most recent call last):
  File "/usr/local/lib/python3.11/dist-packages/django/core/handlers/exception.py", line 55, in inner
    response = get_response(request)
               ^^^^^^^^^^^^^^^^^^^^^
  File "/usr/local/lib/python3.11/dist-packages/django/core/handlers/base.py", line 197, in _get_response
    response = wrapped_callback(request, *callback_args, **callback_kwargs)
               ^^^^^^^^^^^^^^^^^^^^^^^^^^^^^^^^^^^^^^^^^^^^^^^^^^^^^^^^^^^^
  File "/home/pi/rasp/rfid/views_v2.py", line 54, in disposal
    raise CustomException("태깅 중 오류 발생", status_code=500)
rfid.exceptions.CustomException: 태깅 중 오류 발생
ERROR 2024-11-26 05:05:34,558 basehttp "POST /disposal/ HTTP/1.1" 500 1860
ERROR 2024-11-26 05:05:34,581 log Internal Server Error: /favicon.ico
ERROR 2024-11-26 05:05:34,581 basehttp "GET /favicon.ico HTTP/1.1" 500 1860
ERROR 2024-11-26 05:05:38,185 log Internal Server Error: /favicon.ico
ERROR 2024-11-26 05:05:38,186 basehttp "GET /favicon.ico HTTP/1.1" 500 1860
ERROR 2024-11-26 05:05:48,951 log Internal Server Error: /disposal/
Traceback (most recent call last):
  File "/home/pi/rasp/rfid/views_v2.py", line 40, in disposal
    uid = rfid_reader.tagging()
          ^^^^^^^^^^^^^^^^^^^^^
  File "/home/pi/rasp/rfid/rfid_reader.py", line 44, in tagging
    raise CustomException("태깅 시간 초과", status_code=404)
rfid.exceptions.CustomException: 태깅 시간 초과

During handling of the above exception, another exception occurred:

Traceback (most recent call last):
  File "/usr/local/lib/python3.11/dist-packages/django/core/handlers/exception.py", line 55, in inner
    response = get_response(request)
               ^^^^^^^^^^^^^^^^^^^^^
  File "/usr/local/lib/python3.11/dist-packages/django/core/handlers/base.py", line 197, in _get_response
    response = wrapped_callback(request, *callback_args, **callback_kwargs)
               ^^^^^^^^^^^^^^^^^^^^^^^^^^^^^^^^^^^^^^^^^^^^^^^^^^^^^^^^^^^^
  File "/home/pi/rasp/rfid/views_v2.py", line 54, in disposal
    raise CustomException("태깅 중 오류 발생", status_code=500)
rfid.exceptions.CustomException: 태깅 중 오류 발생
ERROR 2024-11-26 05:05:48,954 basehttp "POST /disposal/ HTTP/1.1" 500 1860
ERROR 2024-11-26 05:05:48,975 log Internal Server Error: /favicon.ico
ERROR 2024-11-26 05:05:48,975 basehttp "GET /favicon.ico HTTP/1.1" 500 1860
ERROR 2024-11-26 05:05:53,138 log Internal Server Error: /favicon.ico
ERROR 2024-11-26 05:05:53,138 basehttp "GET /favicon.ico HTTP/1.1" 500 1860
ERROR 2024-11-26 05:06:03,785 log Internal Server Error: /disposal/
Traceback (most recent call last):
  File "/home/pi/rasp/rfid/views_v2.py", line 40, in disposal
    uid = rfid_reader.tagging()
          ^^^^^^^^^^^^^^^^^^^^^
  File "/home/pi/rasp/rfid/rfid_reader.py", line 44, in tagging
    raise CustomException("태깅 시간 초과", status_code=404)
rfid.exceptions.CustomException: 태깅 시간 초과

During handling of the above exception, another exception occurred:

Traceback (most recent call last):
  File "/usr/local/lib/python3.11/dist-packages/django/core/handlers/exception.py", line 55, in inner
    response = get_response(request)
               ^^^^^^^^^^^^^^^^^^^^^
  File "/usr/local/lib/python3.11/dist-packages/django/core/handlers/base.py", line 197, in _get_response
    response = wrapped_callback(request, *callback_args, **callback_kwargs)
               ^^^^^^^^^^^^^^^^^^^^^^^^^^^^^^^^^^^^^^^^^^^^^^^^^^^^^^^^^^^^
  File "/home/pi/rasp/rfid/views_v2.py", line 54, in disposal
    raise CustomException("태깅 중 오류 발생", status_code=500)
rfid.exceptions.CustomException: 태깅 중 오류 발생
ERROR 2024-11-26 05:06:03,786 basehttp "POST /disposal/ HTTP/1.1" 500 1860
ERROR 2024-11-26 05:06:03,811 log Internal Server Error: /favicon.ico
ERROR 2024-11-26 05:06:03,812 basehttp "GET /favicon.ico HTTP/1.1" 500 1860
ERROR 2024-11-26 05:06:48,334 log Internal Server Error: /favicon.ico
ERROR 2024-11-26 05:06:48,334 basehttp "GET /favicon.ico HTTP/1.1" 500 1860
ERROR 2024-11-26 05:06:59,025 log Internal Server Error: /disposal/
Traceback (most recent call last):
  File "/home/pi/rasp/rfid/views_v2.py", line 40, in disposal
    uid = rfid_reader.tagging()
          ^^^^^^^^^^^^^^^^^^^^^
  File "/home/pi/rasp/rfid/rfid_reader.py", line 44, in tagging
    raise CustomException("태깅 시간 초과", status_code=404)
rfid.exceptions.CustomException: 태깅 시간 초과

During handling of the above exception, another exception occurred:

Traceback (most recent call last):
  File "/usr/local/lib/python3.11/dist-packages/django/core/handlers/exception.py", line 55, in inner
    response = get_response(request)
               ^^^^^^^^^^^^^^^^^^^^^
  File "/usr/local/lib/python3.11/dist-packages/django/core/handlers/base.py", line 197, in _get_response
    response = wrapped_callback(request, *callback_args, **callback_kwargs)
               ^^^^^^^^^^^^^^^^^^^^^^^^^^^^^^^^^^^^^^^^^^^^^^^^^^^^^^^^^^^^
  File "/home/pi/rasp/rfid/views_v2.py", line 54, in disposal
    raise CustomException("태깅 중 오류 발생", status_code=500)
rfid.exceptions.CustomException: 태깅 중 오류 발생
ERROR 2024-11-26 05:06:59,026 basehttp "POST /disposal/ HTTP/1.1" 500 1860
ERROR 2024-11-26 05:06:59,052 log Internal Server Error: /favicon.ico
ERROR 2024-11-26 05:06:59,052 basehttp "GET /favicon.ico HTTP/1.1" 500 1860
ERROR 2024-11-26 05:07:11,223 log Internal Server Error: /favicon.ico
ERROR 2024-11-26 05:07:11,224 basehttp "GET /favicon.ico HTTP/1.1" 500 1860
ERROR 2024-11-26 05:07:22,968 log Internal Server Error: /disposal/
Traceback (most recent call last):
  File "/home/pi/rasp/rfid/views_v2.py", line 40, in disposal
    uid = rfid_reader.tagging()
          ^^^^^^^^^^^^^^^^^^^^^
  File "/home/pi/rasp/rfid/rfid_reader.py", line 44, in tagging
    raise CustomException("태깅 시간 초과", status_code=404)
rfid.exceptions.CustomException: 태깅 시간 초과

During handling of the above exception, another exception occurred:

Traceback (most recent call last):
  File "/usr/local/lib/python3.11/dist-packages/django/core/handlers/exception.py", line 55, in inner
    response = get_response(request)
               ^^^^^^^^^^^^^^^^^^^^^
  File "/usr/local/lib/python3.11/dist-packages/django/core/handlers/base.py", line 197, in _get_response
    response = wrapped_callback(request, *callback_args, **callback_kwargs)
               ^^^^^^^^^^^^^^^^^^^^^^^^^^^^^^^^^^^^^^^^^^^^^^^^^^^^^^^^^^^^
  File "/home/pi/rasp/rfid/views_v2.py", line 54, in disposal
    raise CustomException("태깅 중 오류 발생", status_code=500)
rfid.exceptions.CustomException: 태깅 중 오류 발생
ERROR 2024-11-26 05:07:22,969 basehttp "POST /disposal/ HTTP/1.1" 500 1860
ERROR 2024-11-26 05:07:22,991 log Internal Server Error: /favicon.ico
ERROR 2024-11-26 05:07:22,991 basehttp "GET /favicon.ico HTTP/1.1" 500 1860
ERROR 2024-11-26 05:07:40,821 log Internal Server Error: /favicon.ico
ERROR 2024-11-26 05:07:40,821 basehttp "GET /favicon.ico HTTP/1.1" 500 1860
ERROR 2024-11-26 05:08:47,824 log Internal Server Error: /disposal/
Traceback (most recent call last):
  File "/home/pi/rasp/rfid/views_v2.py", line 40, in disposal
    uid = rfid_reader.tagging()
          ^^^^^^^^^^^^^^^^^^^^^
  File "/home/pi/rasp/rfid/rfid_reader.py", line 44, in tagging
    raise CustomException("태깅 시간 초과", status_code=404)
rfid.exceptions.CustomException: 태깅 시간 초과

During handling of the above exception, another exception occurred:

Traceback (most recent call last):
  File "/usr/local/lib/python3.11/dist-packages/django/core/handlers/exception.py", line 55, in inner
    response = get_response(request)
               ^^^^^^^^^^^^^^^^^^^^^
  File "/usr/local/lib/python3.11/dist-packages/django/core/handlers/base.py", line 197, in _get_response
    response = wrapped_callback(request, *callback_args, **callback_kwargs)
               ^^^^^^^^^^^^^^^^^^^^^^^^^^^^^^^^^^^^^^^^^^^^^^^^^^^^^^^^^^^^
  File "/home/pi/rasp/rfid/views_v2.py", line 54, in disposal
    raise CustomException("태깅 중 오류 발생", status_code=500)
rfid.exceptions.CustomException: 태깅 중 오류 발생
ERROR 2024-11-26 05:08:47,825 basehttp "POST /disposal/ HTTP/1.1" 500 1860
ERROR 2024-11-26 05:08:47,845 log Internal Server Error: /favicon.ico
ERROR 2024-11-26 05:08:47,846 basehttp "GET /favicon.ico HTTP/1.1" 500 1860
ERROR 2024-11-26 05:09:20,320 log Internal Server Error: /favicon.ico
ERROR 2024-11-26 05:09:20,320 basehttp "GET /favicon.ico HTTP/1.1" 500 1860
ERROR 2024-11-26 05:16:28,387 log Internal Server Error: /favicon.ico
ERROR 2024-11-26 05:16:28,387 basehttp "GET /favicon.ico HTTP/1.1" 500 1860
ERROR 2024-11-26 05:16:29,405 log Internal Server Error: /disposal/
Traceback (most recent call last):
  File "/usr/local/lib/python3.11/dist-packages/django/core/handlers/exception.py", line 55, in inner
    response = get_response(request)
               ^^^^^^^^^^^^^^^^^^^^^
  File "/usr/local/lib/python3.11/dist-packages/django/core/handlers/base.py", line 204, in _get_response
    self.check_response(response, callback)
  File "/usr/local/lib/python3.11/dist-packages/django/core/handlers/base.py", line 332, in check_response
    raise ValueError(
ValueError: The view rfid.views_v2.disposal didn't return an HttpResponse object. It returned None instead.
ERROR 2024-11-26 05:16:29,407 basehttp "POST /disposal/ HTTP/1.1" 500 1860
ERROR 2024-11-26 05:16:29,428 log Internal Server Error: /favicon.ico
ERROR 2024-11-26 05:16:29,429 basehttp "GET /favicon.ico HTTP/1.1" 500 1860
ERROR 2024-11-26 05:16:30,294 log Internal Server Error: /favicon.ico
ERROR 2024-11-26 05:16:30,295 basehttp "GET /favicon.ico HTTP/1.1" 500 1860
ERROR 2024-11-26 05:16:31,156 log Internal Server Error: /disposal/
Traceback (most recent call last):
  File "/usr/local/lib/python3.11/dist-packages/django/core/handlers/exception.py", line 55, in inner
    response = get_response(request)
               ^^^^^^^^^^^^^^^^^^^^^
  File "/usr/local/lib/python3.11/dist-packages/django/core/handlers/base.py", line 204, in _get_response
    self.check_response(response, callback)
  File "/usr/local/lib/python3.11/dist-packages/django/core/handlers/base.py", line 332, in check_response
    raise ValueError(
ValueError: The view rfid.views_v2.disposal didn't return an HttpResponse object. It returned None instead.
ERROR 2024-11-26 05:16:31,157 basehttp "POST /disposal/ HTTP/1.1" 500 1860
ERROR 2024-11-26 05:16:31,178 log Internal Server Error: /favicon.ico
ERROR 2024-11-26 05:16:31,179 basehttp "GET /favicon.ico HTTP/1.1" 500 1860
ERROR 2024-11-26 05:16:31,931 log Internal Server Error: /favicon.ico
ERROR 2024-11-26 05:16:31,932 basehttp "GET /favicon.ico HTTP/1.1" 500 1860
ERROR 2024-11-26 05:16:53,052 log Internal Server Error: /disposal/
Traceback (most recent call last):
  File "/usr/local/lib/python3.11/dist-packages/django/core/handlers/exception.py", line 55, in inner
    response = get_response(request)
               ^^^^^^^^^^^^^^^^^^^^^
  File "/usr/local/lib/python3.11/dist-packages/django/core/handlers/base.py", line 204, in _get_response
    self.check_response(response, callback)
  File "/usr/local/lib/python3.11/dist-packages/django/core/handlers/base.py", line 332, in check_response
    raise ValueError(
ValueError: The view rfid.views_v2.disposal didn't return an HttpResponse object. It returned None instead.
ERROR 2024-11-26 05:16:53,053 basehttp "POST /disposal/ HTTP/1.1" 500 1860
ERROR 2024-11-26 05:16:53,076 log Internal Server Error: /favicon.ico
ERROR 2024-11-26 05:16:53,077 basehttp "GET /favicon.ico HTTP/1.1" 500 1860
ERROR 2024-11-26 05:16:55,315 log Internal Server Error: /favicon.ico
ERROR 2024-11-26 05:16:55,315 basehttp "GET /favicon.ico HTTP/1.1" 500 1860
ERROR 2024-11-26 05:17:06,416 log Internal Server Error: /disposal/
Traceback (most recent call last):
  File "/usr/local/lib/python3.11/dist-packages/django/core/handlers/exception.py", line 55, in inner
    response = get_response(request)
               ^^^^^^^^^^^^^^^^^^^^^
  File "/usr/local/lib/python3.11/dist-packages/django/core/handlers/base.py", line 197, in _get_response
    response = wrapped_callback(request, *callback_args, **callback_kwargs)
               ^^^^^^^^^^^^^^^^^^^^^^^^^^^^^^^^^^^^^^^^^^^^^^^^^^^^^^^^^^^^
  File "/home/pi/rasp/rfid/views_v2.py", line 50, in disposal
    raise e
  File "/home/pi/rasp/rfid/views_v2.py", line 41, in disposal
    uid = rfid_reader.tagging()
          ^^^^^^^^^^^^^^^^^^^^^
  File "/home/pi/rasp/rfid/rfid_reader.py", line 44, in tagging
    raise CustomException("태깅 시간 초과", status_code=404)
rfid.exceptions.CustomException: 태깅 시간 초과
ERROR 2024-11-26 05:17:06,417 basehttp "POST /disposal/ HTTP/1.1" 500 1860
ERROR 2024-11-26 05:17:06,683 log Internal Server Error: /favicon.ico
ERROR 2024-11-26 05:17:06,683 basehttp "GET /favicon.ico HTTP/1.1" 500 1860
ERROR 2024-11-26 05:17:08,614 log Internal Server Error: /favicon.ico
ERROR 2024-11-26 05:17:08,615 basehttp "GET /favicon.ico HTTP/1.1" 500 1860
ERROR 2024-11-26 05:17:11,939 log Internal Server Error: /disposal/
Traceback (most recent call last):
  File "/usr/local/lib/python3.11/dist-packages/django/core/handlers/exception.py", line 55, in inner
    response = get_response(request)
               ^^^^^^^^^^^^^^^^^^^^^
  File "/usr/local/lib/python3.11/dist-packages/django/core/handlers/base.py", line 204, in _get_response
    self.check_response(response, callback)
  File "/usr/local/lib/python3.11/dist-packages/django/core/handlers/base.py", line 332, in check_response
    raise ValueError(
ValueError: The view rfid.views_v2.disposal didn't return an HttpResponse object. It returned None instead.
ERROR 2024-11-26 05:17:11,940 basehttp "POST /disposal/ HTTP/1.1" 500 1860
ERROR 2024-11-26 05:17:11,964 log Internal Server Error: /favicon.ico
ERROR 2024-11-26 05:17:11,964 basehttp "GET /favicon.ico HTTP/1.1" 500 1860
ERROR 2024-11-26 05:17:13,965 log Internal Server Error: /favicon.ico
ERROR 2024-11-26 05:17:13,966 basehttp "GET /favicon.ico HTTP/1.1" 500 1860
ERROR 2024-11-26 05:19:35,033 log Internal Server Error: /favicon.ico
ERROR 2024-11-26 05:19:35,033 basehttp "GET /favicon.ico HTTP/1.1" 500 1860
ERROR 2024-11-26 05:19:37,281 log Internal Server Error: /favicon.ico
ERROR 2024-11-26 05:19:37,281 basehttp "GET /favicon.ico HTTP/1.1" 500 1860
ERROR 2024-11-26 05:19:38,042 log Internal Server Error: /favicon.ico
ERROR 2024-11-26 05:19:38,042 basehttp "GET /favicon.ico HTTP/1.1" 500 1860
ERROR 2024-11-26 05:21:47,685 log Internal Server Error: /favicon.ico
ERROR 2024-11-26 05:21:47,685 basehttp "GET /favicon.ico HTTP/1.1" 500 1860
ERROR 2024-11-26 05:21:50,499 log Internal Server Error: /result/
Traceback (most recent call last):
  File "/usr/local/lib/python3.11/dist-packages/django/core/handlers/exception.py", line 55, in inner
    response = get_response(request)
               ^^^^^^^^^^^^^^^^^^^^^
  File "/usr/local/lib/python3.11/dist-packages/django/core/handlers/base.py", line 197, in _get_response
    response = wrapped_callback(request, *callback_args, **callback_kwargs)
               ^^^^^^^^^^^^^^^^^^^^^^^^^^^^^^^^^^^^^^^^^^^^^^^^^^^^^^^^^^^^
  File "/home/pi/rasp/rfid/views_v2.py", line 86, in result
    raise e
  File "/home/pi/rasp/rfid/views_v2.py", line 75, in result
    raise CustomException("사용자 확인 실패", status_code=404)
rfid.exceptions.CustomException: 사용자 확인 실패
ERROR 2024-11-26 05:21:50,500 basehttp "GET /result/?uid=195883367363&name=%EC%9D%B4%EC%B0%BD%ED%99%98&company=HD%ED%98%84%EB%8C%80%EB%AF%B8%ED%8F%AC HTTP/1.1" 500 1860
ERROR 2024-11-26 05:21:50,523 log Internal Server Error: /favicon.ico
ERROR 2024-11-26 05:21:50,523 basehttp "GET /favicon.ico HTTP/1.1" 500 1860
ERROR 2024-11-26 05:21:51,413 log Internal Server Error: /favicon.ico
ERROR 2024-11-26 05:21:51,413 basehttp "GET /favicon.ico HTTP/1.1" 500 1860
ERROR 2024-11-26 05:27:34,765 log Internal Server Error: /disposal/
Traceback (most recent call last):
  File "/home/pi/rasp/rfid/views_v2.py", line 50, in disposal
    raise e
  File "/home/pi/rasp/rfid/views_v2.py", line 41, in disposal
    uid = rfid_reader.tagging()
          ^^^^^^^^^^^^^^^^^^^^^
  File "/home/pi/rasp/rfid/rfid_reader.py", line 44, in tagging
    raise CustomException("태깅 시간 초과", status_code=404)
rfid.exceptions.CustomException: 태깅 시간 초과

During handling of the above exception, another exception occurred:

Traceback (most recent call last):
  File "/usr/local/lib/python3.11/dist-packages/django/core/handlers/exception.py", line 55, in inner
    response = get_response(request)
               ^^^^^^^^^^^^^^^^^^^^^
  File "/usr/local/lib/python3.11/dist-packages/django/core/handlers/base.py", line 197, in _get_response
    response = wrapped_callback(request, *callback_args, **callback_kwargs)
               ^^^^^^^^^^^^^^^^^^^^^^^^^^^^^^^^^^^^^^^^^^^^^^^^^^^^^^^^^^^^
  File "/home/pi/rasp/rfid/views_v2.py", line 55, in disposal
    message = f"사용자 {user.name}이(가) 확인되었습니다."
                     ^^^^
UnboundLocalError: cannot access local variable 'user' where it is not associated with a value
ERROR 2024-11-26 05:27:34,767 basehttp "POST /disposal/ HTTP/1.1" 500 131
ERROR 2024-11-26 05:27:34,800 log Internal Server Error: /favicon.ico
ERROR 2024-11-26 05:27:34,800 basehttp "GET /favicon.ico HTTP/1.1" 500 131
ERROR 2024-11-26 05:27:45,503 log Internal Server Error: /favicon.ico
ERROR 2024-11-26 05:27:45,503 basehttp "GET /favicon.ico HTTP/1.1" 500 131
ERROR 2024-11-26 05:28:58,185 log Internal Server Error: /favicon.ico
ERROR 2024-11-26 05:28:58,185 basehttp "GET /favicon.ico HTTP/1.1" 500 131
ERROR 2024-11-26 05:29:09,224 log Internal Server Error: /disposal/
Traceback (most recent call last):
  File "/home/pi/rasp/rfid/views_v2.py", line 50, in disposal
    raise e
  File "/home/pi/rasp/rfid/views_v2.py", line 41, in disposal
    uid = rfid_reader.tagging()
          ^^^^^^^^^^^^^^^^^^^^^
  File "/home/pi/rasp/rfid/rfid_reader.py", line 44, in tagging
    raise CustomException("태깅 시간 초과", status_code=404)
rfid.exceptions.CustomException: 태깅 시간 초과

During handling of the above exception, another exception occurred:

Traceback (most recent call last):
  File "/usr/local/lib/python3.11/dist-packages/django/core/handlers/exception.py", line 55, in inner
    response = get_response(request)
               ^^^^^^^^^^^^^^^^^^^^^
  File "/usr/local/lib/python3.11/dist-packages/django/core/handlers/base.py", line 197, in _get_response
    response = wrapped_callback(request, *callback_args, **callback_kwargs)
               ^^^^^^^^^^^^^^^^^^^^^^^^^^^^^^^^^^^^^^^^^^^^^^^^^^^^^^^^^^^^
  File "/home/pi/rasp/rfid/views_v2.py", line 55, in disposal
    message = f"사용자 {user.name}이(가) 확인되었습니다."
                     ^^^^
UnboundLocalError: cannot access local variable 'user' where it is not associated with a value
ERROR 2024-11-26 05:29:09,225 basehttp "POST /disposal/ HTTP/1.1" 500 131
ERROR 2024-11-26 05:29:09,261 log Internal Server Error: /favicon.ico
ERROR 2024-11-26 05:29:09,261 basehttp "GET /favicon.ico HTTP/1.1" 500 131
ERROR 2024-11-26 05:29:13,246 log Internal Server Error: /favicon.ico
ERROR 2024-11-26 05:29:13,247 basehttp "GET /favicon.ico HTTP/1.1" 500 131
ERROR 2024-11-26 05:29:39,607 log Internal Server Error: /favicon.ico
ERROR 2024-11-26 05:29:39,608 basehttp "GET /favicon.ico HTTP/1.1" 500 131
ERROR 2024-11-26 05:29:51,099 log Internal Server Error: /disposal/
Traceback (most recent call last):
  File "/home/pi/rasp/rfid/views_v2.py", line 50, in disposal
    raise e
  File "/home/pi/rasp/rfid/views_v2.py", line 41, in disposal
    uid = rfid_reader.tagging()
          ^^^^^^^^^^^^^^^^^^^^^
  File "/home/pi/rasp/rfid/rfid_reader.py", line 44, in tagging
    raise CustomException("태깅 시간 초과", status_code=404)
rfid.exceptions.CustomException: 태깅 시간 초과

During handling of the above exception, another exception occurred:

Traceback (most recent call last):
  File "/usr/local/lib/python3.11/dist-packages/django/core/handlers/exception.py", line 55, in inner
    response = get_response(request)
               ^^^^^^^^^^^^^^^^^^^^^
  File "/usr/local/lib/python3.11/dist-packages/django/core/handlers/base.py", line 197, in _get_response
    response = wrapped_callback(request, *callback_args, **callback_kwargs)
               ^^^^^^^^^^^^^^^^^^^^^^^^^^^^^^^^^^^^^^^^^^^^^^^^^^^^^^^^^^^^
  File "/home/pi/rasp/rfid/views_v2.py", line 55, in disposal
    message = f"사용자 {user.name}이(가) 확인되었습니다."
                     ^^^^
UnboundLocalError: cannot access local variable 'user' where it is not associated with a value
ERROR 2024-11-26 05:29:51,100 basehttp "POST /disposal/ HTTP/1.1" 500 131
ERROR 2024-11-26 05:29:51,136 log Internal Server Error: /favicon.ico
ERROR 2024-11-26 05:29:51,136 basehttp "GET /favicon.ico HTTP/1.1" 500 131
ERROR 2024-11-26 05:30:20,044 log Internal Server Error: /favicon.ico
ERROR 2024-11-26 05:30:20,044 basehttp "GET /favicon.ico HTTP/1.1" 500 131
ERROR 2024-11-26 05:30:24,673 log Internal Server Error: /favicon.ico
ERROR 2024-11-26 05:30:24,673 basehttp "GET /favicon.ico HTTP/1.1" 500 131
ERROR 2024-11-26 05:33:12,143 log Internal Server Error: /result/
Traceback (most recent call last):
  File "/usr/local/lib/python3.11/dist-packages/django/core/handlers/exception.py", line 55, in inner
    response = get_response(request)
               ^^^^^^^^^^^^^^^^^^^^^
  File "/usr/local/lib/python3.11/dist-packages/django/core/handlers/base.py", line 197, in _get_response
    response = wrapped_callback(request, *callback_args, **callback_kwargs)
               ^^^^^^^^^^^^^^^^^^^^^^^^^^^^^^^^^^^^^^^^^^^^^^^^^^^^^^^^^^^^
  File "/home/pi/rasp/rfid/views_v2.py", line 86, in result
    raise e
  File "/home/pi/rasp/rfid/views_v2.py", line 75, in result
    raise CustomException("사용자 확인 실패", status_code=404)
rfid.exceptions.CustomException: 사용자 확인 실패
ERROR 2024-11-26 05:33:12,145 basehttp "GET /result/?uid=596393001371&name=%ED%85%8C%EC%8A%A4%ED%8A%B8%EC%9C%A0%EC%A0%80&company=HD%ED%98%84%EB%8C%80%EB%AF%B8%ED%8F%AC HTTP/1.1" 500 131
ERROR 2024-11-26 05:33:12,182 log Internal Server Error: /favicon.ico
ERROR 2024-11-26 05:33:12,183 basehttp "GET /favicon.ico HTTP/1.1" 500 131
ERROR 2024-11-26 05:33:18,963 log Internal Server Error: /favicon.ico
ERROR 2024-11-26 05:33:18,963 basehttp "GET /favicon.ico HTTP/1.1" 500 131
ERROR 2024-11-26 05:33:22,485 log Internal Server Error: /favicon.ico
ERROR 2024-11-26 05:33:22,485 basehttp "GET /favicon.ico HTTP/1.1" 500 131
ERROR 2024-11-26 05:33:23,516 log Internal Server Error: /favicon.ico
ERROR 2024-11-26 05:33:23,517 basehttp "GET /favicon.ico HTTP/1.1" 500 131
ERROR 2024-11-26 05:33:24,204 log Internal Server Error: /favicon.ico
ERROR 2024-11-26 05:33:24,205 basehttp "GET /favicon.ico HTTP/1.1" 500 131
ERROR 2024-11-26 05:42:04,703 log Internal Server Error: /disposal/
Traceback (most recent call last):
  File "/home/pi/rasp/rfid/views_v2.py", line 51, in disposal
    raise e
  File "/home/pi/rasp/rfid/views_v2.py", line 42, in disposal
    uid = rfid_reader.tagging()
          ^^^^^^^^^^^^^^^^^^^^^
  File "/home/pi/rasp/rfid/rfid_reader.py", line 44, in tagging
    raise CustomException("태깅 시간 초과", status_code=404)
rfid.exceptions.CustomException: 태깅 시간 초과

During handling of the above exception, another exception occurred:

Traceback (most recent call last):
  File "/usr/local/lib/python3.11/dist-packages/django/core/handlers/exception.py", line 55, in inner
    response = get_response(request)
               ^^^^^^^^^^^^^^^^^^^^^
  File "/usr/local/lib/python3.11/dist-packages/django/core/handlers/base.py", line 197, in _get_response
    response = wrapped_callback(request, *callback_args, **callback_kwargs)
               ^^^^^^^^^^^^^^^^^^^^^^^^^^^^^^^^^^^^^^^^^^^^^^^^^^^^^^^^^^^^
  File "/home/pi/rasp/rfid/views_v2.py", line 56, in disposal
    message = f"사용자 {user.name}이(가) 확인되었습니다."
                     ^^^^
UnboundLocalError: cannot access local variable 'user' where it is not associated with a value
ERROR 2024-11-26 05:42:04,705 basehttp "POST /disposal/ HTTP/1.1" 500 1860
ERROR 2024-11-26 05:42:04,729 log Internal Server Error: /favicon.ico
ERROR 2024-11-26 05:42:04,729 basehttp "GET /favicon.ico HTTP/1.1" 500 1860
ERROR 2024-11-26 05:42:06,412 log Internal Server Error: /favicon.ico
ERROR 2024-11-26 05:42:06,412 basehttp "GET /favicon.ico HTTP/1.1" 500 1860
ERROR 2024-11-26 05:42:13,112 log Internal Server Error: /favicon.ico
ERROR 2024-11-26 05:42:13,112 basehttp "GET /favicon.ico HTTP/1.1" 500 1860
ERROR 2024-11-26 05:42:17,031 log Internal Server Error: /result/
Traceback (most recent call last):
  File "/usr/local/lib/python3.11/dist-packages/django/core/handlers/exception.py", line 55, in inner
    response = get_response(request)
               ^^^^^^^^^^^^^^^^^^^^^
  File "/usr/local/lib/python3.11/dist-packages/django/core/handlers/base.py", line 197, in _get_response
    response = wrapped_callback(request, *callback_args, **callback_kwargs)
               ^^^^^^^^^^^^^^^^^^^^^^^^^^^^^^^^^^^^^^^^^^^^^^^^^^^^^^^^^^^^
  File "/home/pi/rasp/rfid/views_v2.py", line 87, in result
    raise e
  File "/home/pi/rasp/rfid/views_v2.py", line 76, in result
    raise CustomException("사용자 확인 실패", status_code=404)
rfid.exceptions.CustomException: 사용자 확인 실패
ERROR 2024-11-26 05:42:17,032 basehttp "GET /result/?uid=195883367363&name=%EC%9D%B4%EC%B0%BD%ED%99%98&company=HD%ED%98%84%EB%8C%80%EB%AF%B8%ED%8F%AC HTTP/1.1" 500 1860
ERROR 2024-11-26 05:42:17,054 log Internal Server Error: /favicon.ico
ERROR 2024-11-26 05:42:17,054 basehttp "GET /favicon.ico HTTP/1.1" 500 1860
ERROR 2024-11-26 05:42:19,012 log Internal Server Error: /favicon.ico
ERROR 2024-11-26 05:42:19,012 basehttp "GET /favicon.ico HTTP/1.1" 500 1860
ERROR 2024-11-26 05:46:10,371 log Internal Server Error: /disposal/
Traceback (most recent call last):
  File "/home/pi/rasp/rfid/views_v2.py", line 51, in disposal
    raise e
  File "/home/pi/rasp/rfid/views_v2.py", line 42, in disposal
    uid = rfid_reader.tagging()
          ^^^^^^^^^^^^^^^^^^^^^
  File "/home/pi/rasp/rfid/rfid_reader.py", line 44, in tagging
    raise CustomException("태깅 시간 초과", status_code=404)
rfid.exceptions.CustomException: 태깅 시간 초과

During handling of the above exception, another exception occurred:

Traceback (most recent call last):
  File "/usr/local/lib/python3.11/dist-packages/django/core/handlers/exception.py", line 55, in inner
    response = get_response(request)
               ^^^^^^^^^^^^^^^^^^^^^
  File "/usr/local/lib/python3.11/dist-packages/django/core/handlers/base.py", line 197, in _get_response
    response = wrapped_callback(request, *callback_args, **callback_kwargs)
               ^^^^^^^^^^^^^^^^^^^^^^^^^^^^^^^^^^^^^^^^^^^^^^^^^^^^^^^^^^^^
  File "/home/pi/rasp/rfid/views_v2.py", line 56, in disposal
    message = f"사용자 {user.name}이(가) 확인되었습니다."
                     ^^^^
UnboundLocalError: cannot access local variable 'user' where it is not associated with a value
ERROR 2024-11-26 05:46:10,373 basehttp "POST /disposal/ HTTP/1.1" 500 1860
ERROR 2024-11-26 05:46:10,399 log Internal Server Error: /favicon.ico
ERROR 2024-11-26 05:46:10,400 basehttp "GET /favicon.ico HTTP/1.1" 500 1860
ERROR 2024-11-26 05:46:11,330 log Internal Server Error: /favicon.ico
ERROR 2024-11-26 05:46:11,330 basehttp "GET /favicon.ico HTTP/1.1" 500 1860
ERROR 2024-11-26 05:49:02,143 log Internal Server Error: /disposal/
Traceback (most recent call last):
  File "/home/pi/rasp/rfid/views_v2.py", line 51, in disposal
    raise e
  File "/home/pi/rasp/rfid/views_v2.py", line 42, in disposal
    uid = rfid_reader.tagging()
          ^^^^^^^^^^^^^^^^^^^^^
  File "/home/pi/rasp/rfid/rfid_reader.py", line 44, in tagging
    raise CustomException("태깅 시간 초과", status_code=404)
rfid.exceptions.CustomException: 태깅 시간 초과

During handling of the above exception, another exception occurred:

Traceback (most recent call last):
  File "/usr/local/lib/python3.11/dist-packages/django/core/handlers/exception.py", line 55, in inner
    response = get_response(request)
               ^^^^^^^^^^^^^^^^^^^^^
  File "/usr/local/lib/python3.11/dist-packages/django/core/handlers/base.py", line 197, in _get_response
    response = wrapped_callback(request, *callback_args, **callback_kwargs)
               ^^^^^^^^^^^^^^^^^^^^^^^^^^^^^^^^^^^^^^^^^^^^^^^^^^^^^^^^^^^^
  File "/home/pi/rasp/rfid/views_v2.py", line 56, in disposal
    message = f"사용자 {user.name}이(가) 확인되었습니다."
                     ^^^^
UnboundLocalError: cannot access local variable 'user' where it is not associated with a value
ERROR 2024-11-26 05:49:02,145 basehttp "POST /disposal/ HTTP/1.1" 500 1860
ERROR 2024-11-26 05:49:02,435 log Internal Server Error: /favicon.ico
ERROR 2024-11-26 05:49:02,436 basehttp "GET /favicon.ico HTTP/1.1" 500 1860
ERROR 2024-11-26 05:49:03,677 log Internal Server Error: /favicon.ico
ERROR 2024-11-26 05:49:03,677 basehttp "GET /favicon.ico HTTP/1.1" 500 1860
ERROR 2024-11-26 07:45:04,253 exception Invalid HTTP_HOST header: '10.150.8.165:8000'. You may need to add '10.150.8.165' to ALLOWED_HOSTS.
Traceback (most recent call last):
  File "/usr/local/lib/python3.11/dist-packages/django/core/handlers/exception.py", line 55, in inner
    response = get_response(request)
               ^^^^^^^^^^^^^^^^^^^^^
  File "/usr/local/lib/python3.11/dist-packages/django/utils/deprecation.py", line 128, in __call__
    response = self.process_request(request)
               ^^^^^^^^^^^^^^^^^^^^^^^^^^^^^
  File "/usr/local/lib/python3.11/dist-packages/django/middleware/common.py", line 48, in process_request
    host = request.get_host()
           ^^^^^^^^^^^^^^^^^^
  File "/usr/local/lib/python3.11/dist-packages/django/http/request.py", line 151, in get_host
    raise DisallowedHost(msg)
django.core.exceptions.DisallowedHost: Invalid HTTP_HOST header: '10.150.8.165:8000'. You may need to add '10.150.8.165' to ALLOWED_HOSTS.
ERROR 2024-11-26 07:50:52,255 exception Invalid HTTP_HOST header: '10.150.8.165:8000'. You may need to add '10.150.8.165' to ALLOWED_HOSTS.
Traceback (most recent call last):
  File "/usr/local/lib/python3.11/dist-packages/django/core/handlers/exception.py", line 55, in inner
    response = get_response(request)
               ^^^^^^^^^^^^^^^^^^^^^
  File "/usr/local/lib/python3.11/dist-packages/django/utils/deprecation.py", line 128, in __call__
    response = self.process_request(request)
               ^^^^^^^^^^^^^^^^^^^^^^^^^^^^^
  File "/usr/local/lib/python3.11/dist-packages/django/middleware/common.py", line 48, in process_request
    host = request.get_host()
           ^^^^^^^^^^^^^^^^^^
  File "/usr/local/lib/python3.11/dist-packages/django/http/request.py", line 151, in get_host
    raise DisallowedHost(msg)
django.core.exceptions.DisallowedHost: Invalid HTTP_HOST header: '10.150.8.165:8000'. You may need to add '10.150.8.165' to ALLOWED_HOSTS.
ERROR 2024-11-26 07:50:56,326 exception Invalid HTTP_HOST header: '10.150.8.165:8000'. You may need to add '10.150.8.165' to ALLOWED_HOSTS.
Traceback (most recent call last):
  File "/usr/local/lib/python3.11/dist-packages/django/core/handlers/exception.py", line 55, in inner
    response = get_response(request)
               ^^^^^^^^^^^^^^^^^^^^^
  File "/usr/local/lib/python3.11/dist-packages/django/utils/deprecation.py", line 128, in __call__
    response = self.process_request(request)
               ^^^^^^^^^^^^^^^^^^^^^^^^^^^^^
  File "/usr/local/lib/python3.11/dist-packages/django/middleware/common.py", line 48, in process_request
    host = request.get_host()
           ^^^^^^^^^^^^^^^^^^
  File "/usr/local/lib/python3.11/dist-packages/django/http/request.py", line 151, in get_host
    raise DisallowedHost(msg)
django.core.exceptions.DisallowedHost: Invalid HTTP_HOST header: '10.150.8.165:8000'. You may need to add '10.150.8.165' to ALLOWED_HOSTS.
ERROR 2024-11-26 22:42:16,163 log Internal Server Error: /disposal/
Traceback (most recent call last):
  File "/home/pi/rasp/rfid/views_v2.py", line 34, in wrapper
    return func(request, *args, **kwargs)
           ^^^^^^^^^^^^^^^^^^^^^^^^^^^^^^
  File "/home/pi/rasp/rfid/views_v2.py", line 66, in disposal
    uid = rfid_reader.tagging()
          ^^^^^^^^^^^^^^^^^^^^^
  File "/home/pi/rasp/rfid/rfid_reader.py", line 44, in tagging
    raise CustomException("태깅 시간 초과", status_code=404)
rfid.exceptions.CustomException: 태깅 시간 초과

During handling of the above exception, another exception occurred:

Traceback (most recent call last):
  File "/usr/local/lib/python3.11/dist-packages/django/core/handlers/exception.py", line 55, in inner
    response = get_response(request)
               ^^^^^^^^^^^^^^^^^^^^^
  File "/usr/local/lib/python3.11/dist-packages/django/core/handlers/base.py", line 197, in _get_response
    response = wrapped_callback(request, *callback_args, **callback_kwargs)
               ^^^^^^^^^^^^^^^^^^^^^^^^^^^^^^^^^^^^^^^^^^^^^^^^^^^^^^^^^^^^
  File "/home/pi/rasp/rfid/views_v2.py", line 38, in wrapper
    return render(request, 'errors/error.html', {
           ^^^^^^^^^^^^^^^^^^^^^^^^^^^^^^^^^^^^^^
  File "/usr/local/lib/python3.11/dist-packages/django/shortcuts.py", line 25, in render
    content = loader.render_to_string(template_name, context, request, using=using)
              ^^^^^^^^^^^^^^^^^^^^^^^^^^^^^^^^^^^^^^^^^^^^^^^^^^^^^^^^^^^^^^^^^^^^^
  File "/usr/local/lib/python3.11/dist-packages/django/template/loader.py", line 61, in render_to_string
    template = get_template(template_name, using=using)
               ^^^^^^^^^^^^^^^^^^^^^^^^^^^^^^^^^^^^^^^^
  File "/usr/local/lib/python3.11/dist-packages/django/template/loader.py", line 19, in get_template
    raise TemplateDoesNotExist(template_name, chain=chain)
django.template.exceptions.TemplateDoesNotExist: errors/error.html
ERROR 2024-11-26 22:42:16,167 basehttp "POST /disposal/ HTTP/1.1" 500 145
ERROR 2024-11-26 22:56:45,105 log Internal Server Error: /result/
Traceback (most recent call last):
  File "/home/pi/rasp/rfid/views_v2.py", line 34, in wrapper
    return func(request, *args, **kwargs)
           ^^^^^^^^^^^^^^^^^^^^^^^^^^^^^^
  File "/home/pi/rasp/rfid/views_v2.py", line 91, in result
    raise CustomException("열림 시에 이용한 카드와 동일한 카드를 대주세요", status_code=777)
rfid.exceptions.CustomException: 열림 시에 이용한 카드와 동일한 카드를 대주세요

During handling of the above exception, another exception occurred:

Traceback (most recent call last):
  File "/usr/local/lib/python3.11/dist-packages/django/core/handlers/exception.py", line 55, in inner
    response = get_response(request)
               ^^^^^^^^^^^^^^^^^^^^^
  File "/usr/local/lib/python3.11/dist-packages/django/core/handlers/base.py", line 197, in _get_response
    response = wrapped_callback(request, *callback_args, **callback_kwargs)
               ^^^^^^^^^^^^^^^^^^^^^^^^^^^^^^^^^^^^^^^^^^^^^^^^^^^^^^^^^^^^
  File "/home/pi/rasp/rfid/views_v2.py", line 38, in wrapper
    return render(request, 'error.html', {
           ^^^^^^^^^^^^^^^^^^^^^^^^^^^^^^^
  File "/usr/local/lib/python3.11/dist-packages/django/shortcuts.py", line 26, in render
    return HttpResponse(content, content_type, status)
           ^^^^^^^^^^^^^^^^^^^^^^^^^^^^^^^^^^^^^^^^^^^
  File "/usr/local/lib/python3.11/dist-packages/django/http/response.py", line 374, in __init__
    super().__init__(*args, **kwargs)
  File "/usr/local/lib/python3.11/dist-packages/django/http/response.py", line 139, in __init__
    raise ValueError("HTTP status code must be an integer from 100 to 599.")
ValueError: HTTP status code must be an integer from 100 to 599.
ERROR 2024-11-26 22:56:45,150 basehttp "GET /result/?uid=195883367363&name=%EC%9D%B4%EC%B0%BD%ED%99%98&company=HD%ED%98%84%EB%8C%80%EB%AF%B8%ED%8F%AC HTTP/1.1" 500 145
ERROR 2024-11-26 22:57:21,883 log Unknown Status Code: /result/
ERROR 2024-11-26 22:57:21,884 basehttp "GET /result/?uid=195883367363&name=%EC%9D%B4%EC%B0%BD%ED%99%98&company=HD%ED%98%84%EB%8C%80%EB%AF%B8%ED%8F%AC HTTP/1.1" 555 1875
ERROR 2024-11-26 23:45:01,155 log Internal Server Error: /user_add/
Traceback (most recent call last):
  File "/usr/local/lib/python3.11/dist-packages/django/core/handlers/exception.py", line 55, in inner
    response = get_response(request)
               ^^^^^^^^^^^^^^^^^^^^^
  File "/usr/local/lib/python3.11/dist-packages/django/core/handlers/base.py", line 197, in _get_response
    response = wrapped_callback(request, *callback_args, **callback_kwargs)
               ^^^^^^^^^^^^^^^^^^^^^^^^^^^^^^^^^^^^^^^^^^^^^^^^^^^^^^^^^^^^
  File "/home/pi/rasp/rfid/user_management.py", line 39, in add_user
    raise CustomException("이미 등록된 사용자입니다.", status_code=409)
rfid.exceptions.CustomException: 이미 등록된 사용자입니다.
ERROR 2024-11-26 23:45:01,156 basehttp "POST /user_add/ HTTP/1.1" 500 145
ERROR 2024-11-27 00:01:31,882 log Internal Server Error: /disposal/
ERROR 2024-11-27 00:01:31,883 basehttp "POST /disposal/ HTTP/1.1" 500 1852
ERROR 2024-11-27 00:01:33,585 log Internal Server Error: /disposal/
ERROR 2024-11-27 00:01:33,585 basehttp "POST /disposal/ HTTP/1.1" 500 1852
ERROR 2024-11-27 00:01:53,933 log Internal Server Error: /disposal/
ERROR 2024-11-27 00:01:53,934 basehttp "POST /disposal/ HTTP/1.1" 500 1852
ERROR 2024-11-27 00:02:13,279 log Internal Server Error: /disposal/
ERROR 2024-11-27 00:02:13,279 basehttp "POST /disposal/ HTTP/1.1" 500 1852
ERROR 2024-11-27 00:02:55,441 log Internal Server Error: /disposal/
Traceback (most recent call last):
  File "/home/pi/rasp/rfid/views_v2.py", line 34, in wrapper
    return func(request, *args, **kwargs)
           ^^^^^^^^^^^^^^^^^^^^^^^^^^^^^^
  File "/home/pi/rasp/rfid/views_v2.py", line 65, in disposal
    uid = rfid_reader.tagging()
          ^^^^^^^^^^^^^^^^^^^^^
TypeError: handle_exception.<locals>.wrapper() missing 1 required positional argument: 'request'

During handling of the above exception, another exception occurred:

Traceback (most recent call last):
  File "/usr/local/lib/python3.11/dist-packages/django/core/handlers/exception.py", line 55, in inner
    response = get_response(request)
               ^^^^^^^^^^^^^^^^^^^^^
  File "/usr/local/lib/python3.11/dist-packages/django/core/handlers/base.py", line 197, in _get_response
    response = wrapped_callback(request, *callback_args, **callback_kwargs)
               ^^^^^^^^^^^^^^^^^^^^^^^^^^^^^^^^^^^^^^^^^^^^^^^^^^^^^^^^^^^^
  File "/home/pi/rasp/rfid/views_v2.py", line 45, in wrapper
    return render(request, 'errors/error.html', {
           ^^^^^^^^^^^^^^^^^^^^^^^^^^^^^^^^^^^^^^
  File "/usr/local/lib/python3.11/dist-packages/django/shortcuts.py", line 25, in render
    content = loader.render_to_string(template_name, context, request, using=using)
              ^^^^^^^^^^^^^^^^^^^^^^^^^^^^^^^^^^^^^^^^^^^^^^^^^^^^^^^^^^^^^^^^^^^^^
  File "/usr/local/lib/python3.11/dist-packages/django/template/loader.py", line 61, in render_to_string
    template = get_template(template_name, using=using)
               ^^^^^^^^^^^^^^^^^^^^^^^^^^^^^^^^^^^^^^^^
  File "/usr/local/lib/python3.11/dist-packages/django/template/loader.py", line 19, in get_template
    raise TemplateDoesNotExist(template_name, chain=chain)
django.template.exceptions.TemplateDoesNotExist: errors/error.html
ERROR 2024-11-27 00:02:55,442 basehttp "POST /disposal/ HTTP/1.1" 500 145
ERROR 2024-11-27 00:03:09,708 log Internal Server Error: /disposal/
ERROR 2024-11-27 00:03:09,708 basehttp "POST /disposal/ HTTP/1.1" 500 1852
ERROR 2024-11-27 02:02:57,452 log Internal Server Error: /disposal/
ERROR 2024-11-27 02:02:57,453 basehttp "POST /disposal/ HTTP/1.1" 500 1852
ERROR 2024-11-27 02:03:03,484 log Internal Server Error: /disposal/
ERROR 2024-11-27 02:03:03,485 basehttp "POST /disposal/ HTTP/1.1" 500 1852
ERROR 2024-11-27 02:03:08,589 log Internal Server Error: /disposal/
ERROR 2024-11-27 02:03:08,589 basehttp "POST /disposal/ HTTP/1.1" 500 1852
ERROR 2024-11-27 02:35:58,323 log Internal Server Error: /result/
ERROR 2024-11-27 02:35:58,366 basehttp "GET /result/?uid=596393001371&name=%ED%85%8C%EC%8A%A4%ED%8A%B8%EC%9C%A0%EC%A0%80&company=HD%ED%98%84%EB%8C%80%EB%AF%B8%ED%8F%AC HTTP/1.1" 500 1852
ERROR 2024-11-27 02:43:08,458 log Internal Server Error: /result/
Traceback (most recent call last):
  File "/home/pi/rasp/rfid/utils.py", line 14, in wrapper
    return func(request, *args, **kwargs)
           ^^^^^^^^^^^^^^^^^^^^^^^^^^^^^^
  File "/home/pi/rasp/rfid/views_v2.py", line 90, in result
    extra_data={'uid': uid, 'name': name, 'company': company, 'message': weight_info['message']}
                                                                         ~~~~~~~~~~~^^^^^^^^^^^
KeyError: 'message'

During handling of the above exception, another exception occurred:

Traceback (most recent call last):
  File "/usr/local/lib/python3.11/dist-packages/django/core/handlers/exception.py", line 55, in inner
    response = get_response(request)
               ^^^^^^^^^^^^^^^^^^^^^
  File "/usr/local/lib/python3.11/dist-packages/django/core/handlers/base.py", line 197, in _get_response
    response = wrapped_callback(request, *callback_args, **callback_kwargs)
               ^^^^^^^^^^^^^^^^^^^^^^^^^^^^^^^^^^^^^^^^^^^^^^^^^^^^^^^^^^^^
  File "/home/pi/rasp/rfid/utils.py", line 29, in wrapper
    logger.error(f"예기치 못한 오류: {e}", exc_info=True)
    ^^^^^^
NameError: name 'logger' is not defined
ERROR 2024-11-27 02:43:08,461 basehttp "GET /result/?uid=195883367363&name=%EC%9D%B4%EC%B0%BD%ED%99%98&company=HD%ED%98%84%EB%8C%80%EB%AF%B8%ED%8F%AC HTTP/1.1" 500 145
ERROR 2024-11-27 02:44:35,857 log Internal Server Error: /result/
ERROR 2024-11-27 02:44:35,857 basehttp "GET /result/?uid=596393001371&name=%ED%85%8C%EC%8A%A4%ED%8A%B8%EC%9C%A0%EC%A0%80&company=HD%ED%98%84%EB%8C%80%EB%AF%B8%ED%8F%AC HTTP/1.1" 500 1852
ERROR 2024-11-27 02:58:52,664 log Internal Server Error: /result/
ERROR 2024-11-27 02:58:52,664 basehttp "GET /result/?uid=596393001371&name=%ED%85%8C%EC%8A%A4%ED%8A%B8%EC%9C%A0%EC%A0%80&company=HD%ED%98%84%EB%8C%80%EB%AF%B8%ED%8F%AC HTTP/1.1" 500 1852
ERROR 2024-11-27 04:35:20,941 log Internal Server Error: /result/
ERROR 2024-11-27 04:35:20,942 basehttp "GET /result/?uid=None&name=&company= HTTP/1.1" 500 1852
ERROR 2024-11-27 05:57:47,515 log Internal Server Error: /result/
ERROR 2024-11-27 05:57:47,558 basehttp "GET /result/?uid=596393001371&name=%ED%85%8C%EC%8A%A4%ED%8A%B8%EC%9C%A0%EC%A0%80&company=HD%ED%98%84%EB%8C%80%EB%AF%B8%ED%8F%AC HTTP/1.1" 500 1852
ERROR 2024-11-27 05:57:56,696 log Internal Server Error: /disposal/
ERROR 2024-11-27 05:57:56,696 basehttp "POST /disposal/ HTTP/1.1" 500 1852
ERROR 2024-11-27 06:28:19,974 log Internal Server Error: /disposal/
ERROR 2024-11-27 06:28:20,039 basehttp "POST /disposal/ HTTP/1.1" 500 1852
ERROR 2024-11-27 06:28:22,073 log Internal Server Error: /disposal/
ERROR 2024-11-27 06:28:22,073 basehttp "POST /disposal/ HTTP/1.1" 500 1852
ERROR 2024-11-27 06:28:26,999 log Internal Server Error: /disposal/
ERROR 2024-11-27 06:28:27,000 basehttp "POST /disposal/ HTTP/1.1" 500 1852
ERROR 2024-11-27 06:28:35,597 log Internal Server Error: /result/
ERROR 2024-11-27 06:28:35,597 basehttp "GET /result/?uid=596393001371&name=%ED%85%8C%EC%8A%A4%ED%8A%B8%EC%9C%A0%EC%A0%80&company=HD%ED%98%84%EB%8C%80%EB%AF%B8%ED%8F%AC HTTP/1.1" 500 1852
ERROR 2024-11-27 06:28:39,664 log Internal Server Error: /result/
ERROR 2024-11-27 06:28:39,664 basehttp "GET /result/?uid=596393001371&name=%ED%85%8C%EC%8A%A4%ED%8A%B8%EC%9C%A0%EC%A0%80&company=HD%ED%98%84%EB%8C%80%EB%AF%B8%ED%8F%AC HTTP/1.1" 500 1852
ERROR 2024-11-27 06:29:06,581 log Internal Server Error: /result/
ERROR 2024-11-27 06:29:06,582 basehttp "GET /result/?uid=596393001371&name=%ED%85%8C%EC%8A%A4%ED%8A%B8%EC%9C%A0%EC%A0%80&company=HD%ED%98%84%EB%8C%80%EB%AF%B8%ED%8F%AC HTTP/1.1" 500 1852
ERROR 2024-11-27 06:29:32,724 log Internal Server Error: /result/
ERROR 2024-11-27 06:29:32,725 basehttp "GET /result/?uid=596393001371&name=%ED%85%8C%EC%8A%A4%ED%8A%B8%EC%9C%A0%EC%A0%80&company=HD%ED%98%84%EB%8C%80%EB%AF%B8%ED%8F%AC HTTP/1.1" 500 1852
ERROR 2024-11-27 06:34:57,815 log Internal Server Error: /result/
ERROR 2024-11-27 06:34:57,815 basehttp "GET /result/?uid=596393001371&name=%ED%85%8C%EC%8A%A4%ED%8A%B8%EC%9C%A0%EC%A0%80&company=HD%ED%98%84%EB%8C%80%EB%AF%B8%ED%8F%AC HTTP/1.1" 500 1852
ERROR 2024-11-27 06:38:27,466 log Internal Server Error: /result/
ERROR 2024-11-27 06:38:27,467 basehttp "GET /result/?uid=596393001371&name=%ED%85%8C%EC%8A%A4%ED%8A%B8%EC%9C%A0%EC%A0%80&company=HD%ED%98%84%EB%8C%80%EB%AF%B8%ED%8F%AC HTTP/1.1" 500 1865
ERROR 2024-11-27 06:38:38,734 log Internal Server Error: /result/
ERROR 2024-11-27 06:38:38,735 basehttp "GET /result/?uid=596393001371&name=%ED%85%8C%EC%8A%A4%ED%8A%B8%EC%9C%A0%EC%A0%80&company=HD%ED%98%84%EB%8C%80%EB%AF%B8%ED%8F%AC HTTP/1.1" 500 1865
ERROR 2024-11-27 06:40:38,023 log Internal Server Error: /result/
ERROR 2024-11-27 06:40:38,023 basehttp "GET /result/?uid=596393001371&name=%ED%85%8C%EC%8A%A4%ED%8A%B8%EC%9C%A0%EC%A0%80&company=HD%ED%98%84%EB%8C%80%EB%AF%B8%ED%8F%AC HTTP/1.1" 500 1865
ERROR 2024-11-27 07:41:31,302 log Internal Server Error: /result/
ERROR 2024-11-27 07:41:31,303 basehttp "GET /result/?uid=195883367363&name=%EC%9D%B4%EC%B0%BD%ED%99%98&company=HD%ED%98%84%EB%8C%80%EB%AF%B8%ED%8F%AC HTTP/1.1" 500 1852
ERROR 2024-11-15 04:50:21,296 log Internal Server Error: /disposal/
ERROR 2024-11-15 04:50:21,296 basehttp "POST /disposal/ HTTP/1.1" 500 1852
ERROR 2024-11-15 12:08:35,686 log Internal Server Error: /result/
ERROR 2024-11-15 12:08:35,687 basehttp "GET /result/?uid=195883367363&name=%EC%9D%B4%EC%B0%BD%ED%99%98&company=hd%ED%98%84%EB%8C%80%EB%AF%B8%ED%8F%AC HTTP/1.1" 500 1848
ERROR 2024-11-15 12:13:01,862 log Internal Server Error: /result/
ERROR 2024-11-15 12:13:01,862 basehttp "GET /result/?uid=195883367363&name=%EC%9D%B4%EC%B0%BD%ED%99%98&company=hd%ED%98%84%EB%8C%80%EB%AF%B8%ED%8F%AC HTTP/1.1" 500 1848
ERROR 2024-11-15 12:13:42,942 log Internal Server Error: /result/
ERROR 2024-11-15 12:13:42,942 basehttp "GET /result/?uid=195883367363&name=%EC%9D%B4%EC%B0%BD%ED%99%98&company=hd%ED%98%84%EB%8C%80%EB%AF%B8%ED%8F%AC HTTP/1.1" 500 1848
ERROR 2024-11-15 12:13:52,457 log Internal Server Error: /result/
ERROR 2024-11-15 12:13:52,457 basehttp "GET /result/?uid=195883367363&name=%EC%9D%B4%EC%B0%BD%ED%99%98&company=hd%ED%98%84%EB%8C%80%EB%AF%B8%ED%8F%AC HTTP/1.1" 500 1848
ERROR 2024-11-15 12:14:10,183 log Internal Server Error: /result/
ERROR 2024-11-15 12:14:10,183 basehttp "GET /result/?uid=195883367363&name=%EC%9D%B4%EC%B0%BD%ED%99%98&company=hd%ED%98%84%EB%8C%80%EB%AF%B8%ED%8F%AC HTTP/1.1" 500 1848
ERROR 2024-11-15 12:15:40,431 log Internal Server Error: /result/
ERROR 2024-11-15 12:15:40,431 basehttp "GET /result/?uid=195883367363&name=%EC%9D%B4%EC%B0%BD%ED%99%98&company=hd%ED%98%84%EB%8C%80%EB%AF%B8%ED%8F%AC HTTP/1.1" 500 1848
ERROR 2024-11-15 12:16:38,921 log Internal Server Error: /result/
ERROR 2024-11-15 12:16:38,921 basehttp "GET /result/?uid=195883367363&name=%EC%9D%B4%EC%B0%BD%ED%99%98&company=hd%ED%98%84%EB%8C%80%EB%AF%B8%ED%8F%AC HTTP/1.1" 500 1848
ERROR 2024-11-15 12:16:44,263 log Internal Server Error: /result/
ERROR 2024-11-15 12:16:44,263 basehttp "GET /result/?uid=195883367363&name=%EC%9D%B4%EC%B0%BD%ED%99%98&company=hd%ED%98%84%EB%8C%80%EB%AF%B8%ED%8F%AC HTTP/1.1" 500 1848
ERROR 2024-11-15 12:16:51,690 log Internal Server Error: /result/
ERROR 2024-11-15 12:16:51,690 basehttp "GET /result/?uid=195883367363&name=%EC%9D%B4%EC%B0%BD%ED%99%98&company=hd%ED%98%84%EB%8C%80%EB%AF%B8%ED%8F%AC HTTP/1.1" 500 1848
ERROR 2024-11-15 12:21:16,246 log Internal Server Error: /result/
ERROR 2024-11-15 12:21:16,246 basehttp "GET /result/?uid=195883367363&name=%EC%9D%B4%EC%B0%BD%ED%99%98&company=hd%ED%98%84%EB%8C%80%EB%AF%B8%ED%8F%AC HTTP/1.1" 500 1848
ERROR 2024-11-15 12:23:35,096 log Internal Server Error: /result/
ERROR 2024-11-15 12:23:35,096 basehttp "GET /result/?uid=195883367363&name=%EC%9D%B4%EC%B0%BD%ED%99%98&company=hd%ED%98%84%EB%8C%80%EB%AF%B8%ED%8F%AC HTTP/1.1" 500 1848
ERROR 2024-11-15 12:24:36,380 log Internal Server Error: /result/
ERROR 2024-11-15 12:24:36,381 basehttp "GET /result/?uid=195883367363&name=%EC%9D%B4%EC%B0%BD%ED%99%98&company=hd%ED%98%84%EB%8C%80%EB%AF%B8%ED%8F%AC HTTP/1.1" 500 1848
ERROR 2024-11-15 12:27:30,144 log Internal Server Error: /result/
ERROR 2024-11-15 12:27:30,144 basehttp "GET /result/?uid=195883367363&name=%EC%9D%B4%EC%B0%BD%ED%99%98&company=hd%ED%98%84%EB%8C%80%EB%AF%B8%ED%8F%AC HTTP/1.1" 500 1848
ERROR 2024-11-15 12:27:47,045 log Internal Server Error: /result/
ERROR 2024-11-15 12:27:47,045 basehttp "GET /result/?uid=195883367363&name=%EC%9D%B4%EC%B0%BD%ED%99%98&company=hd%ED%98%84%EB%8C%80%EB%AF%B8%ED%8F%AC HTTP/1.1" 500 1848
ERROR 2024-11-15 12:28:07,566 log Internal Server Error: /result/
ERROR 2024-11-15 12:28:07,566 basehttp "GET /result/?uid=195883367363&name=%EC%9D%B4%EC%B0%BD%ED%99%98&company=hd%ED%98%84%EB%8C%80%EB%AF%B8%ED%8F%AC HTTP/1.1" 500 1848
ERROR 2024-11-15 12:28:20,799 log Internal Server Error: /result/
ERROR 2024-11-15 12:28:20,800 basehttp "GET /result/?uid=195883367363&name=%EC%9D%B4%EC%B0%BD%ED%99%98&company=hd%ED%98%84%EB%8C%80%EB%AF%B8%ED%8F%AC HTTP/1.1" 500 1848
ERROR 2024-11-15 12:28:52,766 log Internal Server Error: /result/
ERROR 2024-11-15 12:28:52,767 basehttp "GET /result/?uid=195883367363&name=%EC%9D%B4%EC%B0%BD%ED%99%98&company=hd%ED%98%84%EB%8C%80%EB%AF%B8%ED%8F%AC HTTP/1.1" 500 1848
ERROR 2024-11-15 12:43:55,957 log Internal Server Error: /result/
ERROR 2024-11-15 12:43:55,958 basehttp "GET /result/?uid=195883367363&name=%EC%9D%B4%EC%B0%BD%ED%99%98&company=hd%ED%98%84%EB%8C%80%EB%AF%B8%ED%8F%AC HTTP/1.1" 500 1852
ERROR 2024-11-15 12:44:27,359 log Internal Server Error: /result/
ERROR 2024-11-15 12:44:27,360 basehttp "GET /result/?uid=195883367363&name=%EC%9D%B4%EC%B0%BD%ED%99%98&company=hd%ED%98%84%EB%8C%80%EB%AF%B8%ED%8F%AC HTTP/1.1" 500 1848
ERROR 2024-11-15 12:48:00,595 log Internal Server Error: /result/
ERROR 2024-11-15 12:48:00,596 basehttp "GET /result/?uid=195883367363&name=%EC%9D%B4%EC%B0%BD%ED%99%98&company=hd%ED%98%84%EB%8C%80%EB%AF%B8%ED%8F%AC HTTP/1.1" 500 1848
ERROR 2024-11-15 12:48:45,902 log Internal Server Error: /result/
ERROR 2024-11-15 12:48:45,903 basehttp "GET /result/?uid=195883367363&name=%EC%9D%B4%EC%B0%BD%ED%99%98&company=hd%ED%98%84%EB%8C%80%EB%AF%B8%ED%8F%AC HTTP/1.1" 500 1848
ERROR 2024-11-15 12:49:06,868 log Internal Server Error: /result/
ERROR 2024-11-15 12:49:06,868 basehttp "GET /result/?uid=195883367363&name=%EC%9D%B4%EC%B0%BD%ED%99%98&company=hd%ED%98%84%EB%8C%80%EB%AF%B8%ED%8F%AC HTTP/1.1" 500 1848
ERROR 2024-11-15 12:51:10,287 log Internal Server Error: /result/
ERROR 2024-11-15 12:51:10,288 basehttp "GET /result/?uid=195883367363&name=%EC%9D%B4%EC%B0%BD%ED%99%98&company=hd%ED%98%84%EB%8C%80%EB%AF%B8%ED%8F%AC HTTP/1.1" 500 1848
ERROR 2024-11-15 12:51:37,729 log Internal Server Error: /result/
ERROR 2024-11-15 12:51:37,730 basehttp "GET /result/?uid=195883367363&name=%EC%9D%B4%EC%B0%BD%ED%99%98&company=hd%ED%98%84%EB%8C%80%EB%AF%B8%ED%8F%AC HTTP/1.1" 500 1848
ERROR 2024-11-15 12:52:07,134 log Internal Server Error: /result/
ERROR 2024-11-15 12:52:07,134 basehttp "GET /result/?uid=195883367363&name=%EC%9D%B4%EC%B0%BD%ED%99%98&company=hd%ED%98%84%EB%8C%80%EB%AF%B8%ED%8F%AC HTTP/1.1" 500 1848
ERROR 2024-11-15 12:52:18,331 log Internal Server Error: /result/
ERROR 2024-11-15 12:52:18,332 basehttp "GET /result/?uid=195883367363&name=%EC%9D%B4%EC%B0%BD%ED%99%98&company=hd%ED%98%84%EB%8C%80%EB%AF%B8%ED%8F%AC HTTP/1.1" 500 1848
ERROR 2024-11-15 12:52:31,566 log Internal Server Error: /result/
ERROR 2024-11-15 12:52:31,567 basehttp "GET /result/?uid=195883367363&name=%EC%9D%B4%EC%B0%BD%ED%99%98&company=hd%ED%98%84%EB%8C%80%EB%AF%B8%ED%8F%AC HTTP/1.1" 500 1848
ERROR 2024-11-15 13:33:58,582 log Internal Server Error: /result/
ERROR 2024-11-15 13:33:58,582 basehttp "GET /result/?uid=195883367363&name=%EC%9D%B4%EC%B0%BD%ED%99%98&company=hd%ED%98%84%EB%8C%80%EB%AF%B8%ED%8F%AC HTTP/1.1" 500 1848
ERROR 2024-11-15 16:09:51,356 log Internal Server Error: /disposal/
ERROR 2024-11-15 16:09:51,359 basehttp "POST /disposal/ HTTP/1.1" 500 1852
ERROR 2024-11-15 16:09:57,382 log Internal Server Error: /disposal/
ERROR 2024-11-15 16:09:57,383 basehttp "POST /disposal/ HTTP/1.1" 500 1852
ERROR 2024-11-15 16:10:32,234 log Internal Server Error: /disposal/
ERROR 2024-11-15 16:10:32,234 basehttp "POST /disposal/ HTTP/1.1" 500 1852
ERROR 2024-11-15 16:18:05,614 log Internal Server Error: /user_add/
ERROR 2024-11-15 16:18:05,615 basehttp "POST /user_add/ HTTP/1.1" 500 1903
ERROR 2024-11-15 16:25:36,224 log Internal Server Error: /user_add/
ERROR 2024-11-15 16:25:36,225 basehttp "POST /user_add/ HTTP/1.1" 500 1903
ERROR 2024-12-04 09:06:31,006 rfid_reader tagging Timeout: UID not detected
ERROR 2024-12-04 09:06:44,072 rfid_reader tagging Timeout: UID not detected
ERROR 2024-12-04 09:07:14,091 rfid_reader tagging Timeout: UID not detected
ERROR 2024-12-05 08:05:44,054 rfid_reader tagging Timeout: UID not detected
ERROR 2024-12-05 08:06:16,091 rfid_reader tagging Timeout: UID not detected
ERROR 2024-12-05 08:06:48,395 rfid_reader tagging Timeout: UID not detected
ERROR 2024-12-05 08:07:05,907 rfid_reader tagging Timeout: UID not detected
ERROR 2024-12-05 08:12:35,300 rfid_reader tagging Timeout: UID not detected
ERROR 2024-12-05 08:21:26,808 views_v2 result 세션에 UID가 없습니다.
ERROR 2024-12-05 08:21:41,728 rfid_reader tagging Timeout: UID not detected
ERROR 2024-12-05 16:06:40,255 user_management check_user 사용자를 찾을 수 없음: UID 04 E3 43 6A 76 13 90
ERROR 2024-12-05 16:06:52,895 user_management check_user 사용자를 찾을 수 없음: UID 2D 9B 8E FB
ERROR 2024-12-06 13:07:42,952 user_management check_user 사용자를 찾을 수 없음: UID DF 79 1A 82
ERROR 2024-12-06 13:09:34,762 weight update_weight 서버 오류 발생: unsupported operand type(s) for +: 'float' and 'tuple'
ERROR 2024-12-06 13:09:49,911 weight update_weight 서버 오류 발생: unsupported operand type(s) for +: 'float' and 'tuple'
ERROR 2024-12-06 13:10:24,921 weight update_weight 서버 오류 발생: unsupported operand type(s) for +: 'float' and 'tuple'
ERROR 2024-12-09 07:48:37,238 weight update_weight 서버 오류 발생: 유효한 데이터가 수신되지 않았습니다. (Status Code: 404)
ERROR 2024-12-09 07:55:58,511 weight update_weight 서버 오류 발생: 유효한 데이터가 수신되지 않았습니다. (Status Code: 404)
ERROR 2024-12-09 07:57:41,976 weight update_weight 서버 오류 발생: 유효한 데이터가 수신되지 않았습니다. (Status Code: 404)
ERROR 2024-12-09 08:03:26,660 weight update_weight 서버 오류 발생: 유효한 데이터가 수신되지 않았습니다. (Status Code: 404)
ERROR 2024-12-09 08:03:42,818 weight update_weight 서버 오류 발생: 유효한 데이터가 수신되지 않았습니다. (Status Code: 404)
ERROR 2024-12-09 08:13:23,891 weight update_weight 서버 오류 발생: 유효한 데이터가 수신되지 않았습니다. (Status Code: 404)
ERROR 2024-12-09 09:55:00,066 weight update_weight 서버 오류 발생: 유효한 데이터가 수신되지 않았습니다. (Status Code: 404)
ERROR 2024-12-09 10:10:49,582 weight update_weight 서버 오류 발생: 유효한 데이터가 수신되지 않았습니다. (Status Code: 404)
ERROR 2024-12-09 10:12:17,876 weight update_weight 서버 오류 발생: 유효한 데이터가 수신되지 않았습니다. (Status Code: 404)
ERROR 2024-12-09 10:19:19,954 weight update_weight 서버 오류 발생: 유효한 데이터가 수신되지 않았습니다. (Status Code: 404)
ERROR 2024-12-09 10:34:04,716 weight update_weight 서버 오류 발생: 유효한 데이터가 수신되지 않았습니다. (Status Code: 404)
ERROR 2024-12-09 10:42:12,260 weight update_weight 서버 오류 발생: 유효한 데이터가 수신되지 않았습니다. (Status Code: 404)
ERROR 2024-12-09 10:42:51,362 utils wrapper 예기치 못한 오류: disposal() missing 1 required positional argument: 'uid'
Traceback (most recent call last):
  File "/home/pi/Desktop/rasp/rfid/utils.py", line 16, in wrapper
    return func(request, *args, **kwargs)
           ^^^^^^^^^^^^^^^^^^^^^^^^^^^^^^
TypeError: disposal() missing 1 required positional argument: 'uid'
ERROR 2024-12-09 10:43:06,392 weight update_weight 서버 오류 발생: 유효한 데이터가 수신되지 않았습니다. (Status Code: 404)
ERROR 2024-12-09 10:43:20,959 weight update_weight 서버 오류 발생: 유효한 데이터가 수신되지 않았습니다. (Status Code: 404)
ERROR 2024-12-09 10:55:03,324 weight update_weight 서버 오류 발생: 유효한 데이터가 수신되지 않았습니다. (Status Code: 404)
ERROR 2024-12-09 11:11:55,241 utils wrapper 예기치 못한 오류: result() missing 1 required positional argument: 'tag_uid'
Traceback (most recent call last):
  File "/home/pi/Desktop/rasp/rfid/utils.py", line 16, in wrapper
    return func(request, *args, **kwargs)
           ^^^^^^^^^^^^^^^^^^^^^^^^^^^^^^
TypeError: result() missing 1 required positional argument: 'tag_uid'
ERROR 2024-12-09 11:12:30,556 utils wrapper 예기치 못한 오류: result() missing 1 required positional argument: 'tag_uid'
Traceback (most recent call last):
  File "/home/pi/Desktop/rasp/rfid/utils.py", line 16, in wrapper
    return func(request, *args, **kwargs)
           ^^^^^^^^^^^^^^^^^^^^^^^^^^^^^^
TypeError: result() missing 1 required positional argument: 'tag_uid'
ERROR 2024-12-09 11:17:51,414 utils wrapper 예기치 못한 오류: result() missing 1 required positional argument: 'uid'
Traceback (most recent call last):
  File "/home/pi/Desktop/rasp/rfid/utils.py", line 16, in wrapper
    return func(request, *args, **kwargs)
           ^^^^^^^^^^^^^^^^^^^^^^^^^^^^^^
TypeError: result() missing 1 required positional argument: 'uid'
ERROR 2024-12-09 11:24:47,562 weight update_weight 서버 오류 발생: 유효한 데이터가 수신되지 않았습니다. (Status Code: 404)
ERROR 2024-12-09 11:31:37,982 weight update_weight 서버 오류 발생: 유효한 데이터가 수신되지 않았습니다. (Status Code: 404)
ERROR 2024-12-09 11:36:07,629 weight update_weight 서버 오류 발생: 유효한 데이터가 수신되지 않았습니다. (Status Code: 404)
ERROR 2024-12-09 11:36:22,832 utils wrapper 예기치 못한 오류: 'message'
Traceback (most recent call last):
  File "/home/pi/Desktop/rasp/rfid/utils.py", line 16, in wrapper
    return func(request, *args, **kwargs)
           ^^^^^^^^^^^^^^^^^^^^^^^^^^^^^^
  File "/home/pi/Desktop/rasp/rfid/views_v2.py", line 148, in result
    'message': weight_info['message'],
               ~~~~~~~~~~~^^^^^^^^^^^
KeyError: 'message'
ERROR 2024-12-09 11:36:30,054 utils wrapper 예기치 못한 오류: 'message'
Traceback (most recent call last):
  File "/home/pi/Desktop/rasp/rfid/utils.py", line 16, in wrapper
    return func(request, *args, **kwargs)
           ^^^^^^^^^^^^^^^^^^^^^^^^^^^^^^
  File "/home/pi/Desktop/rasp/rfid/views_v2.py", line 148, in result
    'message': weight_info['message'],
               ~~~~~~~~~~~^^^^^^^^^^^
KeyError: 'message'
ERROR 2024-12-09 11:36:55,936 utils wrapper 예기치 못한 오류: 'message'
Traceback (most recent call last):
  File "/home/pi/Desktop/rasp/rfid/utils.py", line 16, in wrapper
    return func(request, *args, **kwargs)
           ^^^^^^^^^^^^^^^^^^^^^^^^^^^^^^
  File "/home/pi/Desktop/rasp/rfid/views_v2.py", line 148, in result
    'message': weight_info['message'],
               ~~~~~~~~~~~^^^^^^^^^^^
KeyError: 'message'
ERROR 2024-12-09 11:37:08,235 weight update_weight 서버 오류 발생: 유효한 데이터가 수신되지 않았습니다. (Status Code: 404)
ERROR 2024-12-09 11:39:35,433 views_v2 disposal 알 수 없는 오류: Reverse for 'check_rfid_disposal' not found. 'check_rfid_disposal' is not a valid view function or pattern name.
ERROR 2024-12-09 11:39:49,190 views_v2 disposal 알 수 없는 오류: Reverse for 'check_rfid_disposal' not found. 'check_rfid_disposal' is not a valid view function or pattern name.
ERROR 2024-12-09 11:40:04,432 views_v2 disposal 알 수 없는 오류: Reverse for 'check_rfid_disposal' not found. 'check_rfid_disposal' is not a valid view function or pattern name.
ERROR 2024-12-09 11:40:44,556 views_v2 disposal 알 수 없는 오류: Reverse for 'check_rfid_disposal' not found. 'check_rfid_disposal' is not a valid view function or pattern name.
ERROR 2024-12-09 11:41:58,710 views_v2 disposal 알 수 없는 오류: Reverse for 'check_rfid_disposal' not found. 'check_rfid_disposal' is not a valid view function or pattern name.
ERROR 2024-12-09 11:42:37,037 weight update_weight 서버 오류 발생: 유효한 데이터가 수신되지 않았습니다. (Status Code: 404)
ERROR 2024-12-09 15:49:38,120 weight update_weight 서버 오류 발생: 유효한 데이터가 수신되지 않았습니다. (Status Code: 404)
ERROR 2024-12-09 15:50:25,020 weight update_weight 서버 오류 발생: 유효한 데이터가 수신되지 않았습니다. (Status Code: 404)
ERROR 2024-12-09 15:50:38,017 weight update_weight 서버 오류 발생: 유효한 데이터가 수신되지 않았습니다. (Status Code: 404)
ERROR 2024-12-09 15:51:18,373 weight update_weight 서버 오류 발생: 유효한 데이터가 수신되지 않았습니다. (Status Code: 404)
ERROR 2024-12-09 15:51:32,477 weight update_weight 서버 오류 발생: 유효한 데이터가 수신되지 않았습니다. (Status Code: 404)
ERROR 2024-12-09 15:51:41,364 user_management check_user 사용자를 찾을 수 없음: UID 07 62 D7 63
ERROR 2024-12-09 16:00:43,905 views_v2 disposal 알 수 없는 오류: Invalid block tag on line 70: ''check_rfid''. Did you forget to register or load this tag?
ERROR 2024-12-09 16:10:21,922 utils wrapper 예기치 못한 오류: Reverse for 'check_rfid' not found. 'check_rfid' is not a valid view function or pattern name.
Traceback (most recent call last):
  File "/home/pi/Desktop/rasp/rfid/utils.py", line 16, in wrapper
    return func(request, *args, **kwargs)
           ^^^^^^^^^^^^^^^^^^^^^^^^^^^^^^
  File "/home/pi/Desktop/rasp/rfid/views_v2.py", line 75, in homePage
    return render(request, 'home.html')
           ^^^^^^^^^^^^^^^^^^^^^^^^^^^^
  File "/usr/local/lib/python3.11/dist-packages/django/shortcuts.py", line 25, in render
    content = loader.render_to_string(template_name, context, request, using=using)
              ^^^^^^^^^^^^^^^^^^^^^^^^^^^^^^^^^^^^^^^^^^^^^^^^^^^^^^^^^^^^^^^^^^^^^
  File "/usr/local/lib/python3.11/dist-packages/django/template/loader.py", line 62, in render_to_string
    return template.render(context, request)
           ^^^^^^^^^^^^^^^^^^^^^^^^^^^^^^^^^
  File "/usr/local/lib/python3.11/dist-packages/django/template/backends/django.py", line 107, in render
    return self.template.render(context)
           ^^^^^^^^^^^^^^^^^^^^^^^^^^^^^
  File "/usr/local/lib/python3.11/dist-packages/django/template/base.py", line 171, in render
    return self._render(context)
           ^^^^^^^^^^^^^^^^^^^^^
  File "/usr/local/lib/python3.11/dist-packages/django/template/base.py", line 163, in _render
    return self.nodelist.render(context)
           ^^^^^^^^^^^^^^^^^^^^^^^^^^^^^
  File "/usr/local/lib/python3.11/dist-packages/django/template/base.py", line 1008, in render
    return SafeString("".join([node.render_annotated(context) for node in self]))
                              ^^^^^^^^^^^^^^^^^^^^^^^^^^^^^^^^^^^^^^^^^^^^^^^^^
  File "/usr/local/lib/python3.11/dist-packages/django/template/base.py", line 1008, in <listcomp>
    return SafeString("".join([node.render_annotated(context) for node in self]))
                               ^^^^^^^^^^^^^^^^^^^^^^^^^^^^^^
  File "/usr/local/lib/python3.11/dist-packages/django/template/base.py", line 969, in render_annotated
    return self.render(context)
           ^^^^^^^^^^^^^^^^^^^^
  File "/usr/local/lib/python3.11/dist-packages/django/template/defaulttags.py", line 480, in render
    url = reverse(view_name, args=args, kwargs=kwargs, current_app=current_app)
          ^^^^^^^^^^^^^^^^^^^^^^^^^^^^^^^^^^^^^^^^^^^^^^^^^^^^^^^^^^^^^^^^^^^^^
  File "/usr/local/lib/python3.11/dist-packages/django/urls/base.py", line 88, in reverse
    return resolver._reverse_with_prefix(view, prefix, *args, **kwargs)
           ^^^^^^^^^^^^^^^^^^^^^^^^^^^^^^^^^^^^^^^^^^^^^^^^^^^^^^^^^^^^
  File "/usr/local/lib/python3.11/dist-packages/django/urls/resolvers.py", line 831, in _reverse_with_prefix
    raise NoReverseMatch(msg)
django.urls.exceptions.NoReverseMatch: Reverse for 'check_rfid' not found. 'check_rfid' is not a valid view function or pattern name.
ERROR 2024-12-09 16:10:22,300 utils wrapper 예기치 못한 오류: Reverse for 'check_rfid' not found. 'check_rfid' is not a valid view function or pattern name.
Traceback (most recent call last):
  File "/home/pi/Desktop/rasp/rfid/utils.py", line 16, in wrapper
    return func(request, *args, **kwargs)
           ^^^^^^^^^^^^^^^^^^^^^^^^^^^^^^
  File "/home/pi/Desktop/rasp/rfid/views_v2.py", line 75, in homePage
    return render(request, 'home.html')
           ^^^^^^^^^^^^^^^^^^^^^^^^^^^^
  File "/usr/local/lib/python3.11/dist-packages/django/shortcuts.py", line 25, in render
    content = loader.render_to_string(template_name, context, request, using=using)
              ^^^^^^^^^^^^^^^^^^^^^^^^^^^^^^^^^^^^^^^^^^^^^^^^^^^^^^^^^^^^^^^^^^^^^
  File "/usr/local/lib/python3.11/dist-packages/django/template/loader.py", line 62, in render_to_string
    return template.render(context, request)
           ^^^^^^^^^^^^^^^^^^^^^^^^^^^^^^^^^
  File "/usr/local/lib/python3.11/dist-packages/django/template/backends/django.py", line 107, in render
    return self.template.render(context)
           ^^^^^^^^^^^^^^^^^^^^^^^^^^^^^
  File "/usr/local/lib/python3.11/dist-packages/django/template/base.py", line 171, in render
    return self._render(context)
           ^^^^^^^^^^^^^^^^^^^^^
  File "/usr/local/lib/python3.11/dist-packages/django/template/base.py", line 163, in _render
    return self.nodelist.render(context)
           ^^^^^^^^^^^^^^^^^^^^^^^^^^^^^
  File "/usr/local/lib/python3.11/dist-packages/django/template/base.py", line 1008, in render
    return SafeString("".join([node.render_annotated(context) for node in self]))
                              ^^^^^^^^^^^^^^^^^^^^^^^^^^^^^^^^^^^^^^^^^^^^^^^^^
  File "/usr/local/lib/python3.11/dist-packages/django/template/base.py", line 1008, in <listcomp>
    return SafeString("".join([node.render_annotated(context) for node in self]))
                               ^^^^^^^^^^^^^^^^^^^^^^^^^^^^^^
  File "/usr/local/lib/python3.11/dist-packages/django/template/base.py", line 969, in render_annotated
    return self.render(context)
           ^^^^^^^^^^^^^^^^^^^^
  File "/usr/local/lib/python3.11/dist-packages/django/template/defaulttags.py", line 480, in render
    url = reverse(view_name, args=args, kwargs=kwargs, current_app=current_app)
          ^^^^^^^^^^^^^^^^^^^^^^^^^^^^^^^^^^^^^^^^^^^^^^^^^^^^^^^^^^^^^^^^^^^^^
  File "/usr/local/lib/python3.11/dist-packages/django/urls/base.py", line 88, in reverse
    return resolver._reverse_with_prefix(view, prefix, *args, **kwargs)
           ^^^^^^^^^^^^^^^^^^^^^^^^^^^^^^^^^^^^^^^^^^^^^^^^^^^^^^^^^^^^
  File "/usr/local/lib/python3.11/dist-packages/django/urls/resolvers.py", line 831, in _reverse_with_prefix
    raise NoReverseMatch(msg)
django.urls.exceptions.NoReverseMatch: Reverse for 'check_rfid' not found. 'check_rfid' is not a valid view function or pattern name.
ERROR 2024-12-09 16:10:51,147 utils wrapper 예기치 못한 오류: Reverse for 'check_rfid' not found. 'check_rfid' is not a valid view function or pattern name.
Traceback (most recent call last):
  File "/home/pi/Desktop/rasp/rfid/utils.py", line 16, in wrapper
    return func(request, *args, **kwargs)
           ^^^^^^^^^^^^^^^^^^^^^^^^^^^^^^
  File "/home/pi/Desktop/rasp/rfid/views_v2.py", line 75, in homePage
    return render(request, 'home.html')
           ^^^^^^^^^^^^^^^^^^^^^^^^^^^^
  File "/usr/local/lib/python3.11/dist-packages/django/shortcuts.py", line 25, in render
    content = loader.render_to_string(template_name, context, request, using=using)
              ^^^^^^^^^^^^^^^^^^^^^^^^^^^^^^^^^^^^^^^^^^^^^^^^^^^^^^^^^^^^^^^^^^^^^
  File "/usr/local/lib/python3.11/dist-packages/django/template/loader.py", line 62, in render_to_string
    return template.render(context, request)
           ^^^^^^^^^^^^^^^^^^^^^^^^^^^^^^^^^
  File "/usr/local/lib/python3.11/dist-packages/django/template/backends/django.py", line 107, in render
    return self.template.render(context)
           ^^^^^^^^^^^^^^^^^^^^^^^^^^^^^
  File "/usr/local/lib/python3.11/dist-packages/django/template/base.py", line 171, in render
    return self._render(context)
           ^^^^^^^^^^^^^^^^^^^^^
  File "/usr/local/lib/python3.11/dist-packages/django/template/base.py", line 163, in _render
    return self.nodelist.render(context)
           ^^^^^^^^^^^^^^^^^^^^^^^^^^^^^
  File "/usr/local/lib/python3.11/dist-packages/django/template/base.py", line 1008, in render
    return SafeString("".join([node.render_annotated(context) for node in self]))
                              ^^^^^^^^^^^^^^^^^^^^^^^^^^^^^^^^^^^^^^^^^^^^^^^^^
  File "/usr/local/lib/python3.11/dist-packages/django/template/base.py", line 1008, in <listcomp>
    return SafeString("".join([node.render_annotated(context) for node in self]))
                               ^^^^^^^^^^^^^^^^^^^^^^^^^^^^^^
  File "/usr/local/lib/python3.11/dist-packages/django/template/base.py", line 969, in render_annotated
    return self.render(context)
           ^^^^^^^^^^^^^^^^^^^^
  File "/usr/local/lib/python3.11/dist-packages/django/template/defaulttags.py", line 480, in render
    url = reverse(view_name, args=args, kwargs=kwargs, current_app=current_app)
          ^^^^^^^^^^^^^^^^^^^^^^^^^^^^^^^^^^^^^^^^^^^^^^^^^^^^^^^^^^^^^^^^^^^^^
  File "/usr/local/lib/python3.11/dist-packages/django/urls/base.py", line 88, in reverse
    return resolver._reverse_with_prefix(view, prefix, *args, **kwargs)
           ^^^^^^^^^^^^^^^^^^^^^^^^^^^^^^^^^^^^^^^^^^^^^^^^^^^^^^^^^^^^
  File "/usr/local/lib/python3.11/dist-packages/django/urls/resolvers.py", line 831, in _reverse_with_prefix
    raise NoReverseMatch(msg)
django.urls.exceptions.NoReverseMatch: Reverse for 'check_rfid' not found. 'check_rfid' is not a valid view function or pattern name.
ERROR 2024-12-09 16:11:27,919 utils wrapper 예기치 못한 오류: DigitalOutputDevice is closed or uninitialized
Traceback (most recent call last):
  File "/usr/lib/python3/dist-packages/gpiozero/output_devices.py", line 87, in _write
    self.pin.state = self._value_to_state(value)
    ^^^^^^^^^^^^^^
AttributeError: 'NoneType' object has no attribute 'state'

During handling of the above exception, another exception occurred:

Traceback (most recent call last):
  File "/usr/lib/python3/dist-packages/gpiozero/devices.py", line 584, in _check_open
    super()._check_open()
  File "/usr/lib/python3/dist-packages/gpiozero/devices.py", line 213, in _check_open
    raise DeviceClosed(
gpiozero.exc.DeviceClosed: DigitalOutputDevice is closed or uninitialized

During handling of the above exception, another exception occurred:

Traceback (most recent call last):
  File "/home/pi/Desktop/rasp/rfid/utils.py", line 16, in wrapper
    return func(request, *args, **kwargs)
           ^^^^^^^^^^^^^^^^^^^^^^^^^^^^^^
  File "/home/pi/Desktop/rasp/rfid/views_v2.py", line 73, in homePage
    lock.on()  # 잠금 장치 닫기
    ^^^^^^^^^
  File "/usr/lib/python3/dist-packages/gpiozero/output_devices.py", line 210, in on
    self._write(True)
  File "/usr/lib/python3/dist-packages/gpiozero/output_devices.py", line 89, in _write
    self._check_open()
  File "/usr/lib/python3/dist-packages/gpiozero/devices.py", line 587, in _check_open
    raise GPIODeviceClosed(str(e))
gpiozero.exc.GPIODeviceClosed: DigitalOutputDevice is closed or uninitialized
ERROR 2024-12-09 16:32:10,786 weight update_weight 서버 오류 발생: 유효한 데이터가 수신되지 않았습니다. (Status Code: 404)
ERROR 2024-12-09 16:41:46,414 utils wrapper 예기치 못한 오류: 'message'
Traceback (most recent call last):
  File "/home/pi/Desktop/rasp/rfid/utils.py", line 16, in wrapper
    return func(request, *args, **kwargs)
           ^^^^^^^^^^^^^^^^^^^^^^^^^^^^^^
  File "/home/pi/Desktop/rasp/rfid/views_v2.py", line 151, in result
    'message': weight_info['message'],
               ~~~~~~~~~~~^^^^^^^^^^^
KeyError: 'message'
ERROR 2024-12-09 16:41:47,398 utils wrapper 예기치 못한 오류: 'message'
Traceback (most recent call last):
  File "/home/pi/Desktop/rasp/rfid/utils.py", line 16, in wrapper
    return func(request, *args, **kwargs)
           ^^^^^^^^^^^^^^^^^^^^^^^^^^^^^^
  File "/home/pi/Desktop/rasp/rfid/views_v2.py", line 151, in result
    'message': weight_info['message'],
               ~~~~~~~~~~~^^^^^^^^^^^
KeyError: 'message'
ERROR 2024-12-09 16:41:55,406 utils wrapper 예기치 못한 오류: 'message'
Traceback (most recent call last):
  File "/home/pi/Desktop/rasp/rfid/utils.py", line 16, in wrapper
    return func(request, *args, **kwargs)
           ^^^^^^^^^^^^^^^^^^^^^^^^^^^^^^
  File "/home/pi/Desktop/rasp/rfid/views_v2.py", line 151, in result
    'message': weight_info['message'],
               ~~~~~~~~~~~^^^^^^^^^^^
KeyError: 'message'
ERROR 2024-12-09 16:41:55,484 utils wrapper 예기치 못한 오류: 'message'
Traceback (most recent call last):
  File "/home/pi/Desktop/rasp/rfid/utils.py", line 16, in wrapper
    return func(request, *args, **kwargs)
           ^^^^^^^^^^^^^^^^^^^^^^^^^^^^^^
  File "/home/pi/Desktop/rasp/rfid/views_v2.py", line 151, in result
    'message': weight_info['message'],
               ~~~~~~~~~~~^^^^^^^^^^^
KeyError: 'message'
ERROR 2024-12-09 16:41:55,561 utils wrapper 예기치 못한 오류: 'message'
Traceback (most recent call last):
  File "/home/pi/Desktop/rasp/rfid/utils.py", line 16, in wrapper
    return func(request, *args, **kwargs)
           ^^^^^^^^^^^^^^^^^^^^^^^^^^^^^^
  File "/home/pi/Desktop/rasp/rfid/views_v2.py", line 151, in result
    'message': weight_info['message'],
               ~~~~~~~~~~~^^^^^^^^^^^
KeyError: 'message'
ERROR 2024-12-09 16:41:55,637 utils wrapper 예기치 못한 오류: 'message'
Traceback (most recent call last):
  File "/home/pi/Desktop/rasp/rfid/utils.py", line 16, in wrapper
    return func(request, *args, **kwargs)
           ^^^^^^^^^^^^^^^^^^^^^^^^^^^^^^
  File "/home/pi/Desktop/rasp/rfid/views_v2.py", line 151, in result
    'message': weight_info['message'],
               ~~~~~~~~~~~^^^^^^^^^^^
KeyError: 'message'
ERROR 2024-12-09 16:41:57,711 utils wrapper 예기치 못한 오류: 'message'
Traceback (most recent call last):
  File "/home/pi/Desktop/rasp/rfid/utils.py", line 16, in wrapper
    return func(request, *args, **kwargs)
           ^^^^^^^^^^^^^^^^^^^^^^^^^^^^^^
  File "/home/pi/Desktop/rasp/rfid/views_v2.py", line 151, in result
    'message': weight_info['message'],
               ~~~~~~~~~~~^^^^^^^^^^^
KeyError: 'message'
ERROR 2024-12-09 16:42:23,911 utils wrapper 예기치 못한 오류: 'message'
Traceback (most recent call last):
  File "/home/pi/Desktop/rasp/rfid/utils.py", line 16, in wrapper
    return func(request, *args, **kwargs)
           ^^^^^^^^^^^^^^^^^^^^^^^^^^^^^^
  File "/home/pi/Desktop/rasp/rfid/views_v2.py", line 151, in result
    'message': weight_info['message'],
               ~~~~~~~~~~~^^^^^^^^^^^
KeyError: 'message'
ERROR 2024-12-09 16:42:24,900 utils wrapper 예기치 못한 오류: 'message'
Traceback (most recent call last):
  File "/home/pi/Desktop/rasp/rfid/utils.py", line 16, in wrapper
    return func(request, *args, **kwargs)
           ^^^^^^^^^^^^^^^^^^^^^^^^^^^^^^
  File "/home/pi/Desktop/rasp/rfid/views_v2.py", line 151, in result
    'message': weight_info['message'],
               ~~~~~~~~~~~^^^^^^^^^^^
KeyError: 'message'
ERROR 2024-12-10 07:32:43,468 user_management check_user 사용자를 찾을 수 없음: UID 07 62 D7 63
ERROR 2024-12-10 07:32:59,093 weight update_weight 서버 오류 발생: 유효한 데이터가 수신되지 않았습니다. (Status Code: 404)
ERROR 2024-12-10 07:32:59,167 weight update_weight 서버 오류 발생: 유효한 데이터가 수신되지 않았습니다. (Status Code: 404)
ERROR 2024-12-10 08:16:54,382 weight update_weight 서버 오류 발생: 유효한 데이터가 수신되지 않았습니다. (Status Code: 404)
ERROR 2024-12-10 08:16:54,458 weight update_weight 서버 오류 발생: 유효한 데이터가 수신되지 않았습니다. (Status Code: 404)
ERROR 2024-12-10 08:16:54,532 weight update_weight 서버 오류 발생: 유효한 데이터가 수신되지 않았습니다. (Status Code: 404)
ERROR 2024-12-10 08:17:35,876 weight update_weight 서버 오류 발생: 유효한 데이터가 수신되지 않았습니다. (Status Code: 404)
ERROR 2024-12-10 08:17:35,952 weight update_weight 서버 오류 발생: 유효한 데이터가 수신되지 않았습니다. (Status Code: 404)
ERROR 2024-12-10 08:28:20,060 weight update_weight 서버 오류 발생: 유효한 데이터가 수신되지 않았습니다. (Status Code: 404)
ERROR 2024-12-10 08:28:20,131 weight update_weight 서버 오류 발생: 유효한 데이터가 수신되지 않았습니다. (Status Code: 404)
ERROR 2024-12-10 08:34:55,319 weight update_weight 서버 오류 발생: 유효한 데이터가 수신되지 않았습니다. (Status Code: 404)
ERROR 2024-12-10 08:34:55,388 weight update_weight 서버 오류 발생: 유효한 데이터가 수신되지 않았습니다. (Status Code: 404)
ERROR 2024-12-10 08:35:56,812 weight update_weight 서버 오류 발생: 유효한 데이터가 수신되지 않았습니다. (Status Code: 404)
ERROR 2024-12-10 08:35:56,888 weight update_weight 서버 오류 발생: 유효한 데이터가 수신되지 않았습니다. (Status Code: 404)
ERROR 2024-12-10 08:35:56,965 weight update_weight 서버 오류 발생: 유효한 데이터가 수신되지 않았습니다. (Status Code: 404)
ERROR 2024-12-10 08:36:22,550 weight update_weight 서버 오류 발생: 유효한 데이터가 수신되지 않았습니다. (Status Code: 404)
ERROR 2024-12-10 08:45:06,491 weight update_weight 서버 오류 발생: 유효한 데이터가 수신되지 않았습니다. (Status Code: 404)
ERROR 2024-12-10 08:45:06,542 weight update_weight 서버 오류 발생: 유효한 데이터가 수신되지 않았습니다. (Status Code: 404)
ERROR 2024-12-10 08:45:06,542 weight update_weight 서버 오류 발생: 유효한 데이터가 수신되지 않았습니다. (Status Code: 404)
ERROR 2024-12-10 08:45:07,341 weight update_weight 서버 오류 발생: 유효한 데이터가 수신되지 않았습니다. (Status Code: 404)
ERROR 2024-12-10 08:45:07,416 weight update_weight 서버 오류 발생: 유효한 데이터가 수신되지 않았습니다. (Status Code: 404)
ERROR 2024-12-10 08:45:07,440 weight update_weight 서버 오류 발생: 유효한 데이터가 수신되지 않았습니다. (Status Code: 404)
ERROR 2024-12-10 08:45:52,388 weight update_weight 서버 오류 발생: 유효한 데이터가 수신되지 않았습니다. (Status Code: 404)
ERROR 2024-12-10 08:48:47,024 weight update_weight 서버 오류 발생: 유효한 데이터가 수신되지 않았습니다. (Status Code: 404)
ERROR 2024-12-10 08:48:47,024 weight update_weight 서버 오류 발생: 유효한 데이터가 수신되지 않았습니다. (Status Code: 404)
ERROR 2024-12-10 08:48:47,983 weight update_weight 서버 오류 발생: 유효한 데이터가 수신되지 않았습니다. (Status Code: 404)
ERROR 2024-12-10 08:53:55,144 weight update_weight 서버 오류 발생: 유효한 데이터가 수신되지 않았습니다. (Status Code: 404)
ERROR 2024-12-10 08:53:55,153 weight update_weight 서버 오류 발생: 유효한 데이터가 수신되지 않았습니다. (Status Code: 404)
ERROR 2024-12-10 08:53:55,676 weight update_weight 서버 오류 발생: unsupported operand type(s) for +: 'float' and 'tuple'
ERROR 2024-12-10 08:54:12,877 weight update_weight 서버 오류 발생: unsupported operand type(s) for +: 'float' and 'tuple'
ERROR 2024-12-10 08:54:12,918 weight update_weight 서버 오류 발생: unsupported operand type(s) for +: 'float' and 'tuple'
ERROR 2024-12-10 09:00:28,935 user_management check_user 사용자를 찾을 수 없음: UID 07 62 D7 63
ERROR 2024-12-10 09:00:42,316 weight update_weight 서버 오류 발생: 유효한 데이터가 수신되지 않았습니다. (Status Code: 404)
ERROR 2024-12-10 09:00:42,391 weight update_weight 서버 오류 발생: 유효한 데이터가 수신되지 않았습니다. (Status Code: 404)
ERROR 2024-12-10 09:01:24,428 weight update_weight 서버 오류 발생: 유효한 데이터가 수신되지 않았습니다. (Status Code: 404)
ERROR 2024-12-10 09:01:24,507 weight update_weight 서버 오류 발생: 유효한 데이터가 수신되지 않았습니다. (Status Code: 404)
ERROR 2024-12-10 09:03:15,721 weight update_weight 서버 오류 발생: 유효한 데이터가 수신되지 않았습니다. (Status Code: 404)
ERROR 2024-12-10 09:03:15,797 weight update_weight 서버 오류 발생: 유효한 데이터가 수신되지 않았습니다. (Status Code: 404)
ERROR 2024-12-10 09:05:18,422 weight update_weight 서버 오류 발생: 유효한 데이터가 수신되지 않았습니다. (Status Code: 404)
ERROR 2024-12-10 09:05:18,498 weight update_weight 서버 오류 발생: 유효한 데이터가 수신되지 않았습니다. (Status Code: 404)
ERROR 2024-12-10 09:05:18,591 weight update_weight 서버 오류 발생: 유효한 데이터가 수신되지 않았습니다. (Status Code: 404)
ERROR 2024-12-10 09:05:18,824 weight update_weight 서버 오류 발생: 유효한 데이터가 수신되지 않았습니다. (Status Code: 404)
ERROR 2024-12-10 09:05:18,897 weight update_weight 서버 오류 발생: 유효한 데이터가 수신되지 않았습니다. (Status Code: 404)
ERROR 2024-12-10 09:05:18,977 weight update_weight 서버 오류 발생: 유효한 데이터가 수신되지 않았습니다. (Status Code: 404)
ERROR 2024-12-10 09:06:05,705 weight update_weight 서버 오류 발생: 유효한 데이터가 수신되지 않았습니다. (Status Code: 404)
ERROR 2024-12-10 09:07:48,500 weight update_weight 서버 오류 발생: 유효한 데이터가 수신되지 않았습니다. (Status Code: 404)
ERROR 2024-12-10 09:07:48,521 views_v2 result UID가 전달되지 않았습니다.
ERROR 2024-12-10 09:10:40,317 weight update_weight 서버 오류 발생: 유효한 데이터가 수신되지 않았습니다. (Status Code: 404)
ERROR 2024-12-10 09:10:40,336 views_v2 result UID가 전달되지 않았습니다.
ERROR 2024-12-10 09:10:40,394 weight update_weight 서버 오류 발생: 유효한 데이터가 수신되지 않았습니다. (Status Code: 404)
ERROR 2024-12-10 09:16:12,986 weight update_weight 서버 오류 발생: 유효한 데이터가 수신되지 않았습니다. (Status Code: 404)
ERROR 2024-12-10 09:16:13,058 weight update_weight 서버 오류 발생: 유효한 데이터가 수신되지 않았습니다. (Status Code: 404)
ERROR 2024-12-10 09:16:45,236 weight update_weight 서버 오류 발생: 유효한 데이터가 수신되지 않았습니다. (Status Code: 404)
ERROR 2024-12-10 09:16:45,314 weight update_weight 서버 오류 발생: 유효한 데이터가 수신되지 않았습니다. (Status Code: 404)
ERROR 2024-12-10 09:16:45,392 weight update_weight 서버 오류 발생: 유효한 데이터가 수신되지 않았습니다. (Status Code: 404)
ERROR 2024-12-10 09:23:46,647 user_management check_user 사용자를 찾을 수 없음: UID 07 62 D7 63
ERROR 2024-12-10 09:23:46,800 user_management check_user 사용자를 찾을 수 없음: UID 07 62 D7 63
ERROR 2024-12-10 10:04:31,845 weight update_weight 서버 오류 발생: 유효한 데이터가 수신되지 않았습니다. (Status Code: 404)
ERROR 2024-12-10 10:08:31,487 weight update_weight 서버 오류 발생: unsupported operand type(s) for +: 'float' and 'tuple'
ERROR 2024-12-10 10:08:41,936 weight update_weight 서버 오류 발생: unsupported operand type(s) for +: 'float' and 'tuple'
ERROR 2024-12-10 10:11:21,059 user_management check_user 사용자를 찾을 수 없음: UID 04 49 3C 6A 76 13 91
ERROR 2024-12-10 10:11:28,844 user_management check_user 사용자를 찾을 수 없음: UID 07 62 D7 63
ERROR 2024-12-10 10:11:56,303 weight update_weight 서버 오류 발생: unsupported operand type(s) for +: 'float' and 'tuple'
ERROR 2024-12-10 10:17:43,762 weight update_weight 서버 오류 발생: unsupported operand type(s) for +: 'float' and 'tuple'
ERROR 2024-12-10 10:18:47,503 weight update_weight 서버 오류 발생: unsupported operand type(s) for +: 'decimal.Decimal' and 'tuple'
ERROR 2024-12-10 10:22:17,544 weight update_weight 서버 오류 발생: unsupported operand type(s) for +: 'decimal.Decimal' and 'float'
ERROR 2024-12-10 13:10:04,590 weight update_weight 서버 오류 발생: unsupported operand type(s) for +: 'decimal.Decimal' and 'float'
ERROR 2024-12-10 13:10:11,901 weight update_weight 서버 오류 발생: unsupported operand type(s) for +: 'decimal.Decimal' and 'float'
ERROR 2024-12-10 14:01:13,575 weight update_weight 서버 오류 발생: 유효한 데이터가 수신되지 않았습니다. (Status Code: 404)
ERROR 2024-12-10 14:04:37,835 weight update_weight 서버 오류 발생: 유효한 데이터가 수신되지 않았습니다. (Status Code: 404)
ERROR 2024-12-10 14:10:35,401 user_management check_user 사용자를 찾을 수 없음: UID 04 E3 43 6A 76 13 90
ERROR 2024-12-10 14:10:47,647 user_management check_user 사용자를 찾을 수 없음: UID 07 62 D7 63
ERROR 2024-12-10 14:11:16,646 weight update_weight 서버 오류 발생: 유효한 데이터가 수신되지 않았습니다. (Status Code: 404)
ERROR 2024-12-10 14:35:33,988 weight update_weight 서버 오류 발생: 유효한 데이터가 수신되지 않았습니다. (Status Code: 404)
ERROR 2024-12-16 13:52:34,225 utils wrapper 예기치 못한 오류: MySQL Connection not available.
Traceback (most recent call last):
  File "/home/pi/Desktop/rasp_notouch/rfid/utils.py", line 16, in wrapper
    return func(request, *args, **kwargs)
           ^^^^^^^^^^^^^^^^^^^^^^^^^^^^^^
  File "/home/pi/Desktop/rasp_notouch/rfid/views_v2.py", line 143, in result
    mqtt_publish.publish()
  File "/home/pi/Desktop/rasp_notouch/rfid/mqtt_publish.py", line 28, in publish
    cursor = conn.cursor()
             ^^^^^^^^^^^^^
  File "/home/pi/.local/lib/python3.11/site-packages/mysql/connector/connection_cext.py", line 773, in cursor
    raise OperationalError("MySQL Connection not available.")
mysql.connector.errors.OperationalError: MySQL Connection not available.
ERROR 2024-12-16 13:52:40,495 utils wrapper 예기치 못한 오류: MySQL Connection not available.
Traceback (most recent call last):
  File "/home/pi/Desktop/rasp_notouch/rfid/utils.py", line 16, in wrapper
    return func(request, *args, **kwargs)
           ^^^^^^^^^^^^^^^^^^^^^^^^^^^^^^
  File "/home/pi/Desktop/rasp_notouch/rfid/views_v2.py", line 143, in result
    mqtt_publish.publish()
  File "/home/pi/Desktop/rasp_notouch/rfid/mqtt_publish.py", line 28, in publish
    cursor = conn.cursor()
             ^^^^^^^^^^^^^
  File "/home/pi/.local/lib/python3.11/site-packages/mysql/connector/connection_cext.py", line 773, in cursor
    raise OperationalError("MySQL Connection not available.")
mysql.connector.errors.OperationalError: MySQL Connection not available.
ERROR 2024-12-16 13:52:43,105 utils wrapper 예기치 못한 오류: MySQL Connection not available.
Traceback (most recent call last):
  File "/home/pi/Desktop/rasp_notouch/rfid/utils.py", line 16, in wrapper
    return func(request, *args, **kwargs)
           ^^^^^^^^^^^^^^^^^^^^^^^^^^^^^^
  File "/home/pi/Desktop/rasp_notouch/rfid/views_v2.py", line 143, in result
    mqtt_publish.publish()
  File "/home/pi/Desktop/rasp_notouch/rfid/mqtt_publish.py", line 28, in publish
    cursor = conn.cursor()
             ^^^^^^^^^^^^^
  File "/home/pi/.local/lib/python3.11/site-packages/mysql/connector/connection_cext.py", line 773, in cursor
    raise OperationalError("MySQL Connection not available.")
mysql.connector.errors.OperationalError: MySQL Connection not available.
ERROR 2024-12-16 14:10:27,201 utils wrapper 예기치 못한 오류: MySQL Connection not available.
Traceback (most recent call last):
  File "/home/pi/Desktop/rasp_notouch/rfid/utils.py", line 16, in wrapper
    return func(request, *args, **kwargs)
           ^^^^^^^^^^^^^^^^^^^^^^^^^^^^^^
  File "/home/pi/Desktop/rasp_notouch/rfid/views_v2.py", line 143, in result
    mqtt_publish.publish()
  File "/home/pi/Desktop/rasp_notouch/rfid/mqtt_publish.py", line 28, in publish
    cursor = conn.cursor()
             ^^^^^^^^^^^^^
  File "/home/pi/.local/lib/python3.11/site-packages/mysql/connector/connection_cext.py", line 773, in cursor
    raise OperationalError("MySQL Connection not available.")
mysql.connector.errors.OperationalError: MySQL Connection not available.
ERROR 2024-12-16 14:10:27,720 utils wrapper 예기치 못한 오류: MySQL Connection not available.
Traceback (most recent call last):
  File "/home/pi/Desktop/rasp_notouch/rfid/utils.py", line 16, in wrapper
    return func(request, *args, **kwargs)
           ^^^^^^^^^^^^^^^^^^^^^^^^^^^^^^
  File "/home/pi/Desktop/rasp_notouch/rfid/views_v2.py", line 143, in result
    mqtt_publish.publish()
  File "/home/pi/Desktop/rasp_notouch/rfid/mqtt_publish.py", line 28, in publish
    cursor = conn.cursor()
             ^^^^^^^^^^^^^
  File "/home/pi/.local/lib/python3.11/site-packages/mysql/connector/connection_cext.py", line 773, in cursor
    raise OperationalError("MySQL Connection not available.")
mysql.connector.errors.OperationalError: MySQL Connection not available.
ERROR 2024-12-16 14:10:28,770 utils wrapper 예기치 못한 오류: MySQL Connection not available.
Traceback (most recent call last):
  File "/home/pi/Desktop/rasp_notouch/rfid/utils.py", line 16, in wrapper
    return func(request, *args, **kwargs)
           ^^^^^^^^^^^^^^^^^^^^^^^^^^^^^^
  File "/home/pi/Desktop/rasp_notouch/rfid/views_v2.py", line 143, in result
    mqtt_publish.publish()
  File "/home/pi/Desktop/rasp_notouch/rfid/mqtt_publish.py", line 28, in publish
    cursor = conn.cursor()
             ^^^^^^^^^^^^^
  File "/home/pi/.local/lib/python3.11/site-packages/mysql/connector/connection_cext.py", line 773, in cursor
    raise OperationalError("MySQL Connection not available.")
mysql.connector.errors.OperationalError: MySQL Connection not available.
ERROR 2024-12-16 14:10:41,828 utils wrapper 예기치 못한 오류: MySQL Connection not available.
Traceback (most recent call last):
  File "/home/pi/Desktop/rasp_notouch/rfid/utils.py", line 16, in wrapper
    return func(request, *args, **kwargs)
           ^^^^^^^^^^^^^^^^^^^^^^^^^^^^^^
  File "/home/pi/Desktop/rasp_notouch/rfid/views_v2.py", line 143, in result
    mqtt_publish.publish()
  File "/home/pi/Desktop/rasp_notouch/rfid/mqtt_publish.py", line 28, in publish
    cursor = conn.cursor()
             ^^^^^^^^^^^^^
  File "/home/pi/.local/lib/python3.11/site-packages/mysql/connector/connection_cext.py", line 773, in cursor
    raise OperationalError("MySQL Connection not available.")
mysql.connector.errors.OperationalError: MySQL Connection not available.
ERROR 2024-12-16 14:10:49,144 weight update_weight 서버 오류 발생: 유효한 데이터가 수신되지 않았습니다. (Status Code: 404)
ERROR 2024-12-16 14:10:49,667 utils wrapper 예기치 못한 오류: MySQL Connection not available.
Traceback (most recent call last):
  File "/home/pi/Desktop/rasp_notouch/rfid/utils.py", line 16, in wrapper
    return func(request, *args, **kwargs)
           ^^^^^^^^^^^^^^^^^^^^^^^^^^^^^^
  File "/home/pi/Desktop/rasp_notouch/rfid/views_v2.py", line 143, in result
    mqtt_publish.publish()
  File "/home/pi/Desktop/rasp_notouch/rfid/mqtt_publish.py", line 28, in publish
    cursor = conn.cursor()
             ^^^^^^^^^^^^^
  File "/home/pi/.local/lib/python3.11/site-packages/mysql/connector/connection_cext.py", line 773, in cursor
    raise OperationalError("MySQL Connection not available.")
mysql.connector.errors.OperationalError: MySQL Connection not available.
ERROR 2024-12-16 14:11:12,134 utils wrapper 예기치 못한 오류: MySQL Connection not available.
Traceback (most recent call last):
  File "/home/pi/Desktop/rasp_notouch/rfid/utils.py", line 16, in wrapper
    return func(request, *args, **kwargs)
           ^^^^^^^^^^^^^^^^^^^^^^^^^^^^^^
  File "/home/pi/Desktop/rasp_notouch/rfid/views_v2.py", line 143, in result
    mqtt_publish.publish()
  File "/home/pi/Desktop/rasp_notouch/rfid/mqtt_publish.py", line 28, in publish
    cursor = conn.cursor()
             ^^^^^^^^^^^^^
  File "/home/pi/.local/lib/python3.11/site-packages/mysql/connector/connection_cext.py", line 773, in cursor
    raise OperationalError("MySQL Connection not available.")
mysql.connector.errors.OperationalError: MySQL Connection not available.
ERROR 2024-12-16 14:11:19,436 weight update_weight 서버 오류 발생: 유효한 데이터가 수신되지 않았습니다. (Status Code: 404)
ERROR 2024-12-16 14:11:19,445 weight update_weight 서버 오류 발생: 유효한 데이터가 수신되지 않았습니다. (Status Code: 404)
ERROR 2024-12-16 14:11:20,496 utils wrapper 예기치 못한 오류: MySQL Connection not available.
Traceback (most recent call last):
  File "/home/pi/Desktop/rasp_notouch/rfid/utils.py", line 16, in wrapper
    return func(request, *args, **kwargs)
           ^^^^^^^^^^^^^^^^^^^^^^^^^^^^^^
  File "/home/pi/Desktop/rasp_notouch/rfid/views_v2.py", line 143, in result
    mqtt_publish.publish()
  File "/home/pi/Desktop/rasp_notouch/rfid/mqtt_publish.py", line 28, in publish
    cursor = conn.cursor()
             ^^^^^^^^^^^^^
  File "/home/pi/.local/lib/python3.11/site-packages/mysql/connector/connection_cext.py", line 773, in cursor
    raise OperationalError("MySQL Connection not available.")
mysql.connector.errors.OperationalError: MySQL Connection not available.
ERROR 2024-12-16 14:11:34,604 utils wrapper 예기치 못한 오류: MySQL Connection not available.
Traceback (most recent call last):
  File "/home/pi/Desktop/rasp_notouch/rfid/utils.py", line 16, in wrapper
    return func(request, *args, **kwargs)
           ^^^^^^^^^^^^^^^^^^^^^^^^^^^^^^
  File "/home/pi/Desktop/rasp_notouch/rfid/views_v2.py", line 143, in result
    mqtt_publish.publish()
  File "/home/pi/Desktop/rasp_notouch/rfid/mqtt_publish.py", line 28, in publish
    cursor = conn.cursor()
             ^^^^^^^^^^^^^
  File "/home/pi/.local/lib/python3.11/site-packages/mysql/connector/connection_cext.py", line 773, in cursor
    raise OperationalError("MySQL Connection not available.")
mysql.connector.errors.OperationalError: MySQL Connection not available.
ERROR 2024-12-16 14:11:38,258 utils wrapper 예기치 못한 오류: MySQL Connection not available.
Traceback (most recent call last):
  File "/home/pi/Desktop/rasp_notouch/rfid/utils.py", line 16, in wrapper
    return func(request, *args, **kwargs)
           ^^^^^^^^^^^^^^^^^^^^^^^^^^^^^^
  File "/home/pi/Desktop/rasp_notouch/rfid/views_v2.py", line 143, in result
    mqtt_publish.publish()
  File "/home/pi/Desktop/rasp_notouch/rfid/mqtt_publish.py", line 28, in publish
    cursor = conn.cursor()
             ^^^^^^^^^^^^^
  File "/home/pi/.local/lib/python3.11/site-packages/mysql/connector/connection_cext.py", line 773, in cursor
    raise OperationalError("MySQL Connection not available.")
mysql.connector.errors.OperationalError: MySQL Connection not available.
ERROR 2024-12-16 14:12:25,805 utils wrapper 예기치 못한 오류: MySQL Connection not available.
Traceback (most recent call last):
  File "/home/pi/Desktop/rasp_notouch/rfid/utils.py", line 16, in wrapper
    return func(request, *args, **kwargs)
           ^^^^^^^^^^^^^^^^^^^^^^^^^^^^^^
  File "/home/pi/Desktop/rasp_notouch/rfid/views_v2.py", line 143, in result
    mqtt_publish.publish()
  File "/home/pi/Desktop/rasp_notouch/rfid/mqtt_publish.py", line 28, in publish
    cursor = conn.cursor()
             ^^^^^^^^^^^^^
  File "/home/pi/.local/lib/python3.11/site-packages/mysql/connector/connection_cext.py", line 773, in cursor
    raise OperationalError("MySQL Connection not available.")
mysql.connector.errors.OperationalError: MySQL Connection not available.
ERROR 2024-12-16 15:30:49,259 weight update_weight 서버 오류 발생: 유효한 데이터가 수신되지 않았습니다. (Status Code: 404)
ERROR 2024-12-16 15:31:20,611 utils wrapper 예기치 못한 오류: MySQL Connection not available.
Traceback (most recent call last):
  File "/home/pi/Desktop/rasp_notouch/rfid/utils.py", line 16, in wrapper
    return func(request, *args, **kwargs)
           ^^^^^^^^^^^^^^^^^^^^^^^^^^^^^^
  File "/home/pi/Desktop/rasp_notouch/rfid/views_v2.py", line 143, in result
    mqtt_publish.publish()
  File "/home/pi/Desktop/rasp_notouch/rfid/mqtt_publish.py", line 28, in publish
    cursor = conn.cursor()
             ^^^^^^^^^^^^^
  File "/home/pi/.local/lib/python3.11/site-packages/mysql/connector/connection_cext.py", line 773, in cursor
    raise OperationalError("MySQL Connection not available.")
mysql.connector.errors.OperationalError: MySQL Connection not available.
ERROR 2024-12-16 15:31:29,494 weight update_weight 서버 오류 발생: 유효한 데이터가 수신되지 않았습니다. (Status Code: 404)
ERROR 2024-12-16 15:31:30,017 utils wrapper 예기치 못한 오류: MySQL Connection not available.
Traceback (most recent call last):
  File "/home/pi/Desktop/rasp_notouch/rfid/utils.py", line 16, in wrapper
    return func(request, *args, **kwargs)
           ^^^^^^^^^^^^^^^^^^^^^^^^^^^^^^
  File "/home/pi/Desktop/rasp_notouch/rfid/views_v2.py", line 143, in result
    mqtt_publish.publish()
  File "/home/pi/Desktop/rasp_notouch/rfid/mqtt_publish.py", line 28, in publish
    cursor = conn.cursor()
             ^^^^^^^^^^^^^
  File "/home/pi/.local/lib/python3.11/site-packages/mysql/connector/connection_cext.py", line 773, in cursor
    raise OperationalError("MySQL Connection not available.")
mysql.connector.errors.OperationalError: MySQL Connection not available.
ERROR 2024-12-16 15:31:37,854 utils wrapper 예기치 못한 오류: MySQL Connection not available.
Traceback (most recent call last):
  File "/home/pi/Desktop/rasp_notouch/rfid/utils.py", line 16, in wrapper
    return func(request, *args, **kwargs)
           ^^^^^^^^^^^^^^^^^^^^^^^^^^^^^^
  File "/home/pi/Desktop/rasp_notouch/rfid/views_v2.py", line 143, in result
    mqtt_publish.publish()
  File "/home/pi/Desktop/rasp_notouch/rfid/mqtt_publish.py", line 28, in publish
    cursor = conn.cursor()
             ^^^^^^^^^^^^^
  File "/home/pi/.local/lib/python3.11/site-packages/mysql/connector/connection_cext.py", line 773, in cursor
    raise OperationalError("MySQL Connection not available.")
mysql.connector.errors.OperationalError: MySQL Connection not available.
ERROR 2024-12-16 15:31:38,900 utils wrapper 예기치 못한 오류: MySQL Connection not available.
Traceback (most recent call last):
  File "/home/pi/Desktop/rasp_notouch/rfid/utils.py", line 16, in wrapper
    return func(request, *args, **kwargs)
           ^^^^^^^^^^^^^^^^^^^^^^^^^^^^^^
  File "/home/pi/Desktop/rasp_notouch/rfid/views_v2.py", line 143, in result
    mqtt_publish.publish()
  File "/home/pi/Desktop/rasp_notouch/rfid/mqtt_publish.py", line 28, in publish
    cursor = conn.cursor()
             ^^^^^^^^^^^^^
  File "/home/pi/.local/lib/python3.11/site-packages/mysql/connector/connection_cext.py", line 773, in cursor
    raise OperationalError("MySQL Connection not available.")
mysql.connector.errors.OperationalError: MySQL Connection not available.
ERROR 2024-12-16 15:33:44,773 weight update_weight 서버 오류 발생: 유효한 데이터가 수신되지 않았습니다. (Status Code: 404)
ERROR 2024-12-17 16:07:30,692 weight update_weight 서버 오류 발생: 유효한 데이터가 수신되지 않았습니다. (Status Code: 404)
ERROR 2024-12-20 11:43:34,360 weight update_weight 서버 오류 발생: 유효한 데이터가 수신되지 않았습니다. (Status Code: 484)
ERROR 2024-12-20 11:43:43,246 weight update_weight 서버 오류 발생: 유효한 데이터가 수신되지 않았습니다. (Status Code: 484)
ERROR 2024-12-20 11:43:52,125 weight update_weight 서버 오류 발생: 유효한 데이터가 수신되지 않았습니다. (Status Code: 484)
ERROR 2024-12-20 11:44:01,007 weight update_weight 서버 오류 발생: 유효한 데이터가 수신되지 않았습니다. (Status Code: 484)
ERROR 2024-12-20 11:44:09,893 weight update_weight 서버 오류 발생: 유효한 데이터가 수신되지 않았습니다. (Status Code: 484)
ERROR 2024-12-20 11:44:34,972 weight update_weight 서버 오류 발생: 유효한 데이터가 수신되지 않았습니다. (Status Code: 484)
ERROR 2024-12-20 11:44:43,852 weight update_weight 서버 오류 발생: 유효한 데이터가 수신되지 않았습니다. (Status Code: 484)
ERROR 2024-12-20 11:44:52,734 weight update_weight 서버 오류 발생: 유효한 데이터가 수신되지 않았습니다. (Status Code: 484)
ERROR 2024-12-20 11:46:55,965 weight update_weight 서버 오류 발생: 유효한 데이터가 수신되지 않았습니다. (Status Code: 484)
ERROR 2024-12-20 11:46:59,622 weight update_weight 서버 오류 발생: 유효한 데이터가 수신되지 않았습니다. (Status Code: 484)
ERROR 2024-12-20 11:47:04,850 weight update_weight 서버 오류 발생: 유효한 데이터가 수신되지 않았습니다. (Status Code: 484)
ERROR 2024-12-20 11:47:06,937 weight update_weight 서버 오류 발생: 유효한 데이터가 수신되지 않았습니다. (Status Code: 484)
ERROR 2024-12-20 11:47:13,207 weight update_weight 서버 오류 발생: 유효한 데이터가 수신되지 않았습니다. (Status Code: 484)
ERROR 2024-12-20 11:47:15,822 weight update_weight 서버 오류 발생: 유효한 데이터가 수신되지 않았습니다. (Status Code: 484)
ERROR 2024-12-20 11:47:22,092 weight update_weight 서버 오류 발생: 유효한 데이터가 수신되지 않았습니다. (Status Code: 484)
ERROR 2024-12-20 11:47:24,702 weight update_weight 서버 오류 발생: 유효한 데이터가 수신되지 않았습니다. (Status Code: 484)
ERROR 2024-12-20 11:47:30,972 weight update_weight 서버 오류 발생: 유효한 데이터가 수신되지 않았습니다. (Status Code: 484)
ERROR 2024-12-20 11:47:33,584 weight update_weight 서버 오류 발생: 유효한 데이터가 수신되지 않았습니다. (Status Code: 484)
ERROR 2024-12-20 11:47:39,335 weight update_weight 서버 오류 발생: 유효한 데이터가 수신되지 않았습니다. (Status Code: 484)
ERROR 2024-12-20 11:47:42,470 weight update_weight 서버 오류 발생: 유효한 데이터가 수신되지 않았습니다. (Status Code: 484)
ERROR 2024-12-20 11:47:48,214 weight update_weight 서버 오류 발생: 유효한 데이터가 수신되지 않았습니다. (Status Code: 484)
ERROR 2024-12-20 11:47:51,349 weight update_weight 서버 오류 발생: 유효한 데이터가 수신되지 않았습니다. (Status Code: 484)
ERROR 2024-12-20 11:47:57,096 weight update_weight 서버 오류 발생: 유효한 데이터가 수신되지 않았습니다. (Status Code: 484)
ERROR 2024-12-20 11:48:00,754 weight update_weight 서버 오류 발생: 유효한 데이터가 수신되지 않았습니다. (Status Code: 484)
ERROR 2024-12-20 11:48:05,456 weight update_weight 서버 오류 발생: 유효한 데이터가 수신되지 않았습니다. (Status Code: 484)
ERROR 2024-12-20 11:48:09,638 weight update_weight 서버 오류 발생: 유효한 데이터가 수신되지 않았습니다. (Status Code: 484)
ERROR 2024-12-20 11:48:13,821 weight update_weight 서버 오류 발생: 유효한 데이터가 수신되지 않았습니다. (Status Code: 484)
ERROR 2024-12-20 13:04:20,385 weight update_weight 서버 오류 발생: 유효한 데이터가 수신되지 않았습니다. (Status Code: 484)
ERROR 2024-12-20 13:11:20,989 weight update_weight 서버 오류 발생: 유효한 데이터가 수신되지 않았습니다. (Status Code: 484)
ERROR 2024-12-20 15:33:13,935 weight update_weight 서버 오류 발생: 유효한 데이터가 수신되지 않았습니다. (Status Code: 484)
ERROR 2024-12-20 15:33:19,163 weight update_weight 서버 오류 발생: 유효한 데이터가 수신되지 않았습니다. (Status Code: 484)
ERROR 2024-12-20 15:33:22,818 weight update_weight 서버 오류 발생: 유효한 데이터가 수신되지 않았습니다. (Status Code: 484)
ERROR 2024-12-20 15:33:28,043 weight update_weight 서버 오류 발생: 유효한 데이터가 수신되지 않았습니다. (Status Code: 484)
ERROR 2024-12-20 15:33:31,703 weight update_weight 서버 오류 발생: 유효한 데이터가 수신되지 않았습니다. (Status Code: 484)
ERROR 2024-12-20 15:33:36,925 weight update_weight 서버 오류 발생: 유효한 데이터가 수신되지 않았습니다. (Status Code: 484)
ERROR 2024-12-20 15:34:11,932 weight update_weight 서버 오류 발생: 유효한 데이터가 수신되지 않았습니다. (Status Code: 484)
ERROR 2024-12-20 15:34:20,814 weight update_weight 서버 오류 발생: 유효한 데이터가 수신되지 않았습니다. (Status Code: 484)
ERROR 2024-12-20 15:34:29,699 weight update_weight 서버 오류 발생: 유효한 데이터가 수신되지 않았습니다. (Status Code: 484)
ERROR 2024-12-20 15:34:38,579 weight update_weight 서버 오류 발생: 유효한 데이터가 수신되지 않았습니다. (Status Code: 484)
ERROR 2024-12-20 15:34:47,461 weight update_weight 서버 오류 발생: 유효한 데이터가 수신되지 않았습니다. (Status Code: 484)
ERROR 2024-12-20 15:37:43,018 weight update_weight 서버 오류 발생: 유효한 데이터가 수신되지 않았습니다. (Status Code: 484)
ERROR 2024-12-20 15:37:51,905 weight update_weight 서버 오류 발생: 유효한 데이터가 수신되지 않았습니다. (Status Code: 484)
ERROR 2024-12-20 15:38:01,828 weight update_weight 서버 오류 발생: 유효한 데이터가 수신되지 않았습니다. (Status Code: 484)
ERROR 2024-12-20 15:38:10,713 weight update_weight 서버 오류 발생: 유효한 데이터가 수신되지 않았습니다. (Status Code: 484)
ERROR 2024-12-20 15:46:21,851 weight update_weight 서버 오류 발생: 유효한 데이터가 수신되지 않았습니다. (Status Code: 484)
ERROR 2024-12-20 15:48:59,121 weight update_weight 서버 오류 발생: 유효한 데이터가 수신되지 않았습니다. (Status Code: 484)
ERROR 2024-12-20 16:05:28,398 weight update_weight 서버 오류 발생: 유효한 데이터가 수신되지 않았습니다. (Status Code: 484)
ERROR 2024-12-20 16:06:41,549 weight update_weight 서버 오류 발생: 유효한 데이터가 수신되지 않았습니다. (Status Code: 484)
ERROR 2024-12-20 16:06:42,591 weight update_weight 서버 오류 발생: 유효한 데이터가 수신되지 않았습니다. (Status Code: 484)
ERROR 2024-12-20 16:06:51,473 weight update_weight 서버 오류 발생: 유효한 데이터가 수신되지 않았습니다. (Status Code: 484)
ERROR 2024-12-20 16:06:51,996 weight update_weight 서버 오류 발생: 유효한 데이터가 수신되지 않았습니다. (Status Code: 484)
ERROR 2024-12-20 16:27:48,540 weight update_weight 서버 오류 발생: name 'get_weight_v2' is not defined
ERROR 2024-12-20 16:27:56,938 weight update_weight 서버 오류 발생: name 'get_weight_v2' is not defined
ERROR 2024-12-20 16:28:06,920 weight update_weight 서버 오류 발생: name 'get_weight_v2' is not defined
ERROR 2024-12-20 16:28:18,369 weight update_weight 서버 오류 발생: 유효한 데이터가 수신되지 않았습니다. (Status Code: 484)
ERROR 2024-12-20 16:28:27,254 weight update_weight 서버 오류 발생: 유효한 데이터가 수신되지 않았습니다. (Status Code: 484)
ERROR 2024-12-20 16:28:38,746 weight update_weight 서버 오류 발생: 유효한 데이터가 수신되지 않았습니다. (Status Code: 484)
ERROR 2024-12-20 16:28:45,538 weight update_weight 서버 오류 발생: 유효한 데이터가 수신되지 않았습니다. (Status Code: 484)
ERROR 2024-12-20 16:28:54,421 weight update_weight 서버 오류 발생: 유효한 데이터가 수신되지 않았습니다. (Status Code: 484)
ERROR 2024-12-20 16:29:04,348 weight update_weight 서버 오류 발생: 유효한 데이터가 수신되지 않았습니다. (Status Code: 484)
ERROR 2024-12-20 16:29:15,320 weight update_weight 서버 오류 발생: 유효한 데이터가 수신되지 않았습니다. (Status Code: 484)
ERROR 2024-12-20 16:29:26,293 weight update_weight 서버 오류 발생: 유효한 데이터가 수신되지 않았습니다. (Status Code: 484)
ERROR 2024-12-20 16:29:37,265 weight update_weight 서버 오류 발생: 유효한 데이터가 수신되지 않았습니다. (Status Code: 484)
ERROR 2024-12-20 16:29:48,237 weight update_weight 서버 오류 발생: 유효한 데이터가 수신되지 않았습니다. (Status Code: 484)
ERROR 2024-12-20 16:29:59,210 weight update_weight 서버 오류 발생: 유효한 데이터가 수신되지 않았습니다. (Status Code: 484)
ERROR 2025-01-04 10:18:21,567 weight update_weight 서버 오류 발생: 유효한 데이터가 수신되지 않았습니다. (Status Code: 484)
ERROR 2025-01-04 10:43:31,192 user_management add_user 사용자 추가 오류: 이미 등록된 사용자입니다. (Status Code: 409)
ERROR 2025-01-04 10:44:16,043 user_management check_user 사용자를 찾을 수 없음: UID DF 78 1A 82
ERROR 2025-01-08 10:32:56,907 user_management add_user 사용자 추가 오류: 이미 등록된 사용자입니다. (Status Code: 409)
ERROR 2025-01-16 15:02:18,271 weight update_weight 서버 오류 발생: 유효한 데이터가 수신되지 않았습니다. (Status Code: 484)
ERROR 2025-01-20 15:43:02,829 user_management add_user 사용자 추가 오류: 이미 등록된 사용자입니다. (Status Code: 409)
ERROR 2025-01-20 15:43:57,056 user_management add_user_v2 사용자 추가 오류: Cannot assign "'D0_KY'": "User_v2.asgn_cd" must be a "Weight_v2" instance.
ERROR 2025-01-20 15:44:07,348 user_management add_user_v2 사용자 추가 오류: Cannot assign "'D0_KY'": "User_v2.asgn_cd" must be a "Weight_v2" instance.
ERROR 2025-01-20 15:51:55,281 user_management add_user_v2 사용자 추가 오류: Cannot assign "'D0_KY'": "User_v2.asgn_cd" must be a "Weight_v2" instance.
ERROR 2025-01-20 16:20:54,293 user_management add_user_v2 사용자 추가 오류: Cannot assign "'D0_KY'": "User_v2.asgn_cd" must be a "Weight_v2" instance.
ERROR 2025-01-20 16:21:22,970 user_management add_user_v2 사용자 추가 오류: Weight_v2() got unexpected keyword arguments: 'company'
ERROR 2025-01-20 16:21:45,845 user_management add_user_v2 사용자 추가 오류: Cannot assign "'D0_KY'": "User_v2.asgn_cd" must be a "Weight_v2" instance.
ERROR 2025-01-20 16:22:21,325 user_management add_user_v2 사용자 추가 오류: Cannot assign "'D0_KY'": "User_v2.asgn_cd" must be a "Weight_v2" instance.
ERROR 2025-01-20 16:47:19,731 user_management add_user_v2 사용자 추가 오류: 관리자 비밀번호가 잘못되었습니다. (Status Code: 403)
ERROR 2025-01-20 16:54:22,858 user_management add_user_v2 사용자 추가 오류: Cannot assign "'D0_KY'": "User_v2.asgn_cd" must be a "Weight_v2" instance.
ERROR 2025-01-20 16:54:37,684 user_management add_user_v2 사용자 추가 오류: Cannot assign "'D0_KY'": "User_v2.asgn_cd" must be a "Weight_v2" instance.
ERROR 2025-01-20 16:54:46,079 user_management add_user_v2 사용자 추가 오류: Cannot assign "'D0_KY'": "User_v2.asgn_cd" must be a "Weight_v2" instance.
ERROR 2025-01-20 16:54:55,904 user_management add_user_v2 사용자 추가 오류: Cannot assign "'D0_KY'": "User_v2.asgn_cd" must be a "Weight_v2" instance.
ERROR 2025-01-20 16:56:53,095 user_management add_user_v2 사용자 추가 오류: Cannot assign "'D0_KY'": "User_v2.asgn_cd" must be a "Weight_v2" instance.
ERROR 2025-01-21 07:26:41,089 user_management add_user_v2 사용자 추가 오류: Cannot assign "'D0_KY'": "User_v2.asgn_cd" must be a "Weight_v2" instance.
ERROR 2025-01-21 07:26:51,626 user_management add_user_v2 사용자 추가 오류: (1054, "Unknown column 'asgn_cd_id' in 'field list'")
ERROR 2025-01-21 07:27:02,686 user_management add_user_v2 사용자 추가 오류: (1054, "Unknown column 'asgn_cd_id' in 'field list'")
ERROR 2025-01-21 07:33:30,570 utils wrapper 예기치 못한 오류: 'User_v2' object has no attribute 'company'
Traceback (most recent call last):
  File "/home/pi/Desktop/rasp_notouch/rfid/utils.py", line 16, in wrapper
    return func(request, *args, **kwargs)
           ^^^^^^^^^^^^^^^^^^^^^^^^^^^^^^
  File "/home/pi/Desktop/rasp_notouch/rfid/views_v2.py", line 141, in result
    company = user.company
              ^^^^^^^^^^^^
AttributeError: 'User_v2' object has no attribute 'company'
ERROR 2025-01-21 07:33:30,727 utils wrapper 예기치 못한 오류: 'User_v2' object has no attribute 'company'
Traceback (most recent call last):
  File "/home/pi/Desktop/rasp_notouch/rfid/utils.py", line 16, in wrapper
    return func(request, *args, **kwargs)
           ^^^^^^^^^^^^^^^^^^^^^^^^^^^^^^
  File "/home/pi/Desktop/rasp_notouch/rfid/views_v2.py", line 141, in result
    company = user.company
              ^^^^^^^^^^^^
AttributeError: 'User_v2' object has no attribute 'company'
ERROR 2025-01-21 07:33:36,900 utils wrapper 예기치 못한 오류: 'User_v2' object has no attribute 'company'
Traceback (most recent call last):
  File "/home/pi/Desktop/rasp_notouch/rfid/utils.py", line 16, in wrapper
    return func(request, *args, **kwargs)
           ^^^^^^^^^^^^^^^^^^^^^^^^^^^^^^
  File "/home/pi/Desktop/rasp_notouch/rfid/views_v2.py", line 141, in result
    company = user.company
              ^^^^^^^^^^^^
AttributeError: 'User_v2' object has no attribute 'company'
ERROR 2025-01-21 07:33:37,934 utils wrapper 예기치 못한 오류: 'User_v2' object has no attribute 'company'
Traceback (most recent call last):
  File "/home/pi/Desktop/rasp_notouch/rfid/utils.py", line 16, in wrapper
    return func(request, *args, **kwargs)
           ^^^^^^^^^^^^^^^^^^^^^^^^^^^^^^
  File "/home/pi/Desktop/rasp_notouch/rfid/views_v2.py", line 141, in result
    company = user.company
              ^^^^^^^^^^^^
AttributeError: 'User_v2' object has no attribute 'company'
ERROR 2025-01-21 07:33:42,322 utils wrapper 예기치 못한 오류: 'User_v2' object has no attribute 'company'
Traceback (most recent call last):
  File "/home/pi/Desktop/rasp_notouch/rfid/utils.py", line 16, in wrapper
    return func(request, *args, **kwargs)
           ^^^^^^^^^^^^^^^^^^^^^^^^^^^^^^
  File "/home/pi/Desktop/rasp_notouch/rfid/views_v2.py", line 141, in result
    company = user.company
              ^^^^^^^^^^^^
AttributeError: 'User_v2' object has no attribute 'company'
ERROR 2025-01-21 07:33:45,231 utils wrapper 예기치 못한 오류: 'User_v2' object has no attribute 'company'
Traceback (most recent call last):
  File "/home/pi/Desktop/rasp_notouch/rfid/utils.py", line 16, in wrapper
    return func(request, *args, **kwargs)
           ^^^^^^^^^^^^^^^^^^^^^^^^^^^^^^
  File "/home/pi/Desktop/rasp_notouch/rfid/views_v2.py", line 141, in result
    company = user.company
              ^^^^^^^^^^^^
AttributeError: 'User_v2' object has no attribute 'company'
ERROR 2025-01-21 07:33:45,499 utils wrapper 예기치 못한 오류: DigitalOutputDevice is closed or uninitialized
Traceback (most recent call last):
  File "/usr/lib/python3/dist-packages/gpiozero/output_devices.py", line 87, in _write
    self.pin.state = self._value_to_state(value)
    ^^^^^^^^^^^^^^
AttributeError: 'NoneType' object has no attribute 'state'

During handling of the above exception, another exception occurred:

Traceback (most recent call last):
  File "/usr/lib/python3/dist-packages/gpiozero/devices.py", line 584, in _check_open
    super()._check_open()
  File "/usr/lib/python3/dist-packages/gpiozero/devices.py", line 213, in _check_open
    raise DeviceClosed(
gpiozero.exc.DeviceClosed: DigitalOutputDevice is closed or uninitialized

During handling of the above exception, another exception occurred:

Traceback (most recent call last):
  File "/home/pi/Desktop/rasp_notouch/rfid/utils.py", line 16, in wrapper
    return func(request, *args, **kwargs)
           ^^^^^^^^^^^^^^^^^^^^^^^^^^^^^^
  File "/home/pi/Desktop/rasp_notouch/rfid/views_v2.py", line 77, in homePage
    lock.on()  # 잠금 장치 닫기
    ^^^^^^^^^
  File "/usr/lib/python3/dist-packages/gpiozero/output_devices.py", line 210, in on
    self._write(True)
  File "/usr/lib/python3/dist-packages/gpiozero/output_devices.py", line 89, in _write
    self._check_open()
  File "/usr/lib/python3/dist-packages/gpiozero/devices.py", line 587, in _check_open
    raise GPIODeviceClosed(str(e))
gpiozero.exc.GPIODeviceClosed: DigitalOutputDevice is closed or uninitialized
ERROR 2025-01-21 07:46:56,636 user_management add_user 사용자 추가 오류: 이미 등록된 사용자입니다. (Status Code: 409)
ERROR 2025-01-21 08:34:31,411 utils wrapper 예기치 못한 오류: DigitalOutputDevice is closed or uninitialized
Traceback (most recent call last):
  File "/usr/lib/python3/dist-packages/gpiozero/output_devices.py", line 87, in _write
    self.pin.state = self._value_to_state(value)
    ^^^^^^^^^^^^^^
AttributeError: 'NoneType' object has no attribute 'state'

During handling of the above exception, another exception occurred:

Traceback (most recent call last):
  File "/usr/lib/python3/dist-packages/gpiozero/devices.py", line 584, in _check_open
    super()._check_open()
  File "/usr/lib/python3/dist-packages/gpiozero/devices.py", line 213, in _check_open
    raise DeviceClosed(
gpiozero.exc.DeviceClosed: DigitalOutputDevice is closed or uninitialized

During handling of the above exception, another exception occurred:

Traceback (most recent call last):
  File "/home/pi/Desktop/rasp_notouch/rfid/utils.py", line 16, in wrapper
    return func(request, *args, **kwargs)
           ^^^^^^^^^^^^^^^^^^^^^^^^^^^^^^
  File "/home/pi/Desktop/rasp_notouch/rfid/views_v2.py", line 77, in homePage
    lock.on()  # 잠금 장치 닫기
    ^^^^^^^^^
  File "/usr/lib/python3/dist-packages/gpiozero/output_devices.py", line 210, in on
    self._write(True)
  File "/usr/lib/python3/dist-packages/gpiozero/output_devices.py", line 89, in _write
    self._check_open()
  File "/usr/lib/python3/dist-packages/gpiozero/devices.py", line 587, in _check_open
    raise GPIODeviceClosed(str(e))
gpiozero.exc.GPIODeviceClosed: DigitalOutputDevice is closed or uninitialized
ERROR 2025-02-03 10:43:23,885 weight update_weight 서버 오류 발생: 유효한 데이터가 수신되지 않았습니다. (Status Code: 484)
ERROR 2025-02-03 11:18:16,780 user_management check_user 사용자를 찾을 수 없음: UID 2D 9B 8E2 FB
ERROR 2025-02-03 11:18:22,193 user_management check_user 사용자를 찾을 수 없음: UID 2D 9B 8E2 FB
ERROR 2025-02-03 11:18:27,570 user_management check_user 사용자를 찾을 수 없음: UID 2D 9B 8E2 FB
ERROR 2025-02-03 11:18:32,927 user_management check_user 사용자를 찾을 수 없음: UID 2D 9B 8E2 FB
ERROR 2025-02-03 11:18:37,365 user_management check_user 사용자를 찾을 수 없음: UID 2D 9B 8E2 FB
ERROR 2025-02-12 09:29:27,026 user_management add_user 사용자 추가 오류: 이미 등록된 사용자입니다. (Status Code: 409)
ERROR 2025-02-12 09:33:18,045 user_management add_user 사용자 추가 오류: Cannot assign "<Weight_v3: D0_KY: 0.0kg>": "User_v3.asgn_cd" must be a "Weight_v2" instance.
ERROR 2025-02-12 09:33:44,333 user_management add_user 사용자 추가 오류: Cannot assign "<Weight_v3: D0_KY: 0.00kg>": "User_v3.asgn_cd" must be a "Weight_v2" instance.
ERROR 2025-02-12 14:31:10,480 utils wrapper 예기치 못한 오류: DigitalOutputDevice is closed or uninitialized
Traceback (most recent call last):
  File "/usr/lib/python3/dist-packages/gpiozero/output_devices.py", line 87, in _write
    self.pin.state = self._value_to_state(value)
    ^^^^^^^^^^^^^^
AttributeError: 'NoneType' object has no attribute 'state'

During handling of the above exception, another exception occurred:

Traceback (most recent call last):
  File "/usr/lib/python3/dist-packages/gpiozero/devices.py", line 584, in _check_open
    super()._check_open()
  File "/usr/lib/python3/dist-packages/gpiozero/devices.py", line 213, in _check_open
    raise DeviceClosed(
gpiozero.exc.DeviceClosed: DigitalOutputDevice is closed or uninitialized

During handling of the above exception, another exception occurred:

Traceback (most recent call last):
  File "/home/pi/Desktop/rasp_notouch/rfid/utils.py", line 16, in wrapper
    return func(request, *args, **kwargs)
           ^^^^^^^^^^^^^^^^^^^^^^^^^^^^^^
  File "/home/pi/Desktop/rasp_notouch/rfid/views_v2.py", line 77, in homePage
    lock.on()  # 잠금 장치 닫기
    ^^^^^^^^^
  File "/usr/lib/python3/dist-packages/gpiozero/output_devices.py", line 210, in on
    self._write(True)
  File "/usr/lib/python3/dist-packages/gpiozero/output_devices.py", line 89, in _write
    self._check_open()
  File "/usr/lib/python3/dist-packages/gpiozero/devices.py", line 587, in _check_open
    raise GPIODeviceClosed(str(e))
gpiozero.exc.GPIODeviceClosed: DigitalOutputDevice is closed or uninitialized
ERROR 2025-02-12 15:25:26,533 utils wrapper 예기치 못한 오류: name 'Weight' is not defined
Traceback (most recent call last):
  File "/home/pi/Desktop/rasp_notouch/rfid/weight.py", line 93, in update_weight
    disposal_weight = get_weight_v2() # 저울에서 받아온
                      ^^^^^^^^^^^^^^^
  File "/home/pi/Desktop/rasp_notouch/rfid/weight.py", line 67, in get_weight_v2
    raise CustomException("유효한 데이터가 수신되지 않았습니다.", status_code=484)
rfid.exceptions.CustomException: 유효한 데이터가 수신되지 않았습니다. (Status Code: 484)

During handling of the above exception, another exception occurred:

Traceback (most recent call last):
  File "/home/pi/Desktop/rasp_notouch/rfid/utils.py", line 16, in wrapper
    return func(request, *args, **kwargs)
           ^^^^^^^^^^^^^^^^^^^^^^^^^^^^^^
  File "/home/pi/Desktop/rasp_notouch/rfid/views_v2.py", line 148, in result
    weight_info = weight.update_weight(company, name)
                  ^^^^^^^^^^^^^^^^^^^^^^^^^^^^^^^^^^^
  File "/home/pi/Desktop/rasp_notouch/rfid/weight.py", line 103, in update_weight
    except Weight.DoesNotExist:
           ^^^^^^
NameError: name 'Weight' is not defined
ERROR 2025-02-21 13:35:12,380 user_management check_user 사용자를 찾을 수 없음: UID 04 E3 43 6A 76 13 90
ERROR 2025-02-21 13:35:17,707 user_management check_user 사용자를 찾을 수 없음: UID 04 E3 43 6A 76 13 90
ERROR 2025-02-21 13:35:27,897 user_management check_user 사용자를 찾을 수 없음: UID 4F B8 1B 82
ERROR 2025-02-21 13:35:33,088 user_management check_user 사용자를 찾을 수 없음: UID 8F 56 0C 82
ERROR 2025-02-21 13:36:06,301 user_management check_user 사용자를 찾을 수 없음: UID 4F B8 1B 82
ERROR 2025-02-21 15:49:00,729 weight update_weight 서버 오류 발생: 유효한 데이터가 수신되지 않았습니다. (Status Code: 484)
ERROR 2025-02-21 15:49:23,199 weight update_weight 서버 오류 발생: 유효한 데이터가 수신되지 않았습니다. (Status Code: 484)
ERROR 2025-02-21 15:50:40,005 weight update_weight 서버 오류 발생: 유효한 데이터가 수신되지 않았습니다. (Status Code: 484)
ERROR 2025-02-21 15:51:22,326 weight update_weight 서버 오류 발생: 유효한 데이터가 수신되지 않았습니다. (Status Code: 484)
ERROR 2025-02-21 15:51:41,656 weight update_weight 서버 오류 발생: 유효한 데이터가 수신되지 않았습니다. (Status Code: 484)
ERROR 2025-02-21 15:51:48,448 weight update_weight 서버 오류 발생: 유효한 데이터가 수신되지 않았습니다. (Status Code: 484)
ERROR 2025-02-21 15:52:15,095 weight update_weight 서버 오류 발생: 유효한 데이터가 수신되지 않았습니다. (Status Code: 484)
ERROR 2025-02-21 15:52:22,933 weight update_weight 서버 오류 발생: 유효한 데이터가 수신되지 않았습니다. (Status Code: 484)
ERROR 2025-02-21 15:52:49,013 weight update_weight 서버 오류 발생: 유효한 데이터가 수신되지 않았습니다. (Status Code: 484)
ERROR 2025-02-21 15:52:57,942 weight update_weight 서버 오류 발생: 유효한 데이터가 수신되지 않았습니다. (Status Code: 484)
ERROR 2025-02-21 15:53:30,859 weight update_weight 서버 오류 발생: 유효한 데이터가 수신되지 않았습니다. (Status Code: 484)
ERROR 2025-02-21 15:54:19,451 weight update_weight 서버 오류 발생: 유효한 데이터가 수신되지 않았습니다. (Status Code: 484)
ERROR 2025-02-21 15:54:35,126 weight update_weight 서버 오류 발생: 유효한 데이터가 수신되지 않았습니다. (Status Code: 484)
ERROR 2025-02-21 15:56:03,424 weight update_weight 서버 오류 발생: 유효한 데이터가 수신되지 않았습니다. (Status Code: 484)
ERROR 2025-02-21 15:56:30,071 weight update_weight 서버 오류 발생: 유효한 데이터가 수신되지 않았습니다. (Status Code: 484)
ERROR 2025-02-21 15:56:37,389 weight update_weight 서버 오류 발생: 유효한 데이터가 수신되지 않았습니다. (Status Code: 484)
ERROR 2025-02-21 15:58:17,707 weight update_weight 서버 오류 발생: 유효한 데이터가 수신되지 않았습니다. (Status Code: 484)
ERROR 2025-02-21 15:58:44,354 weight update_weight 서버 오류 발생: 유효한 데이터가 수신되지 않았습니다. (Status Code: 484)
ERROR 2025-02-21 15:59:03,163 weight update_weight 서버 오류 발생: 유효한 데이터가 수신되지 않았습니다. (Status Code: 484)
ERROR 2025-02-21 15:59:10,475 weight update_weight 서버 오류 발생: 유효한 데이터가 수신되지 않았습니다. (Status Code: 484)
ERROR 2025-02-21 16:00:07,430 weight update_weight 서버 오류 발생: 유효한 데이터가 수신되지 않았습니다. (Status Code: 484)
ERROR 2025-02-21 16:00:25,714 weight update_weight 서버 오류 발생: 유효한 데이터가 수신되지 않았습니다. (Status Code: 484)
ERROR 2025-02-21 16:02:13,347 weight update_weight 서버 오류 발생: 유효한 데이터가 수신되지 않았습니다. (Status Code: 484)
ERROR 2025-02-21 16:02:48,879 weight update_weight 서버 오류 발생: 유효한 데이터가 수신되지 않았습니다. (Status Code: 484)
ERROR 2025-02-21 16:03:29,108 weight update_weight 서버 오류 발생: 유효한 데이터가 수신되지 않았습니다. (Status Code: 484)
ERROR 2025-02-21 16:04:33,900 weight update_weight 서버 오류 발생: 유효한 데이터가 수신되지 않았습니다. (Status Code: 484)
ERROR 2025-02-21 16:05:03,682 weight update_weight 서버 오류 발생: 유효한 데이터가 수신되지 않았습니다. (Status Code: 484)
ERROR 2025-02-21 16:05:31,900 weight update_weight 서버 오류 발생: 유효한 데이터가 수신되지 않았습니다. (Status Code: 484)
ERROR 2025-02-21 16:06:05,333 weight update_weight 서버 오류 발생: 유효한 데이터가 수신되지 않았습니다. (Status Code: 484)
ERROR 2025-02-21 16:06:28,845 weight update_weight 서버 오류 발생: 유효한 데이터가 수신되지 않았습니다. (Status Code: 484)
ERROR 2025-02-21 16:07:50,876 weight update_weight 서버 오류 발생: 유효한 데이터가 수신되지 않았습니다. (Status Code: 484)
ERROR 2025-02-21 16:08:20,658 weight update_weight 서버 오류 발생: 유효한 데이터가 수신되지 않았습니다. (Status Code: 484)
ERROR 2025-02-21 16:09:19,180 weight update_weight 서버 오류 발생: 유효한 데이터가 수신되지 않았습니다. (Status Code: 484)
ERROR 2025-02-21 16:09:59,409 weight update_weight 서버 오류 발생: 유효한 데이터가 수신되지 않았습니다. (Status Code: 484)
ERROR 2025-02-21 16:10:19,786 weight update_weight 서버 오류 발생: 유효한 데이터가 수신되지 않았습니다. (Status Code: 484)
ERROR 2025-02-21 16:10:49,568 weight update_weight 서버 오류 발생: 유효한 데이터가 수신되지 않았습니다. (Status Code: 484)
ERROR 2025-02-21 16:12:02,197 weight update_weight 서버 오류 발생: 유효한 데이터가 수신되지 않았습니다. (Status Code: 484)
ERROR 2025-02-21 16:12:18,392 weight update_weight 서버 오류 발생: 유효한 데이터가 수신되지 않았습니다. (Status Code: 484)
ERROR 2025-02-21 16:12:33,550 weight update_weight 서버 오류 발생: 유효한 데이터가 수신되지 않았습니다. (Status Code: 484)
ERROR 2025-02-21 16:12:59,668 weight update_weight 서버 오류 발생: 유효한 데이터가 수신되지 않았습니다. (Status Code: 484)
ERROR 2025-02-21 16:13:20,045 weight update_weight 서버 오류 발생: 유효한 데이터가 수신되지 않았습니다. (Status Code: 484)
ERROR 2025-02-21 16:41:19,322 user_management check_user 사용자를 찾을 수 없음: UID 04E3436A761390
ERROR 2025-02-25 14:34:16,119 user_management check_user 사용자를 찾을 수 없음: UID 04E3436A761390
ERROR 2025-02-25 14:34:16,686 user_management check_user 사용자를 찾을 수 없음: UID 04E3436A761390
ERROR 2025-02-25 14:34:21,436 user_management check_user 사용자를 찾을 수 없음: UID 04E3436A761390
ERROR 2025-02-25 14:34:22,056 user_management check_user 사용자를 찾을 수 없음: UID 04E3436A761390
ERROR 2025-02-25 14:34:26,649 user_management check_user 사용자를 찾을 수 없음: UID 04E3436A761390
ERROR 2025-02-25 14:34:27,411 user_management check_user 사용자를 찾을 수 없음: UID 04E3436A761390
ERROR 2025-02-25 14:34:31,842 user_management check_user 사용자를 찾을 수 없음: UID 04E3436A761390
ERROR 2025-02-25 14:34:32,786 user_management check_user 사용자를 찾을 수 없음: UID 04E3436A761390
ERROR 2025-02-25 16:13:09,033 weight publish_weight MQTT 발행 중 오류 발생: 'Weight_v3' object is not iterable
ERROR 2025-02-25 16:13:23,123 weight publish_weight MQTT 발행 중 오류 발생: 'Weight_v3' object is not iterable
ERROR 2025-02-25 16:13:29,384 weight publish_weight MQTT 발행 중 오류 발생: 'Weight_v3' object is not iterable
ERROR 2025-02-25 16:13:36,203 weight publish_weight MQTT 발행 중 오류 발생: 'Weight_v3' object is not iterable
ERROR 2025-02-25 16:13:42,974 weight publish_weight MQTT 발행 중 오류 발생: 'Weight_v3' object is not iterable
ERROR 2025-02-25 16:13:49,252 weight publish_weight MQTT 발행 중 오류 발생: 'Weight_v3' object is not iterable
ERROR 2025-02-25 16:13:56,606 weight publish_weight MQTT 발행 중 오류 발생: 'Weight_v3' object is not iterable
ERROR 2025-02-25 16:18:17,274 weight publish_weight MQTT 발행 중 오류 발생: 'Weight_v3' object is not iterable
ERROR 2025-02-25 16:18:29,871 weight publish_weight MQTT 발행 중 오류 발생: 'Weight_v3' object is not iterable
ERROR 2025-02-25 16:18:42,354 weight publish_weight MQTT 발행 중 오류 발생: 'Weight_v3' object is not iterable
ERROR 2025-02-25 16:18:54,367 weight publish_weight MQTT 발행 중 오류 발생: 'Weight_v3' object is not iterable
ERROR 2025-02-25 16:20:22,674 weight publish_weight MQTT 발행 중 오류 발생: Type <class 'rfid.models.Weight_v3'> not serializable
ERROR 2025-02-25 16:20:35,284 weight publish_weight MQTT 발행 중 오류 발생: Type <class 'rfid.models.Weight_v3'> not serializable
ERROR 2025-02-25 16:21:31,638 weight publish_weight MQTT 발행 중 오류 발생: name 'data_list' is not defined
ERROR 2025-02-25 16:21:47,324 weight publish_weight MQTT 발행 중 오류 발생: Type <class 'rfid.models.Weight_v3'> not serializable
ERROR 2025-02-25 16:22:01,944 weight publish_weight MQTT 발행 중 오류 발생: Type <class 'rfid.models.Weight_v3'> not serializable
ERROR 2025-02-25 16:22:15,532 weight publish_weight MQTT 발행 중 오류 발생: Type <class 'rfid.models.Weight_v3'> not serializable
ERROR 2025-02-25 16:22:29,643 weight publish_weight MQTT 발행 중 오류 발생: Type <class 'rfid.models.Weight_v3'> not serializable
ERROR 2025-02-25 16:22:43,754 weight publish_weight MQTT 발행 중 오류 발생: Type <class 'rfid.models.Weight_v3'> not serializable
ERROR 2025-02-25 16:22:57,852 weight publish_weight MQTT 발행 중 오류 발생: name 'serializers' is not defined
ERROR 2025-02-25 16:23:11,973 weight publish_weight MQTT 발행 중 오류 발생: name 'serializers' is not defined
ERROR 2025-02-25 16:23:32,349 weight publish_weight MQTT 발행 중 오류 발생: module 'json' has no attribute 'serialize'
ERROR 2025-02-25 16:23:42,268 weight publish_weight MQTT 발행 중 오류 발생: module 'json' has no attribute 'serialize'
ERROR 2025-02-25 16:23:54,284 weight publish_weight MQTT 발행 중 오류 발생: module 'json' has no attribute 'serialize'
ERROR 2025-02-25 16:24:06,314 weight publish_weight MQTT 발행 중 오류 발생: module 'json' has no attribute 'serialize'
ERROR 2025-02-25 16:24:22,504 weight publish_weight MQTT 발행 중 오류 발생: Type <class 'django.db.models.query.QuerySet'> not serializable
ERROR 2025-02-25 16:24:34,510 weight publish_weight MQTT 발행 중 오류 발생: Type <class 'django.db.models.query.QuerySet'> not serializable
ERROR 2025-02-25 16:25:45,582 weight publish_weight MQTT 발행 중 오류 발생: Type <class 'rfid.models.Weight_v3'> not serializable
ERROR 2025-02-25 16:25:59,709 weight publish_weight MQTT 발행 중 오류 발생: Type <class 'rfid.models.Weight_v3'> not serializable
ERROR 2025-02-25 16:28:00,912 weight publish_weight MQTT 발행 중 오류 발생: Cannot resolve keyword 'ASGN_CD' into field. Choices are: asgn_cd, company, user_v3, weight
ERROR 2025-02-27 14:28:18,322 weight publish_weight MQTT 발행 중 오류 발생: list.append() takes exactly one argument (2 given)
ERROR 2025-02-27 14:28:27,723 weight publish_weight MQTT 발행 중 오류 발생: list.append() takes exactly one argument (2 given)
ERROR 2025-02-27 14:28:37,133 weight publish_weight MQTT 발행 중 오류 발생: list.append() takes exactly one argument (2 given)
ERROR 2025-02-27 14:28:46,534 weight publish_weight MQTT 발행 중 오류 발생: list.append() takes exactly one argument (2 given)
ERROR 2025-02-27 14:47:19,267 weight update_weight 서버 오류 발생: 유효한 데이터가 수신되지 않았습니다. (Status Code: 484)
ERROR 2025-07-24 07:43:48,588 utils wrapper 예기치 못한 오류: DigitalOutputDevice is closed or uninitialized
Traceback (most recent call last):
  File "/usr/lib/python3/dist-packages/gpiozero/output_devices.py", line 87, in _write
    self.pin.state = self._value_to_state(value)
    ^^^^^^^^^^^^^^
AttributeError: 'NoneType' object has no attribute 'state'

During handling of the above exception, another exception occurred:

Traceback (most recent call last):
  File "/usr/lib/python3/dist-packages/gpiozero/devices.py", line 584, in _check_open
    super()._check_open()
  File "/usr/lib/python3/dist-packages/gpiozero/devices.py", line 213, in _check_open
    raise DeviceClosed(
gpiozero.exc.DeviceClosed: DigitalOutputDevice is closed or uninitialized

During handling of the above exception, another exception occurred:

Traceback (most recent call last):
  File "/home/pi/Desktop/rasp_notouch_2/rfid/utils.py", line 16, in wrapper
    return func(request, *args, **kwargs)
           ^^^^^^^^^^^^^^^^^^^^^^^^^^^^^^
  File "/home/pi/Desktop/rasp_notouch_2/rfid/views_v2.py", line 73, in homePage
    lock.on()  # 잠금 장치 닫기
    ^^^^^^^^^
  File "/usr/lib/python3/dist-packages/gpiozero/output_devices.py", line 210, in on
    self._write(True)
  File "/usr/lib/python3/dist-packages/gpiozero/output_devices.py", line 89, in _write
    self._check_open()
  File "/usr/lib/python3/dist-packages/gpiozero/devices.py", line 587, in _check_open
    raise GPIODeviceClosed(str(e))
gpiozero.exc.GPIODeviceClosed: DigitalOutputDevice is closed or uninitialized
ERROR 2025-07-24 08:28:49,333 rfid_reader read_card_uid 리더기를 찾을 수 없습니다. 연결 상태를 확인하세요.
ERROR 2025-07-24 08:57:40,588 rfid_reader read_card_uid 리더기를 찾을 수 없습니다. 연결 상태를 확인하세요.
                                                                                                                                ERROR 2025-07-28 13:29:29,263 rfid_reader read_card_uid 리더기를 찾을 수 없습니다. 연결 상태를 확인하세요.
ERROR 2025-07-28 13:31:04,351 rfid_reader read_card_uid 리더기를 찾을 수 없습니다. 연결 상태를 확인하세요.
ERROR 2025-07-28 13:55:04,062 rfid_reader read_card_uid 리더기를 찾을 수 없습니다. 연결 상태를 확인하세요.
ERROR 2025-07-28 13:56:08,636 rfid_reader read_card_uid 리더기를 찾을 수 없습니다. 연결 상태를 확인하세요.
ERROR 2025-07-28 13:57:49,713 rfid_reader read_card_uid 리더기를 찾을 수 없습니다. 연결 상태를 확인하세요.
ERROR 2025-07-28 14:43:29,315 rfid_reader read_card_uid 리더기를 찾을 수 없습니다. 연결 상태를 확인하세요.
ERROR 2025-07-28 14:46:52,061 rfid_reader read_card_uid 리더기를 찾을 수 없습니다. 연결 상태를 확인하세요.
ERROR 2025-07-28 14:48:11,970 rfid_reader read_card_uid 리더기를 찾을 수 없습니다. 연결 상태를 확인하세요.
ERROR 2025-07-28 16:45:21,946 rfid_reader read_card_uid 리더기를 찾을 수 없습니다. 연결 상태를 확인하세요.
ERROR 2025-07-28 16:57:04,732 rfid_reader read_card_uid 리더기를 찾을 수 없습니다. 연결 상태를 확인하세요.
ERROR 2025-07-28 16:57:16,247 rfid_reader read_card_uid 리더기를 찾을 수 없습니다. 연결 상태를 확인하세요.
ERROR 2025-07-28 17:05:50,148 rfid_reader read_card_uid 리더기를 찾을 수 없습니다. 연결 상태를 확인하세요.
                                                                                                                                ERROR 2025-07-29 06:58:21,110 rfid_reader read_card_uid 리더기를 찾을 수 없습니다. 연결 상태를 확인하세요.
ERROR 2025-07-29 07:01:47,232 rfid_reader read_card_uid 리더기를 찾을 수 없습니다. 연결 상태를 확인하세요.
ERROR 2025-07-31 15:06:10,741 rfid_reader read_card_uid 리더기를 찾을 수 없습니다. 연결 상태를 확인하세요.
ERROR 2025-07-31 15:11:44,662 rfid_reader read_card_uid 리더기를 찾을 수 없습니다. 연결 상태를 확인하세요.
                                                                                                                                ERROR 2025-08-01 13:46:34,369 rfid_reader read_card_uid 리더기를 찾을 수 없습니다. 연결 상태를 확인하세요.
ERROR 2025-08-01 13:52:03,715 rfid_reader read_card_uid 리더기를 찾을 수 없습니다. 연결 상태를 확인하세요.
ERROR 2025-08-01 14:17:21,193 rfid_reader read_card_uid 리더기를 찾을 수 없습니다. 연결 상태를 확인하세요.
ERROR 2025-08-01 14:19:49,725 rfid_reader read_card_uid 리더기를 찾을 수 없습니다. 연결 상태를 확인하세요.
ERROR 2025-08-01 14:22:01,707 rfid_reader read_card_uid 리더기를 찾을 수 없습니다. 연결 상태를 확인하세요.
ERROR 2025-08-01 14:22:52,115 rfid_reader read_card_uid 리더기를 찾을 수 없습니다. 연결 상태를 확인하세요.
ERROR 2025-08-01 14:24:04,095 rfid_reader read_card_uid 리더기를 찾을 수 없습니다. 연결 상태를 확인하세요.
ERROR 2025-08-01 14:25:22,315 rfid_reader read_card_uid 리더기를 찾을 수 없습니다. 연결 상태를 확인하세요.
ERROR 2025-08-01 14:29:37,322 rfid_reader read_card_uid 리더기를 찾을 수 없습니다. 연결 상태를 확인하세요.
ERROR 2025-08-01 14:32:21,310 rfid_reader read_card_uid 리더기를 찾을 수 없습니다. 연결 상태를 확인하세요.
ERROR 2025-08-01 14:33:25,048 rfid_reader read_card_uid 리더기를 찾을 수 없습니다. 연결 상태를 확인하세요.
ERROR 2025-08-01 14:38:34,976 rfid_reader read_card_uid 리더기를 찾을 수 없습니다. 연결 상태를 확인하세요.
ERROR 2025-08-01 14:41:15,054 rfid_reader read_card_uid 리더기를 찾을 수 없습니다. 연결 상태를 확인하세요.
ERROR 2025-08-01 15:32:01,211 utils wrapper 예기치 못한 오류: [Errno 101] Network is unreachable
Traceback (most recent call last):
  File "/home/pi/Desktop/rasp_notouch/rfid/utils.py", line 16, in wrapper
    return func(request, *args, **kwargs)
           ^^^^^^^^^^^^^^^^^^^^^^^^^^^^^^
  File "/home/pi/Desktop/rasp_notouch/rfid/views_v2.py", line 154, in result
    weight.publish_weight(company, weight_info.get('disposal_weight'))
  File "/home/pi/Desktop/rasp_notouch/rfid/weight.py", line 121, in publish_weight
    client.connect("10.150.232.41")
  File "/home/pi/.local/lib/python3.11/site-packages/paho/mqtt/client.py", line 914, in connect
    return self.reconnect()
           ^^^^^^^^^^^^^^^^
  File "/home/pi/.local/lib/python3.11/site-packages/paho/mqtt/client.py", line 1044, in reconnect
    sock = self._create_socket_connection()
           ^^^^^^^^^^^^^^^^^^^^^^^^^^^^^^^^
  File "/home/pi/.local/lib/python3.11/site-packages/paho/mqtt/client.py", line 3685, in _create_socket_connection
    return socket.create_connection(addr, timeout=self._connect_timeout, source_address=source)
           ^^^^^^^^^^^^^^^^^^^^^^^^^^^^^^^^^^^^^^^^^^^^^^^^^^^^^^^^^^^^^^^^^^^^^^^^^^^^^^^^^^^^
  File "/usr/lib/python3.11/socket.py", line 851, in create_connection
    raise exceptions[0]
  File "/usr/lib/python3.11/socket.py", line 836, in create_connection
    sock.connect(sa)
OSError: [Errno 101] Network is unreachable
ERROR 2025-08-01 15:32:26,291 utils wrapper 예기치 못한 오류: [Errno 101] Network is unreachable
Traceback (most recent call last):
  File "/home/pi/Desktop/rasp_notouch/rfid/utils.py", line 16, in wrapper
    return func(request, *args, **kwargs)
           ^^^^^^^^^^^^^^^^^^^^^^^^^^^^^^
  File "/home/pi/Desktop/rasp_notouch/rfid/views_v2.py", line 154, in result
    weight.publish_weight(company, weight_info.get('disposal_weight'))
  File "/home/pi/Desktop/rasp_notouch/rfid/weight.py", line 121, in publish_weight
    client.connect("10.150.232.41")
  File "/home/pi/.local/lib/python3.11/site-packages/paho/mqtt/client.py", line 914, in connect
    return self.reconnect()
           ^^^^^^^^^^^^^^^^
  File "/home/pi/.local/lib/python3.11/site-packages/paho/mqtt/client.py", line 1044, in reconnect
    sock = self._create_socket_connection()
           ^^^^^^^^^^^^^^^^^^^^^^^^^^^^^^^^
  File "/home/pi/.local/lib/python3.11/site-packages/paho/mqtt/client.py", line 3685, in _create_socket_connection
    return socket.create_connection(addr, timeout=self._connect_timeout, source_address=source)
           ^^^^^^^^^^^^^^^^^^^^^^^^^^^^^^^^^^^^^^^^^^^^^^^^^^^^^^^^^^^^^^^^^^^^^^^^^^^^^^^^^^^^
  File "/usr/lib/python3.11/socket.py", line 851, in create_connection
    raise exceptions[0]
  File "/usr/lib/python3.11/socket.py", line 836, in create_connection
    sock.connect(sa)
OSError: [Errno 101] Network is unreachable
ERROR 2025-08-01 15:39:45,537 utils wrapper 예기치 못한 오류: [Errno 101] Network is unreachable
Traceback (most recent call last):
  File "/home/pi/Desktop/rasp_notouch/rfid/utils.py", line 16, in wrapper
    return func(request, *args, **kwargs)
           ^^^^^^^^^^^^^^^^^^^^^^^^^^^^^^
  File "/home/pi/Desktop/rasp_notouch/rfid/views_v2.py", line 154, in result
    weight.publish_weight(company, weight_info.get('disposal_weight'))
  File "/home/pi/Desktop/rasp_notouch/rfid/weight.py", line 121, in publish_weight
    client.connect("10.150.232.41")
  File "/home/pi/.local/lib/python3.11/site-packages/paho/mqtt/client.py", line 914, in connect
    return self.reconnect()
           ^^^^^^^^^^^^^^^^
  File "/home/pi/.local/lib/python3.11/site-packages/paho/mqtt/client.py", line 1044, in reconnect
    sock = self._create_socket_connection()
           ^^^^^^^^^^^^^^^^^^^^^^^^^^^^^^^^
  File "/home/pi/.local/lib/python3.11/site-packages/paho/mqtt/client.py", line 3685, in _create_socket_connection
    return socket.create_connection(addr, timeout=self._connect_timeout, source_address=source)
           ^^^^^^^^^^^^^^^^^^^^^^^^^^^^^^^^^^^^^^^^^^^^^^^^^^^^^^^^^^^^^^^^^^^^^^^^^^^^^^^^^^^^
  File "/usr/lib/python3.11/socket.py", line 851, in create_connection
    raise exceptions[0]
  File "/usr/lib/python3.11/socket.py", line 836, in create_connection
    sock.connect(sa)
OSError: [Errno 101] Network is unreachable
ERROR 2025-08-01 15:40:52,875 user_management check_user 사용자를 찾을 수 없음: UID 08 73 A8 D5
ERROR 2025-08-01 16:03:47,098 utils wrapper 예기치 못한 오류: [Errno 101] Network is unreachable
Traceback (most recent call last):
  File "/home/pi/Desktop/rasp_notouch/rfid/utils.py", line 16, in wrapper
    return func(request, *args, **kwargs)
           ^^^^^^^^^^^^^^^^^^^^^^^^^^^^^^
  File "/home/pi/Desktop/rasp_notouch/rfid/views_v2.py", line 154, in result
    weight.publish_weight(company, weight_info.get('disposal_weight'))
  File "/home/pi/Desktop/rasp_notouch/rfid/weight.py", line 121, in publish_weight
    client.connect("10.150.232.41")
  File "/home/pi/.local/lib/python3.11/site-packages/paho/mqtt/client.py", line 914, in connect
    return self.reconnect()
           ^^^^^^^^^^^^^^^^
  File "/home/pi/.local/lib/python3.11/site-packages/paho/mqtt/client.py", line 1044, in reconnect
    sock = self._create_socket_connection()
           ^^^^^^^^^^^^^^^^^^^^^^^^^^^^^^^^
  File "/home/pi/.local/lib/python3.11/site-packages/paho/mqtt/client.py", line 3685, in _create_socket_connection
    return socket.create_connection(addr, timeout=self._connect_timeout, source_address=source)
           ^^^^^^^^^^^^^^^^^^^^^^^^^^^^^^^^^^^^^^^^^^^^^^^^^^^^^^^^^^^^^^^^^^^^^^^^^^^^^^^^^^^^
  File "/usr/lib/python3.11/socket.py", line 851, in create_connection
    raise exceptions[0]
  File "/usr/lib/python3.11/socket.py", line 836, in create_connection
    sock.connect(sa)
OSError: [Errno 101] Network is unreachable
ERROR 2025-08-01 16:03:57,025 utils wrapper 예기치 못한 오류: [Errno 101] Network is unreachable
Traceback (most recent call last):
  File "/home/pi/Desktop/rasp_notouch/rfid/utils.py", line 16, in wrapper
    return func(request, *args, **kwargs)
           ^^^^^^^^^^^^^^^^^^^^^^^^^^^^^^
  File "/home/pi/Desktop/rasp_notouch/rfid/views_v2.py", line 154, in result
    weight.publish_weight(company, weight_info.get('disposal_weight'))
  File "/home/pi/Desktop/rasp_notouch/rfid/weight.py", line 121, in publish_weight
    client.connect("10.150.232.41")
  File "/home/pi/.local/lib/python3.11/site-packages/paho/mqtt/client.py", line 914, in connect
    return self.reconnect()
           ^^^^^^^^^^^^^^^^
  File "/home/pi/.local/lib/python3.11/site-packages/paho/mqtt/client.py", line 1044, in reconnect
    sock = self._create_socket_connection()
           ^^^^^^^^^^^^^^^^^^^^^^^^^^^^^^^^
  File "/home/pi/.local/lib/python3.11/site-packages/paho/mqtt/client.py", line 3685, in _create_socket_connection
    return socket.create_connection(addr, timeout=self._connect_timeout, source_address=source)
           ^^^^^^^^^^^^^^^^^^^^^^^^^^^^^^^^^^^^^^^^^^^^^^^^^^^^^^^^^^^^^^^^^^^^^^^^^^^^^^^^^^^^
  File "/usr/lib/python3.11/socket.py", line 851, in create_connection
    raise exceptions[0]
  File "/usr/lib/python3.11/socket.py", line 836, in create_connection
    sock.connect(sa)
OSError: [Errno 101] Network is unreachable
ERROR 2025-08-01 16:11:51,167 utils wrapper 예기치 못한 오류: [Errno 101] Network is unreachable
Traceback (most recent call last):
  File "/home/pi/Desktop/rasp_notouch/rfid/utils.py", line 16, in wrapper
    return func(request, *args, **kwargs)
           ^^^^^^^^^^^^^^^^^^^^^^^^^^^^^^
  File "/home/pi/Desktop/rasp_notouch/rfid/views_v2.py", line 154, in result
    weight.publish_weight(company, weight_info.get('disposal_weight'))
  File "/home/pi/Desktop/rasp_notouch/rfid/weight.py", line 121, in publish_weight
    client.connect("10.150.232.41")
  File "/home/pi/.local/lib/python3.11/site-packages/paho/mqtt/client.py", line 914, in connect
    return self.reconnect()
           ^^^^^^^^^^^^^^^^
  File "/home/pi/.local/lib/python3.11/site-packages/paho/mqtt/client.py", line 1044, in reconnect
    sock = self._create_socket_connection()
           ^^^^^^^^^^^^^^^^^^^^^^^^^^^^^^^^
  File "/home/pi/.local/lib/python3.11/site-packages/paho/mqtt/client.py", line 3685, in _create_socket_connection
    return socket.create_connection(addr, timeout=self._connect_timeout, source_address=source)
           ^^^^^^^^^^^^^^^^^^^^^^^^^^^^^^^^^^^^^^^^^^^^^^^^^^^^^^^^^^^^^^^^^^^^^^^^^^^^^^^^^^^^
  File "/usr/lib/python3.11/socket.py", line 851, in create_connection
    raise exceptions[0]
  File "/usr/lib/python3.11/socket.py", line 836, in create_connection
    sock.connect(sa)
OSError: [Errno 101] Network is unreachable
ERROR 2025-08-01 16:12:15,202 utils wrapper 예기치 못한 오류: [Errno 101] Network is unreachable
Traceback (most recent call last):
  File "/home/pi/Desktop/rasp_notouch/rfid/utils.py", line 16, in wrapper
    return func(request, *args, **kwargs)
           ^^^^^^^^^^^^^^^^^^^^^^^^^^^^^^
  File "/home/pi/Desktop/rasp_notouch/rfid/views_v2.py", line 154, in result
    weight.publish_weight(company, weight_info.get('disposal_weight'))
  File "/home/pi/Desktop/rasp_notouch/rfid/weight.py", line 121, in publish_weight
    client.connect("10.150.232.41")
  File "/home/pi/.local/lib/python3.11/site-packages/paho/mqtt/client.py", line 914, in connect
    return self.reconnect()
           ^^^^^^^^^^^^^^^^
  File "/home/pi/.local/lib/python3.11/site-packages/paho/mqtt/client.py", line 1044, in reconnect
    sock = self._create_socket_connection()
           ^^^^^^^^^^^^^^^^^^^^^^^^^^^^^^^^
  File "/home/pi/.local/lib/python3.11/site-packages/paho/mqtt/client.py", line 3685, in _create_socket_connection
    return socket.create_connection(addr, timeout=self._connect_timeout, source_address=source)
           ^^^^^^^^^^^^^^^^^^^^^^^^^^^^^^^^^^^^^^^^^^^^^^^^^^^^^^^^^^^^^^^^^^^^^^^^^^^^^^^^^^^^
  File "/usr/lib/python3.11/socket.py", line 851, in create_connection
    raise exceptions[0]
  File "/usr/lib/python3.11/socket.py", line 836, in create_connection
    sock.connect(sa)
OSError: [Errno 101] Network is unreachable
ERROR 2025-08-01 16:12:39,236 utils wrapper 예기치 못한 오류: [Errno 101] Network is unreachable
Traceback (most recent call last):
  File "/home/pi/Desktop/rasp_notouch/rfid/utils.py", line 16, in wrapper
    return func(request, *args, **kwargs)
           ^^^^^^^^^^^^^^^^^^^^^^^^^^^^^^
  File "/home/pi/Desktop/rasp_notouch/rfid/views_v2.py", line 154, in result
    weight.publish_weight(company, weight_info.get('disposal_weight'))
  File "/home/pi/Desktop/rasp_notouch/rfid/weight.py", line 121, in publish_weight
    client.connect("10.150.232.41")
  File "/home/pi/.local/lib/python3.11/site-packages/paho/mqtt/client.py", line 914, in connect
    return self.reconnect()
           ^^^^^^^^^^^^^^^^
  File "/home/pi/.local/lib/python3.11/site-packages/paho/mqtt/client.py", line 1044, in reconnect
    sock = self._create_socket_connection()
           ^^^^^^^^^^^^^^^^^^^^^^^^^^^^^^^^
  File "/home/pi/.local/lib/python3.11/site-packages/paho/mqtt/client.py", line 3685, in _create_socket_connection
    return socket.create_connection(addr, timeout=self._connect_timeout, source_address=source)
           ^^^^^^^^^^^^^^^^^^^^^^^^^^^^^^^^^^^^^^^^^^^^^^^^^^^^^^^^^^^^^^^^^^^^^^^^^^^^^^^^^^^^
  File "/usr/lib/python3.11/socket.py", line 851, in create_connection
    raise exceptions[0]
  File "/usr/lib/python3.11/socket.py", line 836, in create_connection
    sock.connect(sa)
OSError: [Errno 101] Network is unreachable
ERROR 2025-08-01 16:12:59,091 utils wrapper 예기치 못한 오류: [Errno 101] Network is unreachable
Traceback (most recent call last):
  File "/home/pi/Desktop/rasp_notouch/rfid/utils.py", line 16, in wrapper
    return func(request, *args, **kwargs)
           ^^^^^^^^^^^^^^^^^^^^^^^^^^^^^^
  File "/home/pi/Desktop/rasp_notouch/rfid/views_v2.py", line 154, in result
    weight.publish_weight(company, weight_info.get('disposal_weight'))
  File "/home/pi/Desktop/rasp_notouch/rfid/weight.py", line 121, in publish_weight
    client.connect("10.150.232.41")
  File "/home/pi/.local/lib/python3.11/site-packages/paho/mqtt/client.py", line 914, in connect
    return self.reconnect()
           ^^^^^^^^^^^^^^^^
  File "/home/pi/.local/lib/python3.11/site-packages/paho/mqtt/client.py", line 1044, in reconnect
    sock = self._create_socket_connection()
           ^^^^^^^^^^^^^^^^^^^^^^^^^^^^^^^^
  File "/home/pi/.local/lib/python3.11/site-packages/paho/mqtt/client.py", line 3685, in _create_socket_connection
    return socket.create_connection(addr, timeout=self._connect_timeout, source_address=source)
           ^^^^^^^^^^^^^^^^^^^^^^^^^^^^^^^^^^^^^^^^^^^^^^^^^^^^^^^^^^^^^^^^^^^^^^^^^^^^^^^^^^^^
  File "/usr/lib/python3.11/socket.py", line 851, in create_connection
    raise exceptions[0]
  File "/usr/lib/python3.11/socket.py", line 836, in create_connection
    sock.connect(sa)
OSError: [Errno 101] Network is unreachable
ERROR 2025-08-01 16:28:00,218 rfid_reader read_card_uid 리더기를 찾을 수 없습니다. 연결 상태를 확인하세요.
ERROR 2025-08-01 16:29:41,511 rfid_reader read_card_uid 리더기를 찾을 수 없습니다. 연결 상태를 확인하세요.
ERROR 2025-08-01 16:31:23,272 user_management check_user 사용자를 찾을 수 없음: UID BF C6 DC 82
ERROR 2025-08-01 16:31:28,464 user_management check_user 사용자를 찾을 수 없음: UID BF C6 DC 82
ERROR 2025-08-01 16:32:15,639 rfid_reader read_card_uid 리더기를 찾을 수 없습니다. 연결 상태를 확인하세요.
ERROR 2025-08-01 16:35:30,945 user_management check_user 사용자를 찾을 수 없음: UID BF C6 DC 82
ERROR 2025-08-01 16:37:22,866 user_management add_user 사용자 추가 오류: 관리자 비밀번호가 잘못되었습니다. (Status Code: 403)
ERROR 2025-08-01 16:37:52,042 user_management add_user 사용자 추가 오류: 관리자 비밀번호가 잘못되었습니다. (Status Code: 403)
ERROR 2025-08-01 16:38:38,615 user_management check_user 사용자를 찾을 수 없음: UID BF C6 DC 82
ERROR 2025-08-01 16:38:42,087 user_management check_user 사용자를 찾을 수 없음: UID BF C6 DC 82
ERROR 2025-08-01 16:38:53,722 user_management check_user 사용자를 찾을 수 없음: UID BF C6 DC 82
ERROR 2025-08-01 16:39:29,145 user_management check_user 사용자를 찾을 수 없음: UID BF C6 DC 82
ERROR 2025-08-01 16:40:09,900 user_management check_user 사용자를 찾을 수 없음: UID AF D4 1A 82
ERROR 2025-08-01 16:41:54,549 user_management check_user 사용자를 찾을 수 없음: UID EF FF 1A 82
ERROR 2025-08-01 16:42:27,979 user_management check_user 사용자를 찾을 수 없음: UID 2F 69 13 82
ERROR 2025-08-01 16:42:40,160 user_management check_user 사용자를 찾을 수 없음: UID 2F 69 13 82
ERROR 2025-08-01 16:43:38,375 user_management check_user 사용자를 찾을 수 없음: UID CF C7 1D 82
ERROR 2025-08-01 16:44:58,897 user_management check_user 사용자를 찾을 수 없음: UID EF 9D 0E 82
ERROR 2025-08-01 16:45:23,350 user_management check_user 사용자를 찾을 수 없음: UID EF 9D 0E 82
ERROR 2025-08-01 16:45:54,533 user_management check_user 사용자를 찾을 수 없음: UID EF F1 72 81
ERROR 2025-08-01 16:46:10,380 user_management check_user 사용자를 찾을 수 없음: UID EF F1 72 81
ERROR 2025-08-01 16:46:37,525 user_management check_user 사용자를 찾을 수 없음: UID 04 F8 4B 6A 76 13 90
ERROR 2025-08-01 16:46:50,778 user_management check_user 사용자를 찾을 수 없음: UID 04 0A 47 0F
ERROR 2025-08-01 16:46:57,325 user_management check_user 사용자를 찾을 수 없음: UID 04 0A 47 0F
ERROR 2025-08-01 16:47:13,522 user_management check_user 사용자를 찾을 수 없음: UID 04 0A 47 0F
ERROR 2025-08-01 16:48:14,296 user_management check_user 사용자를 찾을 수 없음: UID 14 D6 A8 0E
ERROR 2025-08-01 16:48:26,538 user_management check_user 사용자를 찾을 수 없음: UID 14 D6 A8 0E
ERROR 2025-08-01 16:59:22,373 rfid_reader read_card_uid 리더기를 찾을 수 없습니다. 연결 상태를 확인하세요.
ERROR 2025-08-01 17:00:23,154 rfid_reader read_card_uid 리더기를 찾을 수 없습니다. 연결 상태를 확인하세요.
ERROR 2025-08-01 17:03:23,772 rfid_reader read_card_uid 리더기를 찾을 수 없습니다. 연결 상태를 확인하세요.
ERROR 2025-08-01 17:12:28,192 rfid_reader read_card_uid 리더기를 찾을 수 없습니다. 연결 상태를 확인하세요.
ERROR 2025-08-01 17:13:28,852 rfid_reader read_card_uid 리더기를 찾을 수 없습니다. 연결 상태를 확인하세요.
ERROR 2025-08-26 08:57:25,053 user_management check_user 사용자를 찾을 수 없음: UID 04 F8 4B 6A 76 13 90
ERROR 2025-08-26 08:57:51,272 user_management check_user 사용자를 찾을 수 없음: UID 04 F8 4B 6A 76 13 90
ERROR 2025-08-26 08:57:55,844 user_management check_user 사용자를 찾을 수 없음: UID 04 F8 4B 6A 76 13 90
ERROR 2025-08-26 08:58:00,082 user_management check_user 사용자를 찾을 수 없음: UID 04 F8 4B 6A 76 13 90
ERROR 2025-08-26 08:58:04,356 user_management check_user 사용자를 찾을 수 없음: UID 04 F8 4B 6A 76 13 90
ERROR 2025-08-26 08:58:08,604 user_management check_user 사용자를 찾을 수 없음: UID 04 F8 4B 6A 76 13 90
ERROR 2025-08-26 08:58:21,879 user_management check_user 사용자를 찾을 수 없음: UID A4 CF BA 0E
ERROR 2025-08-26 08:58:26,114 user_management check_user 사용자를 찾을 수 없음: UID A4 CF BA 0E
ERROR 2025-08-26 08:58:30,357 user_management check_user 사용자를 찾을 수 없음: UID A4 CF BA 0E
ERROR 2025-08-26 08:58:34,614 user_management check_user 사용자를 찾을 수 없음: UID A4 CF BA 0E
ERROR 2025-08-26 08:59:19,809 rfid_reader read_card_uid 리더기를 찾을 수 없습니다. 연결 상태를 확인하세요.
ERROR 2025-08-26 10:36:15,594 rfid_reader read_card_uid 리더기를 찾을 수 없습니다. 연결 상태를 확인하세요.
ERROR 2025-08-27 07:32:05,741 rfid_reader read_card_uid 리더기를 찾을 수 없습니다. 연결 상태를 확인하세요.
ERROR 2025-08-27 07:32:16,292 rfid_reader read_card_uid 리더기를 찾을 수 없습니다. 연결 상태를 확인하세요.
ERROR 2025-08-27 07:32:35,825 rfid_reader read_card_uid 리더기를 찾을 수 없습니다. 연결 상태를 확인하세요.
ERROR 2025-08-27 07:37:04,103 rfid_reader read_card_uid 리더기를 찾을 수 없습니다. 연결 상태를 확인하세요.
ERROR 2025-08-27 07:43:50,482 rfid_reader read_card_uid 리더기를 찾을 수 없습니다. 연결 상태를 확인하세요.
ERROR 2025-08-27 10:44:20,528 rfid_reader read_card_uid 리더기를 찾을 수 없습니다. 연결 상태를 확인하세요.
ERROR 2025-08-27 10:44:21,827 rfid_reader read_card_uid 리더기를 찾을 수 없습니다. 연결 상태를 확인하세요.
ERROR 2025-08-27 10:44:22,837 rfid_reader read_card_uid 리더기를 찾을 수 없습니다. 연결 상태를 확인하세요.
ERROR 2025-08-27 10:44:23,848 rfid_reader read_card_uid 리더기를 찾을 수 없습니다. 연결 상태를 확인하세요.
ERROR 2025-08-27 10:44:24,859 rfid_reader read_card_uid 리더기를 찾을 수 없습니다. 연결 상태를 확인하세요.
ERROR 2025-08-27 10:44:25,899 rfid_reader read_card_uid 리더기를 찾을 수 없습니다. 연결 상태를 확인하세요.
ERROR 2025-08-27 10:44:26,938 rfid_reader read_card_uid 리더기를 찾을 수 없습니다. 연결 상태를 확인하세요.
ERROR 2025-08-27 10:44:27,947 rfid_reader read_card_uid 리더기를 찾을 수 없습니다. 연결 상태를 확인하세요.
ERROR 2025-08-27 10:44:28,955 rfid_reader read_card_uid 리더기를 찾을 수 없습니다. 연결 상태를 확인하세요.
ERROR 2025-08-27 10:44:29,966 rfid_reader read_card_uid 리더기를 찾을 수 없습니다. 연결 상태를 확인하세요.
ERROR 2025-08-27 10:44:31,015 rfid_reader read_card_uid 리더기를 찾을 수 없습니다. 연결 상태를 확인하세요.
ERROR 2025-08-27 10:48:26,619 rfid_reader read_card_uid 리더기를 찾을 수 없습니다. 연결 상태를 확인하세요.
ERROR 2025-08-27 10:48:27,628 rfid_reader read_card_uid 리더기를 찾을 수 없습니다. 연결 상태를 확인하세요.
ERROR 2025-08-27 10:48:28,641 rfid_reader read_card_uid 리더기를 찾을 수 없습니다. 연결 상태를 확인하세요.
ERROR 2025-08-27 10:48:29,878 rfid_reader read_card_uid 리더기를 찾을 수 없습니다. 연결 상태를 확인하세요.
ERROR 2025-08-27 10:48:30,888 rfid_reader read_card_uid 리더기를 찾을 수 없습니다. 연결 상태를 확인하세요.
ERROR 2025-08-27 10:48:31,898 rfid_reader read_card_uid 리더기를 찾을 수 없습니다. 연결 상태를 확인하세요.
ERROR 2025-08-27 10:48:32,907 rfid_reader read_card_uid 리더기를 찾을 수 없습니다. 연결 상태를 확인하세요.
ERROR 2025-08-27 10:48:33,916 rfid_reader read_card_uid 리더기를 찾을 수 없습니다. 연결 상태를 확인하세요.
ERROR 2025-08-27 10:48:34,923 rfid_reader read_card_uid 리더기를 찾을 수 없습니다. 연결 상태를 확인하세요.
ERROR 2025-08-27 10:48:35,931 rfid_reader read_card_uid 리더기를 찾을 수 없습니다. 연결 상태를 확인하세요.
ERROR 2025-08-27 10:48:36,939 rfid_reader read_card_uid 리더기를 찾을 수 없습니다. 연결 상태를 확인하세요.
ERROR 2025-08-27 10:48:37,955 rfid_reader read_card_uid 리더기를 찾을 수 없습니다. 연결 상태를 확인하세요.
ERROR 2025-08-27 10:48:43,600 rfid_reader read_card_uid 리더기를 찾을 수 없습니다. 연결 상태를 확인하세요.
ERROR 2025-08-27 10:48:44,912 rfid_reader read_card_uid 리더기를 찾을 수 없습니다. 연결 상태를 확인하세요.
ERROR 2025-08-27 10:48:45,920 rfid_reader read_card_uid 리더기를 찾을 수 없습니다. 연결 상태를 확인하세요.
ERROR 2025-08-27 10:48:46,928 rfid_reader read_card_uid 리더기를 찾을 수 없습니다. 연결 상태를 확인하세요.
ERROR 2025-08-27 10:48:48,097 rfid_reader read_card_uid 리더기를 찾을 수 없습니다. 연결 상태를 확인하세요.
ERROR 2025-08-27 10:48:49,104 rfid_reader read_card_uid 리더기를 찾을 수 없습니다. 연결 상태를 확인하세요.
ERROR 2025-08-27 10:48:50,117 rfid_reader read_card_uid 리더기를 찾을 수 없습니다. 연결 상태를 확인하세요.
ERROR 2025-08-27 10:48:51,127 rfid_reader read_card_uid 리더기를 찾을 수 없습니다. 연결 상태를 확인하세요.
ERROR 2025-08-27 10:48:52,206 rfid_reader read_card_uid 리더기를 찾을 수 없습니다. 연결 상태를 확인하세요.
ERROR 2025-08-27 10:48:53,405 rfid_reader read_card_uid 리더기를 찾을 수 없습니다. 연결 상태를 확인하세요.
ERROR 2025-08-27 10:48:54,414 rfid_reader read_card_uid 리더기를 찾을 수 없습니다. 연결 상태를 확인하세요.
ERROR 2025-08-27 10:48:55,508 rfid_reader read_card_uid 리더기를 찾을 수 없습니다. 연결 상태를 확인하세요.
ERROR 2025-08-27 10:48:56,523 rfid_reader read_card_uid 리더기를 찾을 수 없습니다. 연결 상태를 확인하세요.
ERROR 2025-08-27 10:48:57,532 rfid_reader read_card_uid 리더기를 찾을 수 없습니다. 연결 상태를 확인하세요.
ERROR 2025-08-27 10:48:58,548 rfid_reader read_card_uid 리더기를 찾을 수 없습니다. 연결 상태를 확인하세요.
ERROR 2025-08-27 10:48:59,560 rfid_reader read_card_uid 리더기를 찾을 수 없습니다. 연결 상태를 확인하세요.
ERROR 2025-08-27 10:49:00,571 rfid_reader read_card_uid 리더기를 찾을 수 없습니다. 연결 상태를 확인하세요.
ERROR 2025-08-27 10:49:01,587 rfid_reader read_card_uid 리더기를 찾을 수 없습니다. 연결 상태를 확인하세요.
ERROR 2025-08-27 10:49:02,596 rfid_reader read_card_uid 리더기를 찾을 수 없습니다. 연결 상태를 확인하세요.
ERROR 2025-08-27 10:49:03,606 rfid_reader read_card_uid 리더기를 찾을 수 없습니다. 연결 상태를 확인하세요.
ERROR 2025-08-27 10:49:04,614 rfid_reader read_card_uid 리더기를 찾을 수 없습니다. 연결 상태를 확인하세요.
ERROR 2025-08-27 10:49:05,625 rfid_reader read_card_uid 리더기를 찾을 수 없습니다. 연결 상태를 확인하세요.
ERROR 2025-08-27 10:49:06,635 rfid_reader read_card_uid 리더기를 찾을 수 없습니다. 연결 상태를 확인하세요.
ERROR 2025-08-27 10:49:07,644 rfid_reader read_card_uid 리더기를 찾을 수 없습니다. 연결 상태를 확인하세요.
ERROR 2025-08-27 10:49:08,653 rfid_reader read_card_uid 리더기를 찾을 수 없습니다. 연결 상태를 확인하세요.
ERROR 2025-08-27 10:49:09,662 rfid_reader read_card_uid 리더기를 찾을 수 없습니다. 연결 상태를 확인하세요.
ERROR 2025-08-27 10:49:10,672 rfid_reader read_card_uid 리더기를 찾을 수 없습니다. 연결 상태를 확인하세요.
ERROR 2025-08-27 10:49:11,694 rfid_reader read_card_uid 리더기를 찾을 수 없습니다. 연결 상태를 확인하세요.
ERROR 2025-08-27 10:49:12,703 rfid_reader read_card_uid 리더기를 찾을 수 없습니다. 연결 상태를 확인하세요.
ERROR 2025-08-27 10:49:13,712 rfid_reader read_card_uid 리더기를 찾을 수 없습니다. 연결 상태를 확인하세요.
ERROR 2025-08-27 10:49:14,721 rfid_reader read_card_uid 리더기를 찾을 수 없습니다. 연결 상태를 확인하세요.
ERROR 2025-08-27 10:49:15,732 rfid_reader read_card_uid 리더기를 찾을 수 없습니다. 연결 상태를 확인하세요.
ERROR 2025-08-27 10:49:16,740 rfid_reader read_card_uid 리더기를 찾을 수 없습니다. 연결 상태를 확인하세요.
ERROR 2025-08-27 10:49:17,749 rfid_reader read_card_uid 리더기를 찾을 수 없습니다. 연결 상태를 확인하세요.
ERROR 2025-08-27 10:49:18,757 rfid_reader read_card_uid 리더기를 찾을 수 없습니다. 연결 상태를 확인하세요.
ERROR 2025-08-27 10:49:19,767 rfid_reader read_card_uid 리더기를 찾을 수 없습니다. 연결 상태를 확인하세요.
                                                                                                                                                                                                                                                                                                                                                                                                                                                                                                                                                                                                                                                                                                                                                                                                                                                                                                                                                                                                                                                                                                                                                                                                                                                                                                                                                                                                                                                                                                                                                                                                                                                                                                                                ERROR 2025-08-27 10:49:19,316 rfid_reader read_card_uid 리더기를 찾을 수 없습니다. 연결 상태를 확인하세요.
ERROR 2025-08-27 10:49:20,445 rfid_reader read_card_uid 리더기를 찾을 수 없습니다. 연결 상태를 확인하세요.
ERROR 2025-08-27 10:49:21,457 rfid_reader read_card_uid 리더기를 찾을 수 없습니다. 연결 상태를 확인하세요.
ERROR 2025-08-27 10:49:22,468 rfid_reader read_card_uid 리더기를 찾을 수 없습니다. 연결 상태를 확인하세요.
ERROR 2025-08-27 10:49:23,476 rfid_reader read_card_uid 리더기를 찾을 수 없습니다. 연결 상태를 확인하세요.
ERROR 2025-08-27 10:49:24,954 rfid_reader read_card_uid 리더기를 찾을 수 없습니다. 연결 상태를 확인하세요.
ERROR 2025-08-27 10:49:25,966 rfid_reader read_card_uid 리더기를 찾을 수 없습니다. 연결 상태를 확인하세요.
ERROR 2025-08-27 10:49:26,973 rfid_reader read_card_uid 리더기를 찾을 수 없습니다. 연결 상태를 확인하세요.
ERROR 2025-08-27 10:49:27,982 rfid_reader read_card_uid 리더기를 찾을 수 없습니다. 연결 상태를 확인하세요.
ERROR 2025-08-27 10:49:28,993 rfid_reader read_card_uid 리더기를 찾을 수 없습니다. 연결 상태를 확인하세요.
ERROR 2025-08-27 10:49:30,006 rfid_reader read_card_uid 리더기를 찾을 수 없습니다. 연결 상태를 확인하세요.
ERROR 2025-08-27 10:49:31,165 rfid_reader read_card_uid 리더기를 찾을 수 없습니다. 연결 상태를 확인하세요.
ERROR 2025-08-27 10:49:32,203 rfid_reader read_card_uid 리더기를 찾을 수 없습니다. 연결 상태를 확인하세요.
ERROR 2025-08-27 10:49:33,214 rfid_reader read_card_uid 리더기를 찾을 수 없습니다. 연결 상태를 확인하세요.
ERROR 2025-08-27 10:49:34,326 rfid_reader read_card_uid 리더기를 찾을 수 없습니다. 연결 상태를 확인하세요.
ERROR 2025-08-27 10:49:35,335 rfid_reader read_card_uid 리더기를 찾을 수 없습니다. 연결 상태를 확인하세요.
ERROR 2025-08-27 10:49:36,344 rfid_reader read_card_uid 리더기를 찾을 수 없습니다. 연결 상태를 확인하세요.
ERROR 2025-08-27 10:49:37,352 rfid_reader read_card_uid 리더기를 찾을 수 없습니다. 연결 상태를 확인하세요.
ERROR 2025-08-27 10:49:38,361 rfid_reader read_card_uid 리더기를 찾을 수 없습니다. 연결 상태를 확인하세요.
ERROR 2025-08-27 10:49:39,369 rfid_reader read_card_uid 리더기를 찾을 수 없습니다. 연결 상태를 확인하세요.
ERROR 2025-08-27 10:49:40,378 rfid_reader read_card_uid 리더기를 찾을 수 없습니다. 연결 상태를 확인하세요.
ERROR 2025-08-27 10:49:41,386 rfid_reader read_card_uid 리더기를 찾을 수 없습니다. 연결 상태를 확인하세요.
ERROR 2025-08-27 10:49:42,509 rfid_reader read_card_uid 리더기를 찾을 수 없습니다. 연결 상태를 확인하세요.
ERROR 2025-08-27 10:49:43,518 rfid_reader read_card_uid 리더기를 찾을 수 없습니다. 연결 상태를 확인하세요.
ERROR 2025-08-27 10:49:44,528 rfid_reader read_card_uid 리더기를 찾을 수 없습니다. 연결 상태를 확인하세요.
ERROR 2025-08-27 10:49:45,537 rfid_reader read_card_uid 리더기를 찾을 수 없습니다. 연결 상태를 확인하세요.
ERROR 2025-08-27 10:49:46,545 rfid_reader read_card_uid 리더기를 찾을 수 없습니다. 연결 상태를 확인하세요.
ERROR 2025-08-27 10:49:47,569 rfid_reader read_card_uid 리더기를 찾을 수 없습니다. 연결 상태를 확인하세요.
ERROR 2025-08-27 10:49:48,578 rfid_reader read_card_uid 리더기를 찾을 수 없습니다. 연결 상태를 확인하세요.
ERROR 2025-08-27 10:49:49,587 rfid_reader read_card_uid 리더기를 찾을 수 없습니다. 연결 상태를 확인하세요.
ERROR 2025-08-27 10:49:50,596 rfid_reader read_card_uid 리더기를 찾을 수 없습니다. 연결 상태를 확인하세요.
ERROR 2025-08-27 10:49:51,605 rfid_reader read_card_uid 리더기를 찾을 수 없습니다. 연결 상태를 확인하세요.
ERROR 2025-08-27 10:49:52,613 rfid_reader read_card_uid 리더기를 찾을 수 없습니다. 연결 상태를 확인하세요.
ERROR 2025-08-27 10:49:53,623 rfid_reader read_card_uid 리더기를 찾을 수 없습니다. 연결 상태를 확인하세요.
ERROR 2025-08-27 10:49:54,632 rfid_reader read_card_uid 리더기를 찾을 수 없습니다. 연결 상태를 확인하세요.
ERROR 2025-08-27 10:49:55,640 rfid_reader read_card_uid 리더기를 찾을 수 없습니다. 연결 상태를 확인하세요.
ERROR 2025-08-27 10:49:56,650 rfid_reader read_card_uid 리더기를 찾을 수 없습니다. 연결 상태를 확인하세요.
ERROR 2025-08-27 10:49:57,658 rfid_reader read_card_uid 리더기를 찾을 수 없습니다. 연결 상태를 확인하세요.
ERROR 2025-08-27 10:49:58,666 rfid_reader read_card_uid 리더기를 찾을 수 없습니다. 연결 상태를 확인하세요.
ERROR 2025-08-27 10:49:59,675 rfid_reader read_card_uid 리더기를 찾을 수 없습니다. 연결 상태를 확인하세요.
ERROR 2025-08-27 10:50:00,683 rfid_reader read_card_uid 리더기를 찾을 수 없습니다. 연결 상태를 확인하세요.
ERROR 2025-08-27 10:50:01,692 rfid_reader read_card_uid 리더기를 찾을 수 없습니다. 연결 상태를 확인하세요.
ERROR 2025-08-27 10:50:02,702 rfid_reader read_card_uid 리더기를 찾을 수 없습니다. 연결 상태를 확인하세요.
ERROR 2025-08-27 10:50:03,711 rfid_reader read_card_uid 리더기를 찾을 수 없습니다. 연결 상태를 확인하세요.
ERROR 2025-08-27 10:50:04,719 rfid_reader read_card_uid 리더기를 찾을 수 없습니다. 연결 상태를 확인하세요.
ERROR 2025-08-27 10:50:05,731 rfid_reader read_card_uid 리더기를 찾을 수 없습니다. 연결 상태를 확인하세요.
ERROR 2025-08-27 10:50:06,738 rfid_reader read_card_uid 리더기를 찾을 수 없습니다. 연결 상태를 확인하세요.
ERROR 2025-08-27 10:50:07,745 rfid_reader read_card_uid 리더기를 찾을 수 없습니다. 연결 상태를 확인하세요.
ERROR 2025-08-27 10:50:08,753 rfid_reader read_card_uid 리더기를 찾을 수 없습니다. 연결 상태를 확인하세요.
ERROR 2025-08-27 10:50:09,762 rfid_reader read_card_uid 리더기를 찾을 수 없습니다. 연결 상태를 확인하세요.
ERROR 2025-08-27 10:50:10,771 rfid_reader read_card_uid 리더기를 찾을 수 없습니다. 연결 상태를 확인하세요.
ERROR 2025-08-27 10:50:11,782 rfid_reader read_card_uid 리더기를 찾을 수 없습니다. 연결 상태를 확인하세요.
ERROR 2025-08-27 10:50:12,791 rfid_reader read_card_uid 리더기를 찾을 수 없습니다. 연결 상태를 확인하세요.
ERROR 2025-08-27 10:50:13,799 rfid_reader read_card_uid 리더기를 찾을 수 없습니다. 연결 상태를 확인하세요.
ERROR 2025-08-27 10:50:14,807 rfid_reader read_card_uid 리더기를 찾을 수 없습니다. 연결 상태를 확인하세요.
ERROR 2025-08-27 10:50:15,814 rfid_reader read_card_uid 리더기를 찾을 수 없습니다. 연결 상태를 확인하세요.
ERROR 2025-08-27 10:50:16,823 rfid_reader read_card_uid 리더기를 찾을 수 없습니다. 연결 상태를 확인하세요.
ERROR 2025-08-27 10:50:17,832 rfid_reader read_card_uid 리더기를 찾을 수 없습니다. 연결 상태를 확인하세요.
ERROR 2025-08-27 10:50:18,849 rfid_reader read_card_uid 리더기를 찾을 수 없습니다. 연결 상태를 확인하세요.
ERROR 2025-08-27 10:50:19,873 rfid_reader read_card_uid 리더기를 찾을 수 없습니다. 연결 상태를 확인하세요.
ERROR 2025-08-27 10:50:20,911 rfid_reader read_card_uid 리더기를 찾을 수 없습니다. 연결 상태를 확인하세요.
ERROR 2025-08-27 10:50:21,936 rfid_reader read_card_uid 리더기를 찾을 수 없습니다. 연결 상태를 확인하세요.
ERROR 2025-08-27 10:50:22,945 rfid_reader read_card_uid 리더기를 찾을 수 없습니다. 연결 상태를 확인하세요.
ERROR 2025-08-27 10:50:23,953 rfid_reader read_card_uid 리더기를 찾을 수 없습니다. 연결 상태를 확인하세요.
ERROR 2025-08-27 10:50:24,962 rfid_reader read_card_uid 리더기를 찾을 수 없습니다. 연결 상태를 확인하세요.
ERROR 2025-08-27 10:50:25,971 rfid_reader read_card_uid 리더기를 찾을 수 없습니다. 연결 상태를 확인하세요.
ERROR 2025-08-27 10:50:26,981 rfid_reader read_card_uid 리더기를 찾을 수 없습니다. 연결 상태를 확인하세요.
ERROR 2025-08-27 10:50:27,990 rfid_reader read_card_uid 리더기를 찾을 수 없습니다. 연결 상태를 확인하세요.
ERROR 2025-08-27 10:50:29,000 rfid_reader read_card_uid 리더기를 찾을 수 없습니다. 연결 상태를 확인하세요.
ERROR 2025-08-27 10:50:30,010 rfid_reader read_card_uid 리더기를 찾을 수 없습니다. 연결 상태를 확인하세요.
ERROR 2025-08-27 10:50:31,094 rfid_reader read_card_uid 리더기를 찾을 수 없습니다. 연결 상태를 확인하세요.
ERROR 2025-08-27 13:27:36,567 rfid_reader read_card_uid 리더기를 찾을 수 없습니다. 연결 상태를 확인하세요.
ERROR 2025-08-27 13:27:37,875 rfid_reader read_card_uid 리더기를 찾을 수 없습니다. 연결 상태를 확인하세요.
ERROR 2025-08-27 13:27:39,014 rfid_reader read_card_uid 리더기를 찾을 수 없습니다. 연결 상태를 확인하세요.
ERROR 2025-08-27 13:27:40,024 rfid_reader read_card_uid 리더기를 찾을 수 없습니다. 연결 상태를 확인하세요.
ERROR 2025-08-27 13:27:41,034 rfid_reader read_card_uid 리더기를 찾을 수 없습니다. 연결 상태를 확인하세요.
ERROR 2025-08-27 13:27:42,041 rfid_reader read_card_uid 리더기를 찾을 수 없습니다. 연결 상태를 확인하세요.
ERROR 2025-08-27 13:27:43,050 rfid_reader read_card_uid 리더기를 찾을 수 없습니다. 연결 상태를 확인하세요.
ERROR 2025-08-27 13:27:44,375 rfid_reader read_card_uid 리더기를 찾을 수 없습니다. 연결 상태를 확인하세요.
ERROR 2025-08-27 13:27:45,386 rfid_reader read_card_uid 리더기를 찾을 수 없습니다. 연결 상태를 확인하세요.
ERROR 2025-08-27 13:27:46,416 rfid_reader read_card_uid 리더기를 찾을 수 없습니다. 연결 상태를 확인하세요.
ERROR 2025-08-27 13:27:47,428 rfid_reader read_card_uid 리더기를 찾을 수 없습니다. 연결 상태를 확인하세요.
ERROR 2025-08-27 13:27:48,439 rfid_reader read_card_uid 리더기를 찾을 수 없습니다. 연결 상태를 확인하세요.
ERROR 2025-08-27 13:27:49,450 rfid_reader read_card_uid 리더기를 찾을 수 없습니다. 연결 상태를 확인하세요.
ERROR 2025-08-27 13:27:50,462 rfid_reader read_card_uid 리더기를 찾을 수 없습니다. 연결 상태를 확인하세요.
ERROR 2025-08-27 13:27:51,471 rfid_reader read_card_uid 리더기를 찾을 수 없습니다. 연결 상태를 확인하세요.
ERROR 2025-08-27 13:27:52,479 rfid_reader read_card_uid 리더기를 찾을 수 없습니다. 연결 상태를 확인하세요.
ERROR 2025-08-27 13:27:53,498 rfid_reader read_card_uid 리더기를 찾을 수 없습니다. 연결 상태를 확인하세요.
ERROR 2025-08-27 13:27:54,505 rfid_reader read_card_uid 리더기를 찾을 수 없습니다. 연결 상태를 확인하세요.
ERROR 2025-08-27 13:27:55,511 rfid_reader read_card_uid 리더기를 찾을 수 없습니다. 연결 상태를 확인하세요.
ERROR 2025-08-27 13:27:56,518 rfid_reader read_card_uid 리더기를 찾을 수 없습니다. 연결 상태를 확인하세요.
ERROR 2025-08-27 13:27:57,525 rfid_reader read_card_uid 리더기를 찾을 수 없습니다. 연결 상태를 확인하세요.
ERROR 2025-08-27 13:27:58,534 rfid_reader read_card_uid 리더기를 찾을 수 없습니다. 연결 상태를 확인하세요.
ERROR 2025-08-27 13:27:59,544 rfid_reader read_card_uid 리더기를 찾을 수 없습니다. 연결 상태를 확인하세요.
ERROR 2025-08-27 13:28:00,553 rfid_reader read_card_uid 리더기를 찾을 수 없습니다. 연결 상태를 확인하세요.
ERROR 2025-09-01 09:21:08,742 rfid_reader read_card_uid 리더기를 찾을 수 없습니다. 연결 상태를 확인하세요.
ERROR 2025-09-01 09:21:09,751 rfid_reader read_card_uid 리더기를 찾을 수 없습니다. 연결 상태를 확인하세요.
ERROR 2025-09-01 09:21:11,021 rfid_reader read_card_uid 리더기를 찾을 수 없습니다. 연결 상태를 확인하세요.
ERROR 2025-09-01 09:21:12,029 rfid_reader read_card_uid 리더기를 찾을 수 없습니다. 연결 상태를 확인하세요.
ERROR 2025-09-01 09:21:13,048 rfid_reader read_card_uid 리더기를 찾을 수 없습니다. 연결 상태를 확인하세요.
ERROR 2025-09-01 09:21:14,056 rfid_reader read_card_uid 리더기를 찾을 수 없습니다. 연결 상태를 확인하세요.
ERROR 2025-09-01 09:21:15,065 rfid_reader read_card_uid 리더기를 찾을 수 없습니다. 연결 상태를 확인하세요.
ERROR 2025-09-01 09:21:16,074 rfid_reader read_card_uid 리더기를 찾을 수 없습니다. 연결 상태를 확인하세요.
ERROR 2025-09-01 09:21:17,084 rfid_reader read_card_uid 리더기를 찾을 수 없습니다. 연결 상태를 확인하세요.
ERROR 2025-09-01 09:21:18,093 rfid_reader read_card_uid 리더기를 찾을 수 없습니다. 연결 상태를 확인하세요.
ERROR 2025-09-01 09:21:19,104 rfid_reader read_card_uid 리더기를 찾을 수 없습니다. 연결 상태를 확인하세요.
ERROR 2025-09-01 09:21:20,115 rfid_reader read_card_uid 리더기를 찾을 수 없습니다. 연결 상태를 확인하세요.
ERROR 2025-09-01 09:21:21,125 rfid_reader read_card_uid 리더기를 찾을 수 없습니다. 연결 상태를 확인하세요.
ERROR 2025-09-01 09:21:22,134 rfid_reader read_card_uid 리더기를 찾을 수 없습니다. 연결 상태를 확인하세요.
ERROR 2025-09-01 09:21:23,142 rfid_reader read_card_uid 리더기를 찾을 수 없습니다. 연결 상태를 확인하세요.
ERROR 2025-09-01 09:21:24,152 rfid_reader read_card_uid 리더기를 찾을 수 없습니다. 연결 상태를 확인하세요.
ERROR 2025-09-01 09:21:25,160 rfid_reader read_card_uid 리더기를 찾을 수 없습니다. 연결 상태를 확인하세요.
ERROR 2025-09-01 09:21:26,169 rfid_reader read_card_uid 리더기를 찾을 수 없습니다. 연결 상태를 확인하세요.
ERROR 2025-09-01 09:21:27,178 rfid_reader read_card_uid 리더기를 찾을 수 없습니다. 연결 상태를 확인하세요.
ERROR 2025-09-01 09:21:28,186 rfid_reader read_card_uid 리더기를 찾을 수 없습니다. 연결 상태를 확인하세요.
ERROR 2025-09-01 09:21:29,195 rfid_reader read_card_uid 리더기를 찾을 수 없습니다. 연결 상태를 확인하세요.
ERROR 2025-09-01 09:21:30,205 rfid_reader read_card_uid 리더기를 찾을 수 없습니다. 연결 상태를 확인하세요.
ERROR 2025-09-01 09:21:31,214 rfid_reader read_card_uid 리더기를 찾을 수 없습니다. 연결 상태를 확인하세요.
ERROR 2025-09-01 09:21:32,222 rfid_reader read_card_uid 리더기를 찾을 수 없습니다. 연결 상태를 확인하세요.
ERROR 2025-09-01 09:21:33,231 rfid_reader read_card_uid 리더기를 찾을 수 없습니다. 연결 상태를 확인하세요.
ERROR 2025-09-01 09:21:34,239 rfid_reader read_card_uid 리더기를 찾을 수 없습니다. 연결 상태를 확인하세요.
ERROR 2025-09-01 09:21:35,248 rfid_reader read_card_uid 리더기를 찾을 수 없습니다. 연결 상태를 확인하세요.
ERROR 2025-09-01 09:21:36,257 rfid_reader read_card_uid 리더기를 찾을 수 없습니다. 연결 상태를 확인하세요.
ERROR 2025-09-01 09:21:37,266 rfid_reader read_card_uid 리더기를 찾을 수 없습니다. 연결 상태를 확인하세요.
ERROR 2025-09-01 09:21:38,275 rfid_reader read_card_uid 리더기를 찾을 수 없습니다. 연결 상태를 확인하세요.
ERROR 2025-09-01 09:21:39,283 rfid_reader read_card_uid 리더기를 찾을 수 없습니다. 연결 상태를 확인하세요.
ERROR 2025-09-01 09:21:40,291 rfid_reader read_card_uid 리더기를 찾을 수 없습니다. 연결 상태를 확인하세요.
ERROR 2025-09-01 09:21:41,300 rfid_reader read_card_uid 리더기를 찾을 수 없습니다. 연결 상태를 확인하세요.
ERROR 2025-09-01 09:21:42,307 rfid_reader read_card_uid 리더기를 찾을 수 없습니다. 연결 상태를 확인하세요.
ERROR 2025-09-01 09:21:43,314 rfid_reader read_card_uid 리더기를 찾을 수 없습니다. 연결 상태를 확인하세요.
ERROR 2025-09-01 09:21:44,321 rfid_reader read_card_uid 리더기를 찾을 수 없습니다. 연결 상태를 확인하세요.
ERROR 2025-09-01 09:21:45,330 rfid_reader read_card_uid 리더기를 찾을 수 없습니다. 연결 상태를 확인하세요.
ERROR 2025-09-01 09:21:46,338 rfid_reader read_card_uid 리더기를 찾을 수 없습니다. 연결 상태를 확인하세요.
ERROR 2025-09-01 09:21:47,346 rfid_reader read_card_uid 리더기를 찾을 수 없습니다. 연결 상태를 확인하세요.
ERROR 2025-09-01 09:21:48,354 rfid_reader read_card_uid 리더기를 찾을 수 없습니다. 연결 상태를 확인하세요.
ERROR 2025-09-01 09:21:49,360 rfid_reader read_card_uid 리더기를 찾을 수 없습니다. 연결 상태를 확인하세요.
ERROR 2025-09-01 09:21:50,368 rfid_reader read_card_uid 리더기를 찾을 수 없습니다. 연결 상태를 확인하세요.
ERROR 2025-09-01 09:21:51,376 rfid_reader read_card_uid 리더기를 찾을 수 없습니다. 연결 상태를 확인하세요.
ERROR 2025-09-01 09:21:52,384 rfid_reader read_card_uid 리더기를 찾을 수 없습니다. 연결 상태를 확인하세요.
ERROR 2025-09-01 09:21:53,391 rfid_reader read_card_uid 리더기를 찾을 수 없습니다. 연결 상태를 확인하세요.
ERROR 2025-09-01 09:21:54,400 rfid_reader read_card_uid 리더기를 찾을 수 없습니다. 연결 상태를 확인하세요.
ERROR 2025-09-01 09:21:55,409 rfid_reader read_card_uid 리더기를 찾을 수 없습니다. 연결 상태를 확인하세요.
ERROR 2025-09-01 09:21:56,417 rfid_reader read_card_uid 리더기를 찾을 수 없습니다. 연결 상태를 확인하세요.
ERROR 2025-09-01 09:21:57,424 rfid_reader read_card_uid 리더기를 찾을 수 없습니다. 연결 상태를 확인하세요.
ERROR 2025-09-01 09:21:58,437 rfid_reader read_card_uid 리더기를 찾을 수 없습니다. 연결 상태를 확인하세요.
ERROR 2025-09-01 09:21:59,477 rfid_reader read_card_uid 리더기를 찾을 수 없습니다. 연결 상태를 확인하세요.
ERROR 2025-09-01 09:22:00,488 rfid_reader read_card_uid 리더기를 찾을 수 없습니다. 연결 상태를 확인하세요.
ERROR 2025-09-01 09:22:01,497 rfid_reader read_card_uid 리더기를 찾을 수 없습니다. 연결 상태를 확인하세요.
ERROR 2025-09-01 09:22:02,511 rfid_reader read_card_uid 리더기를 찾을 수 없습니다. 연결 상태를 확인하세요.
ERROR 2025-09-01 09:22:03,524 rfid_reader read_card_uid 리더기를 찾을 수 없습니다. 연결 상태를 확인하세요.
ERROR 2025-09-01 09:22:04,538 rfid_reader read_card_uid 리더기를 찾을 수 없습니다. 연결 상태를 확인하세요.
ERROR 2025-09-01 09:22:05,548 rfid_reader read_card_uid 리더기를 찾을 수 없습니다. 연결 상태를 확인하세요.
ERROR 2025-09-01 09:22:06,558 rfid_reader read_card_uid 리더기를 찾을 수 없습니다. 연결 상태를 확인하세요.
ERROR 2025-09-01 09:22:07,567 rfid_reader read_card_uid 리더기를 찾을 수 없습니다. 연결 상태를 확인하세요.
ERROR 2025-09-01 09:22:08,576 rfid_reader read_card_uid 리더기를 찾을 수 없습니다. 연결 상태를 확인하세요.
ERROR 2025-09-01 09:22:09,584 rfid_reader read_card_uid 리더기를 찾을 수 없습니다. 연결 상태를 확인하세요.
ERROR 2025-09-01 09:22:10,592 rfid_reader read_card_uid 리더기를 찾을 수 없습니다. 연결 상태를 확인하세요.
ERROR 2025-09-01 09:22:11,601 rfid_reader read_card_uid 리더기를 찾을 수 없습니다. 연결 상태를 확인하세요.
ERROR 2025-09-01 09:22:12,609 rfid_reader read_card_uid 리더기를 찾을 수 없습니다. 연결 상태를 확인하세요.
ERROR 2025-09-01 09:22:13,618 rfid_reader read_card_uid 리더기를 찾을 수 없습니다. 연결 상태를 확인하세요.
ERROR 2025-09-01 09:22:14,627 rfid_reader read_card_uid 리더기를 찾을 수 없습니다. 연결 상태를 확인하세요.
ERROR 2025-09-01 09:22:15,634 rfid_reader read_card_uid 리더기를 찾을 수 없습니다. 연결 상태를 확인하세요.
ERROR 2025-09-01 09:22:16,642 rfid_reader read_card_uid 리더기를 찾을 수 없습니다. 연결 상태를 확인하세요.
ERROR 2025-09-01 09:22:17,651 rfid_reader read_card_uid 리더기를 찾을 수 없습니다. 연결 상태를 확인하세요.
ERROR 2025-09-01 09:22:18,661 rfid_reader read_card_uid 리더기를 찾을 수 없습니다. 연결 상태를 확인하세요.
ERROR 2025-09-01 09:22:19,670 rfid_reader read_card_uid 리더기를 찾을 수 없습니다. 연결 상태를 확인하세요.
ERROR 2025-09-01 09:22:20,679 rfid_reader read_card_uid 리더기를 찾을 수 없습니다. 연결 상태를 확인하세요.
ERROR 2025-09-01 09:22:21,687 rfid_reader read_card_uid 리더기를 찾을 수 없습니다. 연결 상태를 확인하세요.
ERROR 2025-09-01 09:22:22,696 rfid_reader read_card_uid 리더기를 찾을 수 없습니다. 연결 상태를 확인하세요.
ERROR 2025-09-01 09:22:23,705 rfid_reader read_card_uid 리더기를 찾을 수 없습니다. 연결 상태를 확인하세요.
ERROR 2025-09-01 09:22:24,714 rfid_reader read_card_uid 리더기를 찾을 수 없습니다. 연결 상태를 확인하세요.
ERROR 2025-09-01 09:22:25,722 rfid_reader read_card_uid 리더기를 찾을 수 없습니다. 연결 상태를 확인하세요.
ERROR 2025-09-01 09:22:26,732 rfid_reader read_card_uid 리더기를 찾을 수 없습니다. 연결 상태를 확인하세요.
ERROR 2025-09-01 09:22:27,740 rfid_reader read_card_uid 리더기를 찾을 수 없습니다. 연결 상태를 확인하세요.
ERROR 2025-09-01 09:22:28,749 rfid_reader read_card_uid 리더기를 찾을 수 없습니다. 연결 상태를 확인하세요.
ERROR 2025-09-01 09:22:29,757 rfid_reader read_card_uid 리더기를 찾을 수 없습니다. 연결 상태를 확인하세요.
ERROR 2025-09-01 09:22:30,765 rfid_reader read_card_uid 리더기를 찾을 수 없습니다. 연결 상태를 확인하세요.
ERROR 2025-09-01 09:22:31,774 rfid_reader read_card_uid 리더기를 찾을 수 없습니다. 연결 상태를 확인하세요.
ERROR 2025-09-01 09:22:32,782 rfid_reader read_card_uid 리더기를 찾을 수 없습니다. 연결 상태를 확인하세요.
ERROR 2025-09-01 09:22:33,792 rfid_reader read_card_uid 리더기를 찾을 수 없습니다. 연결 상태를 확인하세요.
ERROR 2025-09-01 09:22:34,802 rfid_reader read_card_uid 리더기를 찾을 수 없습니다. 연결 상태를 확인하세요.
ERROR 2025-09-01 09:22:35,810 rfid_reader read_card_uid 리더기를 찾을 수 없습니다. 연결 상태를 확인하세요.
ERROR 2025-09-01 09:22:36,817 rfid_reader read_card_uid 리더기를 찾을 수 없습니다. 연결 상태를 확인하세요.
ERROR 2025-09-01 09:22:37,825 rfid_reader read_card_uid 리더기를 찾을 수 없습니다. 연결 상태를 확인하세요.
ERROR 2025-09-01 09:22:38,836 rfid_reader read_card_uid 리더기를 찾을 수 없습니다. 연결 상태를 확인하세요.
ERROR 2025-09-01 09:22:39,962 rfid_reader read_card_uid 리더기를 찾을 수 없습니다. 연결 상태를 확인하세요.
ERROR 2025-09-01 09:22:40,970 rfid_reader read_card_uid 리더기를 찾을 수 없습니다. 연결 상태를 확인하세요.
ERROR 2025-09-01 09:22:41,979 rfid_reader read_card_uid 리더기를 찾을 수 없습니다. 연결 상태를 확인하세요.
ERROR 2025-09-01 09:22:42,986 rfid_reader read_card_uid 리더기를 찾을 수 없습니다. 연결 상태를 확인하세요.
ERROR 2025-09-01 09:22:43,994 rfid_reader read_card_uid 리더기를 찾을 수 없습니다. 연결 상태를 확인하세요.
ERROR 2025-09-01 09:22:45,014 rfid_reader read_card_uid 리더기를 찾을 수 없습니다. 연결 상태를 확인하세요.
ERROR 2025-09-01 09:22:46,028 rfid_reader read_card_uid 리더기를 찾을 수 없습니다. 연결 상태를 확인하세요.
ERROR 2025-09-01 09:22:47,042 rfid_reader read_card_uid 리더기를 찾을 수 없습니다. 연결 상태를 확인하세요.
ERROR 2025-09-01 09:22:48,050 rfid_reader read_card_uid 리더기를 찾을 수 없습니다. 연결 상태를 확인하세요.
ERROR 2025-09-01 09:22:49,058 rfid_reader read_card_uid 리더기를 찾을 수 없습니다. 연결 상태를 확인하세요.
ERROR 2025-09-01 09:22:50,066 rfid_reader read_card_uid 리더기를 찾을 수 없습니다. 연결 상태를 확인하세요.
ERROR 2025-09-01 09:22:51,075 rfid_reader read_card_uid 리더기를 찾을 수 없습니다. 연결 상태를 확인하세요.
ERROR 2025-09-01 09:22:52,084 rfid_reader read_card_uid 리더기를 찾을 수 없습니다. 연결 상태를 확인하세요.
ERROR 2025-09-01 09:22:53,093 rfid_reader read_card_uid 리더기를 찾을 수 없습니다. 연결 상태를 확인하세요.
ERROR 2025-09-01 09:22:54,106 rfid_reader read_card_uid 리더기를 찾을 수 없습니다. 연결 상태를 확인하세요.
ERROR 2025-09-01 09:22:55,115 rfid_reader read_card_uid 리더기를 찾을 수 없습니다. 연결 상태를 확인하세요.
ERROR 2025-09-01 09:22:56,122 rfid_reader read_card_uid 리더기를 찾을 수 없습니다. 연결 상태를 확인하세요.
ERROR 2025-09-01 09:22:57,130 rfid_reader read_card_uid 리더기를 찾을 수 없습니다. 연결 상태를 확인하세요.
ERROR 2025-09-01 09:22:58,138 rfid_reader read_card_uid 리더기를 찾을 수 없습니다. 연결 상태를 확인하세요.
ERROR 2025-09-01 09:22:59,146 rfid_reader read_card_uid 리더기를 찾을 수 없습니다. 연결 상태를 확인하세요.
ERROR 2025-09-01 09:23:00,155 rfid_reader read_card_uid 리더기를 찾을 수 없습니다. 연결 상태를 확인하세요.
ERROR 2025-09-01 09:23:01,164 rfid_reader read_card_uid 리더기를 찾을 수 없습니다. 연결 상태를 확인하세요.
ERROR 2025-09-01 09:23:02,176 rfid_reader read_card_uid 리더기를 찾을 수 없습니다. 연결 상태를 확인하세요.
ERROR 2025-09-01 09:23:03,185 rfid_reader read_card_uid 리더기를 찾을 수 없습니다. 연결 상태를 확인하세요.
ERROR 2025-09-01 09:23:04,194 rfid_reader read_card_uid 리더기를 찾을 수 없습니다. 연결 상태를 확인하세요.
ERROR 2025-09-01 09:23:05,208 rfid_reader read_card_uid 리더기를 찾을 수 없습니다. 연결 상태를 확인하세요.
ERROR 2025-09-01 09:23:06,215 rfid_reader read_card_uid 리더기를 찾을 수 없습니다. 연결 상태를 확인하세요.
ERROR 2025-09-01 09:23:07,222 rfid_reader read_card_uid 리더기를 찾을 수 없습니다. 연결 상태를 확인하세요.
ERROR 2025-09-01 09:23:08,229 rfid_reader read_card_uid 리더기를 찾을 수 없습니다. 연결 상태를 확인하세요.
ERROR 2025-09-01 09:23:09,237 rfid_reader read_card_uid 리더기를 찾을 수 없습니다. 연결 상태를 확인하세요.
ERROR 2025-09-01 09:23:10,250 rfid_reader read_card_uid 리더기를 찾을 수 없습니다. 연결 상태를 확인하세요.
ERROR 2025-09-01 09:23:11,259 rfid_reader read_card_uid 리더기를 찾을 수 없습니다. 연결 상태를 확인하세요.
ERROR 2025-09-01 09:23:12,268 rfid_reader read_card_uid 리더기를 찾을 수 없습니다. 연결 상태를 확인하세요.
ERROR 2025-09-01 09:23:13,275 rfid_reader read_card_uid 리더기를 찾을 수 없습니다. 연결 상태를 확인하세요.
ERROR 2025-09-01 09:23:14,282 rfid_reader read_card_uid 리더기를 찾을 수 없습니다. 연결 상태를 확인하세요.
ERROR 2025-09-01 09:23:15,288 rfid_reader read_card_uid 리더기를 찾을 수 없습니다. 연결 상태를 확인하세요.
ERROR 2025-09-01 09:23:16,297 rfid_reader read_card_uid 리더기를 찾을 수 없습니다. 연결 상태를 확인하세요.
ERROR 2025-09-01 09:23:17,304 rfid_reader read_card_uid 리더기를 찾을 수 없습니다. 연결 상태를 확인하세요.
ERROR 2025-09-01 09:23:18,314 rfid_reader read_card_uid 리더기를 찾을 수 없습니다. 연결 상태를 확인하세요.
ERROR 2025-09-01 09:23:19,323 rfid_reader read_card_uid 리더기를 찾을 수 없습니다. 연결 상태를 확인하세요.
ERROR 2025-09-01 09:23:20,333 rfid_reader read_card_uid 리더기를 찾을 수 없습니다. 연결 상태를 확인하세요.
ERROR 2025-09-01 09:23:21,345 rfid_reader read_card_uid 리더기를 찾을 수 없습니다. 연결 상태를 확인하세요.
ERROR 2025-09-01 09:23:22,353 rfid_reader read_card_uid 리더기를 찾을 수 없습니다. 연결 상태를 확인하세요.
ERROR 2025-09-01 09:23:23,361 rfid_reader read_card_uid 리더기를 찾을 수 없습니다. 연결 상태를 확인하세요.
ERROR 2025-09-01 09:23:24,369 rfid_reader read_card_uid 리더기를 찾을 수 없습니다. 연결 상태를 확인하세요.
ERROR 2025-09-01 09:23:25,377 rfid_reader read_card_uid 리더기를 찾을 수 없습니다. 연결 상태를 확인하세요.
ERROR 2025-09-01 09:23:26,389 rfid_reader read_card_uid 리더기를 찾을 수 없습니다. 연결 상태를 확인하세요.
ERROR 2025-09-01 09:23:27,397 rfid_reader read_card_uid 리더기를 찾을 수 없습니다. 연결 상태를 확인하세요.
ERROR 2025-09-01 09:23:28,405 rfid_reader read_card_uid 리더기를 찾을 수 없습니다. 연결 상태를 확인하세요.
ERROR 2025-09-01 09:23:29,414 rfid_reader read_card_uid 리더기를 찾을 수 없습니다. 연결 상태를 확인하세요.
ERROR 2025-09-01 09:23:30,423 rfid_reader read_card_uid 리더기를 찾을 수 없습니다. 연결 상태를 확인하세요.
ERROR 2025-09-01 09:23:31,431 rfid_reader read_card_uid 리더기를 찾을 수 없습니다. 연결 상태를 확인하세요.
ERROR 2025-09-01 09:23:32,438 rfid_reader read_card_uid 리더기를 찾을 수 없습니다. 연결 상태를 확인하세요.
ERROR 2025-09-01 09:23:33,452 rfid_reader read_card_uid 리더기를 찾을 수 없습니다. 연결 상태를 확인하세요.
ERROR 2025-09-01 09:23:34,466 rfid_reader read_card_uid 리더기를 찾을 수 없습니다. 연결 상태를 확인하세요.
ERROR 2025-09-01 09:23:35,482 rfid_reader read_card_uid 리더기를 찾을 수 없습니다. 연결 상태를 확인하세요.
ERROR 2025-09-01 09:23:36,490 rfid_reader read_card_uid 리더기를 찾을 수 없습니다. 연결 상태를 확인하세요.
ERROR 2025-09-01 09:23:37,498 rfid_reader read_card_uid 리더기를 찾을 수 없습니다. 연결 상태를 확인하세요.
ERROR 2025-09-01 09:23:38,506 rfid_reader read_card_uid 리더기를 찾을 수 없습니다. 연결 상태를 확인하세요.
ERROR 2025-09-01 09:23:39,515 rfid_reader read_card_uid 리더기를 찾을 수 없습니다. 연결 상태를 확인하세요.
ERROR 2025-09-01 09:23:40,525 rfid_reader read_card_uid 리더기를 찾을 수 없습니다. 연결 상태를 확인하세요.
ERROR 2025-09-01 09:23:41,533 rfid_reader read_card_uid 리더기를 찾을 수 없습니다. 연결 상태를 확인하세요.
ERROR 2025-09-01 09:23:42,542 rfid_reader read_card_uid 리더기를 찾을 수 없습니다. 연결 상태를 확인하세요.
ERROR 2025-09-01 09:23:43,552 rfid_reader read_card_uid 리더기를 찾을 수 없습니다. 연결 상태를 확인하세요.
ERROR 2025-09-01 09:23:44,565 rfid_reader read_card_uid 리더기를 찾을 수 없습니다. 연결 상태를 확인하세요.
ERROR 2025-09-01 09:23:45,573 rfid_reader read_card_uid 리더기를 찾을 수 없습니다. 연결 상태를 확인하세요.
ERROR 2025-09-01 09:23:46,581 rfid_reader read_card_uid 리더기를 찾을 수 없습니다. 연결 상태를 확인하세요.
ERROR 2025-09-01 09:23:47,589 rfid_reader read_card_uid 리더기를 찾을 수 없습니다. 연결 상태를 확인하세요.
ERROR 2025-09-01 09:23:48,597 rfid_reader read_card_uid 리더기를 찾을 수 없습니다. 연결 상태를 확인하세요.
ERROR 2025-09-01 09:23:49,611 rfid_reader read_card_uid 리더기를 찾을 수 없습니다. 연결 상태를 확인하세요.
ERROR 2025-09-01 09:23:50,620 rfid_reader read_card_uid 리더기를 찾을 수 없습니다. 연결 상태를 확인하세요.
ERROR 2025-09-01 09:23:51,628 rfid_reader read_card_uid 리더기를 찾을 수 없습니다. 연결 상태를 확인하세요.
ERROR 2025-09-01 09:23:52,637 rfid_reader read_card_uid 리더기를 찾을 수 없습니다. 연결 상태를 확인하세요.
ERROR 2025-09-01 09:23:53,645 rfid_reader read_card_uid 리더기를 찾을 수 없습니다. 연결 상태를 확인하세요.
ERROR 2025-09-01 09:23:54,655 rfid_reader read_card_uid 리더기를 찾을 수 없습니다. 연결 상태를 확인하세요.
ERROR 2025-09-01 09:23:55,665 rfid_reader read_card_uid 리더기를 찾을 수 없습니다. 연결 상태를 확인하세요.
ERROR 2025-09-01 09:23:56,682 rfid_reader read_card_uid 리더기를 찾을 수 없습니다. 연결 상태를 확인하세요.
ERROR 2025-09-01 09:23:57,696 rfid_reader read_card_uid 리더기를 찾을 수 없습니다. 연결 상태를 확인하세요.
ERROR 2025-09-01 09:23:58,704 rfid_reader read_card_uid 리더기를 찾을 수 없습니다. 연결 상태를 확인하세요.
ERROR 2025-09-01 09:23:59,712 rfid_reader read_card_uid 리더기를 찾을 수 없습니다. 연결 상태를 확인하세요.
ERROR 2025-09-01 09:24:00,720 rfid_reader read_card_uid 리더기를 찾을 수 없습니다. 연결 상태를 확인하세요.
ERROR 2025-09-01 09:24:01,727 rfid_reader read_card_uid 리더기를 찾을 수 없습니다. 연결 상태를 확인하세요.
ERROR 2025-09-01 09:24:02,736 rfid_reader read_card_uid 리더기를 찾을 수 없습니다. 연결 상태를 확인하세요.
ERROR 2025-09-01 09:24:03,749 rfid_reader read_card_uid 리더기를 찾을 수 없습니다. 연결 상태를 확인하세요.
ERROR 2025-09-01 09:24:04,763 rfid_reader read_card_uid 리더기를 찾을 수 없습니다. 연결 상태를 확인하세요.
ERROR 2025-09-01 09:24:05,771 rfid_reader read_card_uid 리더기를 찾을 수 없습니다. 연결 상태를 확인하세요.
ERROR 2025-09-01 09:24:06,784 rfid_reader read_card_uid 리더기를 찾을 수 없습니다. 연결 상태를 확인하세요.
ERROR 2025-09-01 09:24:07,798 rfid_reader read_card_uid 리더기를 찾을 수 없습니다. 연결 상태를 확인하세요.
ERROR 2025-09-01 09:24:08,807 rfid_reader read_card_uid 리더기를 찾을 수 없습니다. 연결 상태를 확인하세요.
ERROR 2025-09-01 09:24:09,816 rfid_reader read_card_uid 리더기를 찾을 수 없습니다. 연결 상태를 확인하세요.
ERROR 2025-09-01 09:24:10,824 rfid_reader read_card_uid 리더기를 찾을 수 없습니다. 연결 상태를 확인하세요.
ERROR 2025-09-01 09:24:11,833 rfid_reader read_card_uid 리더기를 찾을 수 없습니다. 연결 상태를 확인하세요.
ERROR 2025-09-01 09:24:12,842 rfid_reader read_card_uid 리더기를 찾을 수 없습니다. 연결 상태를 확인하세요.
ERROR 2025-09-01 09:24:13,851 rfid_reader read_card_uid 리더기를 찾을 수 없습니다. 연결 상태를 확인하세요.
ERROR 2025-09-01 09:24:14,860 rfid_reader read_card_uid 리더기를 찾을 수 없습니다. 연결 상태를 확인하세요.
ERROR 2025-09-01 09:24:15,868 rfid_reader read_card_uid 리더기를 찾을 수 없습니다. 연결 상태를 확인하세요.
ERROR 2025-09-01 09:24:16,881 rfid_reader read_card_uid 리더기를 찾을 수 없습니다. 연결 상태를 확인하세요.
ERROR 2025-09-01 09:24:17,890 rfid_reader read_card_uid 리더기를 찾을 수 없습니다. 연결 상태를 확인하세요.
ERROR 2025-09-01 09:24:18,897 rfid_reader read_card_uid 리더기를 찾을 수 없습니다. 연결 상태를 확인하세요.
ERROR 2025-09-01 09:24:19,905 rfid_reader read_card_uid 리더기를 찾을 수 없습니다. 연결 상태를 확인하세요.
ERROR 2025-09-01 09:24:20,911 rfid_reader read_card_uid 리더기를 찾을 수 없습니다. 연결 상태를 확인하세요.
ERROR 2025-09-01 09:24:21,919 rfid_reader read_card_uid 리더기를 찾을 수 없습니다. 연결 상태를 확인하세요.
ERROR 2025-09-01 09:24:22,927 rfid_reader read_card_uid 리더기를 찾을 수 없습니다. 연결 상태를 확인하세요.
ERROR 2025-09-01 09:24:23,934 rfid_reader read_card_uid 리더기를 찾을 수 없습니다. 연결 상태를 확인하세요.
ERROR 2025-09-01 09:24:24,942 rfid_reader read_card_uid 리더기를 찾을 수 없습니다. 연결 상태를 확인하세요.
ERROR 2025-09-01 09:24:25,951 rfid_reader read_card_uid 리더기를 찾을 수 없습니다. 연결 상태를 확인하세요.
ERROR 2025-09-01 09:24:26,962 rfid_reader read_card_uid 리더기를 찾을 수 없습니다. 연결 상태를 확인하세요.
ERROR 2025-09-01 09:24:27,970 rfid_reader read_card_uid 리더기를 찾을 수 없습니다. 연결 상태를 확인하세요.
ERROR 2025-09-01 09:24:28,980 rfid_reader read_card_uid 리더기를 찾을 수 없습니다. 연결 상태를 확인하세요.
ERROR 2025-09-01 09:24:29,990 rfid_reader read_card_uid 리더기를 찾을 수 없습니다. 연결 상태를 확인하세요.
ERROR 2025-09-01 09:24:30,999 rfid_reader read_card_uid 리더기를 찾을 수 없습니다. 연결 상태를 확인하세요.
ERROR 2025-09-01 09:24:32,009 rfid_reader read_card_uid 리더기를 찾을 수 없습니다. 연결 상태를 확인하세요.
ERROR 2025-09-01 09:24:33,018 rfid_reader read_card_uid 리더기를 찾을 수 없습니다. 연결 상태를 확인하세요.
ERROR 2025-09-01 09:24:34,028 rfid_reader read_card_uid 리더기를 찾을 수 없습니다. 연결 상태를 확인하세요.
ERROR 2025-09-01 09:24:35,036 rfid_reader read_card_uid 리더기를 찾을 수 없습니다. 연결 상태를 확인하세요.
ERROR 2025-09-01 09:24:36,044 rfid_reader read_card_uid 리더기를 찾을 수 없습니다. 연결 상태를 확인하세요.
ERROR 2025-09-01 09:24:37,059 rfid_reader read_card_uid 리더기를 찾을 수 없습니다. 연결 상태를 확인하세요.
ERROR 2025-09-01 09:24:38,070 rfid_reader read_card_uid 리더기를 찾을 수 없습니다. 연결 상태를 확인하세요.
ERROR 2025-09-01 09:24:39,076 rfid_reader read_card_uid 리더기를 찾을 수 없습니다. 연결 상태를 확인하세요.
ERROR 2025-09-01 09:24:40,082 rfid_reader read_card_uid 리더기를 찾을 수 없습니다. 연결 상태를 확인하세요.
ERROR 2025-09-01 09:24:41,089 rfid_reader read_card_uid 리더기를 찾을 수 없습니다. 연결 상태를 확인하세요.
ERROR 2025-09-01 09:24:42,098 rfid_reader read_card_uid 리더기를 찾을 수 없습니다. 연결 상태를 확인하세요.
ERROR 2025-09-01 09:24:43,111 rfid_reader read_card_uid 리더기를 찾을 수 없습니다. 연결 상태를 확인하세요.
ERROR 2025-09-01 09:24:44,119 rfid_reader read_card_uid 리더기를 찾을 수 없습니다. 연결 상태를 확인하세요.
ERROR 2025-09-01 09:24:45,127 rfid_reader read_card_uid 리더기를 찾을 수 없습니다. 연결 상태를 확인하세요.
ERROR 2025-09-01 09:24:46,135 rfid_reader read_card_uid 리더기를 찾을 수 없습니다. 연결 상태를 확인하세요.
ERROR 2025-09-01 09:24:47,143 rfid_reader read_card_uid 리더기를 찾을 수 없습니다. 연결 상태를 확인하세요.
ERROR 2025-09-01 09:24:48,152 rfid_reader read_card_uid 리더기를 찾을 수 없습니다. 연결 상태를 확인하세요.
ERROR 2025-09-01 09:24:49,160 rfid_reader read_card_uid 리더기를 찾을 수 없습니다. 연결 상태를 확인하세요.
ERROR 2025-09-01 09:24:50,168 rfid_reader read_card_uid 리더기를 찾을 수 없습니다. 연결 상태를 확인하세요.
ERROR 2025-09-01 09:24:51,177 rfid_reader read_card_uid 리더기를 찾을 수 없습니다. 연결 상태를 확인하세요.
ERROR 2025-09-01 09:24:52,186 rfid_reader read_card_uid 리더기를 찾을 수 없습니다. 연결 상태를 확인하세요.
ERROR 2025-09-01 09:24:53,196 rfid_reader read_card_uid 리더기를 찾을 수 없습니다. 연결 상태를 확인하세요.
ERROR 2025-09-01 09:24:54,205 rfid_reader read_card_uid 리더기를 찾을 수 없습니다. 연결 상태를 확인하세요.
ERROR 2025-09-01 09:24:55,214 rfid_reader read_card_uid 리더기를 찾을 수 없습니다. 연결 상태를 확인하세요.
ERROR 2025-09-01 09:24:56,221 rfid_reader read_card_uid 리더기를 찾을 수 없습니다. 연결 상태를 확인하세요.
ERROR 2025-09-01 09:24:57,229 rfid_reader read_card_uid 리더기를 찾을 수 없습니다. 연결 상태를 확인하세요.
ERROR 2025-09-01 09:24:58,237 rfid_reader read_card_uid 리더기를 찾을 수 없습니다. 연결 상태를 확인하세요.
ERROR 2025-09-01 09:24:59,245 rfid_reader read_card_uid 리더기를 찾을 수 없습니다. 연결 상태를 확인하세요.
ERROR 2025-09-01 09:25:00,254 rfid_reader read_card_uid 리더기를 찾을 수 없습니다. 연결 상태를 확인하세요.
ERROR 2025-09-01 09:25:01,261 rfid_reader read_card_uid 리더기를 찾을 수 없습니다. 연결 상태를 확인하세요.
ERROR 2025-09-01 09:25:02,268 rfid_reader read_card_uid 리더기를 찾을 수 없습니다. 연결 상태를 확인하세요.
ERROR 2025-09-01 09:25:03,275 rfid_reader read_card_uid 리더기를 찾을 수 없습니다. 연결 상태를 확인하세요.
ERROR 2025-09-01 09:25:04,284 rfid_reader read_card_uid 리더기를 찾을 수 없습니다. 연결 상태를 확인하세요.
ERROR 2025-09-01 09:25:05,292 rfid_reader read_card_uid 리더기를 찾을 수 없습니다. 연결 상태를 확인하세요.
ERROR 2025-09-01 09:25:06,298 rfid_reader read_card_uid 리더기를 찾을 수 없습니다. 연결 상태를 확인하세요.
ERROR 2025-09-01 09:25:07,305 rfid_reader read_card_uid 리더기를 찾을 수 없습니다. 연결 상태를 확인하세요.
ERROR 2025-09-01 09:25:08,316 rfid_reader read_card_uid 리더기를 찾을 수 없습니다. 연결 상태를 확인하세요.
ERROR 2025-09-01 09:25:09,326 rfid_reader read_card_uid 리더기를 찾을 수 없습니다. 연결 상태를 확인하세요.
ERROR 2025-09-01 09:25:10,334 rfid_reader read_card_uid 리더기를 찾을 수 없습니다. 연결 상태를 확인하세요.
ERROR 2025-09-01 09:25:11,352 rfid_reader read_card_uid 리더기를 찾을 수 없습니다. 연결 상태를 확인하세요.
ERROR 2025-09-01 09:25:12,364 rfid_reader read_card_uid 리더기를 찾을 수 없습니다. 연결 상태를 확인하세요.
ERROR 2025-09-01 09:25:13,376 rfid_reader read_card_uid 리더기를 찾을 수 없습니다. 연결 상태를 확인하세요.
ERROR 2025-09-01 09:25:14,384 rfid_reader read_card_uid 리더기를 찾을 수 없습니다. 연결 상태를 확인하세요.
ERROR 2025-09-01 09:25:15,393 rfid_reader read_card_uid 리더기를 찾을 수 없습니다. 연결 상태를 확인하세요.
ERROR 2025-09-01 09:25:16,401 rfid_reader read_card_uid 리더기를 찾을 수 없습니다. 연결 상태를 확인하세요.
ERROR 2025-09-01 09:25:17,409 rfid_reader read_card_uid 리더기를 찾을 수 없습니다. 연결 상태를 확인하세요.
ERROR 2025-09-01 09:25:18,418 rfid_reader read_card_uid 리더기를 찾을 수 없습니다. 연결 상태를 확인하세요.
ERROR 2025-09-01 09:25:19,426 rfid_reader read_card_uid 리더기를 찾을 수 없습니다. 연결 상태를 확인하세요.
ERROR 2025-09-01 09:25:20,434 rfid_reader read_card_uid 리더기를 찾을 수 없습니다. 연결 상태를 확인하세요.
ERROR 2025-09-01 09:25:21,442 rfid_reader read_card_uid 리더기를 찾을 수 없습니다. 연결 상태를 확인하세요.
ERROR 2025-09-01 09:25:22,451 rfid_reader read_card_uid 리더기를 찾을 수 없습니다. 연결 상태를 확인하세요.
ERROR 2025-09-01 09:25:23,459 rfid_reader read_card_uid 리더기를 찾을 수 없습니다. 연결 상태를 확인하세요.
ERROR 2025-09-01 09:25:24,468 rfid_reader read_card_uid 리더기를 찾을 수 없습니다. 연결 상태를 확인하세요.
ERROR 2025-09-01 09:25:25,477 rfid_reader read_card_uid 리더기를 찾을 수 없습니다. 연결 상태를 확인하세요.
ERROR 2025-09-01 09:25:26,486 rfid_reader read_card_uid 리더기를 찾을 수 없습니다. 연결 상태를 확인하세요.
ERROR 2025-09-01 09:25:27,494 rfid_reader read_card_uid 리더기를 찾을 수 없습니다. 연결 상태를 확인하세요.
ERROR 2025-09-01 09:25:28,502 rfid_reader read_card_uid 리더기를 찾을 수 없습니다. 연결 상태를 확인하세요.
ERROR 2025-09-01 09:25:29,510 rfid_reader read_card_uid 리더기를 찾을 수 없습니다. 연결 상태를 확인하세요.
ERROR 2025-09-01 09:25:30,518 rfid_reader read_card_uid 리더기를 찾을 수 없습니다. 연결 상태를 확인하세요.
ERROR 2025-09-01 09:25:31,524 rfid_reader read_card_uid 리더기를 찾을 수 없습니다. 연결 상태를 확인하세요.
ERROR 2025-09-01 09:25:32,533 rfid_reader read_card_uid 리더기를 찾을 수 없습니다. 연결 상태를 확인하세요.
ERROR 2025-09-01 09:25:33,545 rfid_reader read_card_uid 리더기를 찾을 수 없습니다. 연결 상태를 확인하세요.
ERROR 2025-09-01 09:25:34,554 rfid_reader read_card_uid 리더기를 찾을 수 없습니다. 연결 상태를 확인하세요.
ERROR 2025-09-01 09:25:35,564 rfid_reader read_card_uid 리더기를 찾을 수 없습니다. 연결 상태를 확인하세요.
ERROR 2025-09-01 09:25:36,573 rfid_reader read_card_uid 리더기를 찾을 수 없습니다. 연결 상태를 확인하세요.
ERROR 2025-09-01 09:25:37,582 rfid_reader read_card_uid 리더기를 찾을 수 없습니다. 연결 상태를 확인하세요.
ERROR 2025-09-01 09:25:38,592 rfid_reader read_card_uid 리더기를 찾을 수 없습니다. 연결 상태를 확인하세요.
ERROR 2025-09-01 09:25:39,600 rfid_reader read_card_uid 리더기를 찾을 수 없습니다. 연결 상태를 확인하세요.
ERROR 2025-09-01 09:25:40,612 rfid_reader read_card_uid 리더기를 찾을 수 없습니다. 연결 상태를 확인하세요.
ERROR 2025-09-01 09:25:41,619 rfid_reader read_card_uid 리더기를 찾을 수 없습니다. 연결 상태를 확인하세요.
ERROR 2025-09-01 09:25:42,626 rfid_reader read_card_uid 리더기를 찾을 수 없습니다. 연결 상태를 확인하세요.
ERROR 2025-09-01 09:25:43,634 rfid_reader read_card_uid 리더기를 찾을 수 없습니다. 연결 상태를 확인하세요.
ERROR 2025-09-01 09:25:44,642 rfid_reader read_card_uid 리더기를 찾을 수 없습니다. 연결 상태를 확인하세요.
ERROR 2025-09-01 09:25:45,661 rfid_reader read_card_uid 리더기를 찾을 수 없습니다. 연결 상태를 확인하세요.
ERROR 2025-09-01 09:25:46,668 rfid_reader read_card_uid 리더기를 찾을 수 없습니다. 연결 상태를 확인하세요.
ERROR 2025-09-01 09:25:47,678 rfid_reader read_card_uid 리더기를 찾을 수 없습니다. 연결 상태를 확인하세요.
ERROR 2025-09-01 09:25:48,692 rfid_reader read_card_uid 리더기를 찾을 수 없습니다. 연결 상태를 확인하세요.
ERROR 2025-09-01 09:25:49,709 rfid_reader read_card_uid 리더기를 찾을 수 없습니다. 연결 상태를 확인하세요.
ERROR 2025-09-01 09:25:50,719 rfid_reader read_card_uid 리더기를 찾을 수 없습니다. 연결 상태를 확인하세요.
ERROR 2025-09-01 09:25:51,728 rfid_reader read_card_uid 리더기를 찾을 수 없습니다. 연결 상태를 확인하세요.
ERROR 2025-09-01 09:25:52,739 rfid_reader read_card_uid 리더기를 찾을 수 없습니다. 연결 상태를 확인하세요.
ERROR 2025-09-01 09:26:02,021 rfid_reader read_card_uid 리더기를 찾을 수 없습니다. 연결 상태를 확인하세요.
ERROR 2025-09-01 09:26:03,031 rfid_reader read_card_uid 리더기를 찾을 수 없습니다. 연결 상태를 확인하세요.
ERROR 2025-09-01 09:26:04,038 rfid_reader read_card_uid 리더기를 찾을 수 없습니다. 연결 상태를 확인하세요.
ERROR 2025-09-01 09:26:05,046 rfid_reader read_card_uid 리더기를 찾을 수 없습니다. 연결 상태를 확인하세요.
ERROR 2025-09-01 09:26:06,053 rfid_reader read_card_uid 리더기를 찾을 수 없습니다. 연결 상태를 확인하세요.
ERROR 2025-09-01 09:26:07,060 rfid_reader read_card_uid 리더기를 찾을 수 없습니다. 연결 상태를 확인하세요.
ERROR 2025-09-01 09:26:08,067 rfid_reader read_card_uid 리더기를 찾을 수 없습니다. 연결 상태를 확인하세요.
ERROR 2025-09-01 09:26:09,075 rfid_reader read_card_uid 리더기를 찾을 수 없습니다. 연결 상태를 확인하세요.
ERROR 2025-09-01 09:26:10,083 rfid_reader read_card_uid 리더기를 찾을 수 없습니다. 연결 상태를 확인하세요.
ERROR 2025-09-01 09:26:11,091 rfid_reader read_card_uid 리더기를 찾을 수 없습니다. 연결 상태를 확인하세요.
ERROR 2025-09-01 09:26:12,100 rfid_reader read_card_uid 리더기를 찾을 수 없습니다. 연결 상태를 확인하세요.
ERROR 2025-09-01 09:26:13,109 rfid_reader read_card_uid 리더기를 찾을 수 없습니다. 연결 상태를 확인하세요.
ERROR 2025-09-01 09:26:14,117 rfid_reader read_card_uid 리더기를 찾을 수 없습니다. 연결 상태를 확인하세요.
ERROR 2025-09-01 09:26:15,126 rfid_reader read_card_uid 리더기를 찾을 수 없습니다. 연결 상태를 확인하세요.
ERROR 2025-09-01 09:26:16,136 rfid_reader read_card_uid 리더기를 찾을 수 없습니다. 연결 상태를 확인하세요.
ERROR 2025-09-01 09:26:17,145 rfid_reader read_card_uid 리더기를 찾을 수 없습니다. 연결 상태를 확인하세요.
ERROR 2025-09-01 09:26:18,152 rfid_reader read_card_uid 리더기를 찾을 수 없습니다. 연결 상태를 확인하세요.
ERROR 2025-09-01 09:26:19,161 rfid_reader read_card_uid 리더기를 찾을 수 없습니다. 연결 상태를 확인하세요.
ERROR 2025-09-01 09:26:20,169 rfid_reader read_card_uid 리더기를 찾을 수 없습니다. 연결 상태를 확인하세요.
ERROR 2025-09-01 09:26:21,177 rfid_reader read_card_uid 리더기를 찾을 수 없습니다. 연결 상태를 확인하세요.
ERROR 2025-09-01 09:26:22,186 rfid_reader read_card_uid 리더기를 찾을 수 없습니다. 연결 상태를 확인하세요.
ERROR 2025-09-01 09:26:23,195 rfid_reader read_card_uid 리더기를 찾을 수 없습니다. 연결 상태를 확인하세요.
ERROR 2025-09-01 09:26:24,206 rfid_reader read_card_uid 리더기를 찾을 수 없습니다. 연결 상태를 확인하세요.
ERROR 2025-09-01 09:26:25,215 rfid_reader read_card_uid 리더기를 찾을 수 없습니다. 연결 상태를 확인하세요.
ERROR 2025-09-01 09:26:26,223 rfid_reader read_card_uid 리더기를 찾을 수 없습니다. 연결 상태를 확인하세요.
ERROR 2025-09-01 09:26:27,232 rfid_reader read_card_uid 리더기를 찾을 수 없습니다. 연결 상태를 확인하세요.
ERROR 2025-09-01 09:26:28,241 rfid_reader read_card_uid 리더기를 찾을 수 없습니다. 연결 상태를 확인하세요.
ERROR 2025-09-01 09:26:29,249 rfid_reader read_card_uid 리더기를 찾을 수 없습니다. 연결 상태를 확인하세요.
ERROR 2025-09-01 09:26:30,259 rfid_reader read_card_uid 리더기를 찾을 수 없습니다. 연결 상태를 확인하세요.
ERROR 2025-09-01 09:26:31,268 rfid_reader read_card_uid 리더기를 찾을 수 없습니다. 연결 상태를 확인하세요.
ERROR 2025-09-01 09:26:32,277 rfid_reader read_card_uid 리더기를 찾을 수 없습니다. 연결 상태를 확인하세요.
ERROR 2025-09-01 09:26:33,285 rfid_reader read_card_uid 리더기를 찾을 수 없습니다. 연결 상태를 확인하세요.
ERROR 2025-09-01 09:26:34,294 rfid_reader read_card_uid 리더기를 찾을 수 없습니다. 연결 상태를 확인하세요.
ERROR 2025-09-01 09:26:35,302 rfid_reader read_card_uid 리더기를 찾을 수 없습니다. 연결 상태를 확인하세요.
ERROR 2025-09-01 09:26:36,310 rfid_reader read_card_uid 리더기를 찾을 수 없습니다. 연결 상태를 확인하세요.
ERROR 2025-09-01 09:26:37,319 rfid_reader read_card_uid 리더기를 찾을 수 없습니다. 연결 상태를 확인하세요.
ERROR 2025-09-01 09:26:38,328 rfid_reader read_card_uid 리더기를 찾을 수 없습니다. 연결 상태를 확인하세요.
ERROR 2025-09-01 09:26:39,337 rfid_reader read_card_uid 리더기를 찾을 수 없습니다. 연결 상태를 확인하세요.
ERROR 2025-09-01 09:26:40,346 rfid_reader read_card_uid 리더기를 찾을 수 없습니다. 연결 상태를 확인하세요.
ERROR 2025-09-01 09:26:41,393 rfid_reader read_card_uid 리더기를 찾을 수 없습니다. 연결 상태를 확인하세요.
ERROR 2025-09-01 09:26:42,401 rfid_reader read_card_uid 리더기를 찾을 수 없습니다. 연결 상태를 확인하세요.
ERROR 2025-09-01 09:33:27,690 rfid_reader read_card_uid 리더기를 찾을 수 없습니다. 연결 상태를 확인하세요.
ERROR 2025-09-01 09:38:41,054 rfid_reader read_card_uid 리더기를 찾을 수 없습니다. 연결 상태를 확인하세요.
ERROR 2025-09-01 09:38:42,101 rfid_reader read_card_uid 리더기를 찾을 수 없습니다. 연결 상태를 확인하세요.
ERROR 2025-09-01 09:41:40,270 rfid_reader read_card_uid 리더기를 찾을 수 없습니다. 연결 상태를 확인하세요.
ERROR 2025-09-01 09:41:41,360 rfid_reader read_card_uid 리더기를 찾을 수 없습니다. 연결 상태를 확인하세요.
ERROR 2025-09-01 09:41:42,365 rfid_reader read_card_uid 리더기를 찾을 수 없습니다. 연결 상태를 확인하세요.
ERROR 2025-09-01 09:41:43,370 rfid_reader read_card_uid 리더기를 찾을 수 없습니다. 연결 상태를 확인하세요.
ERROR 2025-09-01 09:41:44,378 rfid_reader read_card_uid 리더기를 찾을 수 없습니다. 연결 상태를 확인하세요.
ERROR 2025-09-01 09:41:45,382 rfid_reader read_card_uid 리더기를 찾을 수 없습니다. 연결 상태를 확인하세요.
ERROR 2025-09-01 09:41:46,387 rfid_reader read_card_uid 리더기를 찾을 수 없습니다. 연결 상태를 확인하세요.
ERROR 2025-09-01 09:41:47,394 rfid_reader read_card_uid 리더기를 찾을 수 없습니다. 연결 상태를 확인하세요.
ERROR 2025-09-01 09:41:48,397 rfid_reader read_card_uid 리더기를 찾을 수 없습니다. 연결 상태를 확인하세요.
ERROR 2025-09-01 09:41:49,402 rfid_reader read_card_uid 리더기를 찾을 수 없습니다. 연결 상태를 확인하세요.
ERROR 2025-09-01 09:41:50,409 rfid_reader read_card_uid 리더기를 찾을 수 없습니다. 연결 상태를 확인하세요.
ERROR 2025-09-01 09:41:51,414 rfid_reader read_card_uid 리더기를 찾을 수 없습니다. 연결 상태를 확인하세요.
ERROR 2025-09-01 09:41:52,418 rfid_reader read_card_uid 리더기를 찾을 수 없습니다. 연결 상태를 확인하세요.
ERROR 2025-09-01 09:41:53,425 rfid_reader read_card_uid 리더기를 찾을 수 없습니다. 연결 상태를 확인하세요.
ERROR 2025-09-01 09:41:54,430 rfid_reader read_card_uid 리더기를 찾을 수 없습니다. 연결 상태를 확인하세요.
ERROR 2025-09-01 09:41:55,436 rfid_reader read_card_uid 리더기를 찾을 수 없습니다. 연결 상태를 확인하세요.
ERROR 2025-09-01 09:41:56,445 rfid_reader read_card_uid 리더기를 찾을 수 없습니다. 연결 상태를 확인하세요.
ERROR 2025-09-01 09:41:57,450 rfid_reader read_card_uid 리더기를 찾을 수 없습니다. 연결 상태를 확인하세요.
ERROR 2025-09-01 09:41:58,460 rfid_reader read_card_uid 리더기를 찾을 수 없습니다. 연결 상태를 확인하세요.
ERROR 2025-09-01 09:41:59,465 rfid_reader read_card_uid 리더기를 찾을 수 없습니다. 연결 상태를 확인하세요.
ERROR 2025-09-01 09:42:00,470 rfid_reader read_card_uid 리더기를 찾을 수 없습니다. 연결 상태를 확인하세요.
ERROR 2025-09-01 09:42:01,476 rfid_reader read_card_uid 리더기를 찾을 수 없습니다. 연결 상태를 확인하세요.
ERROR 2025-09-01 09:42:02,481 rfid_reader read_card_uid 리더기를 찾을 수 없습니다. 연결 상태를 확인하세요.
ERROR 2025-09-01 09:42:03,485 rfid_reader read_card_uid 리더기를 찾을 수 없습니다. 연결 상태를 확인하세요.
ERROR 2025-09-01 09:42:04,493 rfid_reader read_card_uid 리더기를 찾을 수 없습니다. 연결 상태를 확인하세요.
ERROR 2025-09-01 09:42:05,498 rfid_reader read_card_uid 리더기를 찾을 수 없습니다. 연결 상태를 확인하세요.
ERROR 2025-09-01 09:42:06,502 rfid_reader read_card_uid 리더기를 찾을 수 없습니다. 연결 상태를 확인하세요.
ERROR 2025-09-01 09:42:07,511 rfid_reader read_card_uid 리더기를 찾을 수 없습니다. 연결 상태를 확인하세요.
ERROR 2025-09-01 09:42:08,516 rfid_reader read_card_uid 리더기를 찾을 수 없습니다. 연결 상태를 확인하세요.
ERROR 2025-09-01 09:42:09,520 rfid_reader read_card_uid 리더기를 찾을 수 없습니다. 연결 상태를 확인하세요.
ERROR 2025-09-01 09:42:10,525 rfid_reader read_card_uid 리더기를 찾을 수 없습니다. 연결 상태를 확인하세요.
ERROR 2025-09-01 09:42:11,529 rfid_reader read_card_uid 리더기를 찾을 수 없습니다. 연결 상태를 확인하세요.
ERROR 2025-09-01 09:42:12,534 rfid_reader read_card_uid 리더기를 찾을 수 없습니다. 연결 상태를 확인하세요.
ERROR 2025-09-01 09:42:13,542 rfid_reader read_card_uid 리더기를 찾을 수 없습니다. 연결 상태를 확인하세요.
ERROR 2025-09-01 09:42:14,550 rfid_reader read_card_uid 리더기를 찾을 수 없습니다. 연결 상태를 확인하세요.
ERROR 2025-09-01 09:42:15,556 rfid_reader read_card_uid 리더기를 찾을 수 없습니다. 연결 상태를 확인하세요.
ERROR 2025-09-01 09:42:16,565 rfid_reader read_card_uid 리더기를 찾을 수 없습니다. 연결 상태를 확인하세요.
ERROR 2025-09-01 09:42:17,569 rfid_reader read_card_uid 리더기를 찾을 수 없습니다. 연결 상태를 확인하세요.
ERROR 2025-09-01 09:42:18,577 rfid_reader read_card_uid 리더기를 찾을 수 없습니다. 연결 상태를 확인하세요.
ERROR 2025-09-01 09:42:19,583 rfid_reader read_card_uid 리더기를 찾을 수 없습니다. 연결 상태를 확인하세요.
ERROR 2025-09-01 09:42:20,587 rfid_reader read_card_uid 리더기를 찾을 수 없습니다. 연결 상태를 확인하세요.
ERROR 2025-09-01 09:42:21,593 rfid_reader read_card_uid 리더기를 찾을 수 없습니다. 연결 상태를 확인하세요.
ERROR 2025-09-01 09:42:22,598 rfid_reader read_card_uid 리더기를 찾을 수 없습니다. 연결 상태를 확인하세요.
ERROR 2025-09-01 09:42:23,602 rfid_reader read_card_uid 리더기를 찾을 수 없습니다. 연결 상태를 확인하세요.
ERROR 2025-09-01 09:42:24,609 rfid_reader read_card_uid 리더기를 찾을 수 없습니다. 연결 상태를 확인하세요.
ERROR 2025-09-01 09:42:25,614 rfid_reader read_card_uid 리더기를 찾을 수 없습니다. 연결 상태를 확인하세요.
ERROR 2025-09-01 09:42:26,618 rfid_reader read_card_uid 리더기를 찾을 수 없습니다. 연결 상태를 확인하세요.
ERROR 2025-09-01 09:42:27,626 rfid_reader read_card_uid 리더기를 찾을 수 없습니다. 연결 상태를 확인하세요.
ERROR 2025-09-01 09:42:28,630 rfid_reader read_card_uid 리더기를 찾을 수 없습니다. 연결 상태를 확인하세요.
ERROR 2025-09-01 09:42:29,634 rfid_reader read_card_uid 리더기를 찾을 수 없습니다. 연결 상태를 확인하세요.
ERROR 2025-09-01 09:42:30,643 rfid_reader read_card_uid 리더기를 찾을 수 없습니다. 연결 상태를 확인하세요.
ERROR 2025-09-01 09:42:31,649 rfid_reader read_card_uid 리더기를 찾을 수 없습니다. 연결 상태를 확인하세요.
ERROR 2025-09-01 09:42:32,657 rfid_reader read_card_uid 리더기를 찾을 수 없습니다. 연결 상태를 확인하세요.
ERROR 2025-09-01 09:42:33,662 rfid_reader read_card_uid 리더기를 찾을 수 없습니다. 연결 상태를 확인하세요.
ERROR 2025-09-01 09:42:34,668 rfid_reader read_card_uid 리더기를 찾을 수 없습니다. 연결 상태를 확인하세요.
ERROR 2025-09-01 09:42:35,681 rfid_reader read_card_uid 리더기를 찾을 수 없습니다. 연결 상태를 확인하세요.
ERROR 2025-09-01 09:42:36,690 rfid_reader read_card_uid 리더기를 찾을 수 없습니다. 연결 상태를 확인하세요.
ERROR 2025-09-01 09:42:37,694 rfid_reader read_card_uid 리더기를 찾을 수 없습니다. 연결 상태를 확인하세요.
ERROR 2025-09-01 09:42:38,699 rfid_reader read_card_uid 리더기를 찾을 수 없습니다. 연결 상태를 확인하세요.
ERROR 2025-09-01 09:42:39,703 rfid_reader read_card_uid 리더기를 찾을 수 없습니다. 연결 상태를 확인하세요.
ERROR 2025-09-01 09:44:50,421 rfid_reader read_card_uid 리더기를 찾을 수 없습니다. 연결 상태를 확인하세요.
ERROR 2025-09-01 09:44:51,477 rfid_reader read_card_uid 리더기를 찾을 수 없습니다. 연결 상태를 확인하세요.
ERROR 2025-09-01 09:44:52,531 rfid_reader read_card_uid 리더기를 찾을 수 없습니다. 연결 상태를 확인하세요.
ERROR 2025-09-01 09:44:53,598 rfid_reader read_card_uid 리더기를 찾을 수 없습니다. 연결 상태를 확인하세요.
ERROR 2025-09-01 09:44:54,652 rfid_reader read_card_uid 리더기를 찾을 수 없습니다. 연결 상태를 확인하세요.
ERROR 2025-09-01 09:44:55,717 rfid_reader read_card_uid 리더기를 찾을 수 없습니다. 연결 상태를 확인하세요.
ERROR 2025-09-01 09:44:56,776 rfid_reader read_card_uid 리더기를 찾을 수 없습니다. 연결 상태를 확인하세요.
ERROR 2025-09-01 09:44:57,826 rfid_reader read_card_uid 리더기를 찾을 수 없습니다. 연결 상태를 확인하세요.
ERROR 2025-09-01 09:44:58,885 rfid_reader read_card_uid 리더기를 찾을 수 없습니다. 연결 상태를 확인하세요.
ERROR 2025-09-01 09:45:00,107 rfid_reader read_card_uid 리더기를 찾을 수 없습니다. 연결 상태를 확인하세요.
ERROR 2025-09-01 09:45:01,161 rfid_reader read_card_uid 리더기를 찾을 수 없습니다. 연결 상태를 확인하세요.
ERROR 2025-09-01 09:45:02,228 rfid_reader read_card_uid 리더기를 찾을 수 없습니다. 연결 상태를 확인하세요.
ERROR 2025-09-01 09:45:03,282 rfid_reader read_card_uid 리더기를 찾을 수 없습니다. 연결 상태를 확인하세요.
ERROR 2025-09-01 09:45:04,349 rfid_reader read_card_uid 리더기를 찾을 수 없습니다. 연결 상태를 확인하세요.
ERROR 2025-09-01 09:45:05,402 rfid_reader read_card_uid 리더기를 찾을 수 없습니다. 연결 상태를 확인하세요.
ERROR 2025-09-01 09:45:06,458 rfid_reader read_card_uid 리더기를 찾을 수 없습니다. 연결 상태를 확인하세요.
ERROR 2025-09-01 10:34:10,521 user_management check_user 사용자를 찾을 수 없음: UID 04 B7 77 6A 76 13 90
ERROR 2025-09-01 10:34:10,947 user_management check_user 사용자를 찾을 수 없음: UID 04 B7 77 6A 76 13 90
ERROR 2025-09-01 10:34:17,679 user_management check_user 사용자를 찾을 수 없음: UID 04 B7 77 6A 76 13 90
ERROR 2025-09-01 10:34:18,099 user_management check_user 사용자를 찾을 수 없음: UID 04 B7 77 6A 76 13 90
ERROR 2025-09-01 10:34:21,249 user_management check_user 사용자를 찾을 수 없음: UID 04 B7 77 6A 76 13 90
ERROR 2025-09-01 10:35:28,057 user_management check_user 사용자를 찾을 수 없음: UID 04 B7 77 6A 76 13 90
ERROR 2025-09-01 14:45:10,233 user_management check_user 사용자를 찾을 수 없음: UID 04 F8 4B 6A 76 13 90
ERROR 2025-09-02 07:51:22,302 user_management check_user 사용자를 찾을 수 없음: UID A4 CF BA 0E
ERROR 2025-09-02 07:51:58,498 user_management check_user 사용자를 찾을 수 없음: UID A4 CF BA 0E
ERROR 2025-09-02 07:55:38,855 user_management check_user 사용자를 찾을 수 없음: UID A4 CF BA 0E
ERROR 2025-09-02 07:55:42,002 user_management check_user 사용자를 찾을 수 없음: UID A4 CF BA 0E
ERROR 2025-09-02 07:57:20,207 user_management check_user 사용자를 찾을 수 없음: UID A4 CF BA 0E
ERROR 2025-09-02 07:57:23,356 user_management check_user 사용자를 찾을 수 없음: UID A4 CF BA 0E
ERROR 2025-09-02 07:57:34,508 user_management check_user 사용자를 찾을 수 없음: UID A4 CF BA 0E
ERROR 2025-09-02 07:57:37,657 user_management check_user 사용자를 찾을 수 없음: UID A4 CF BA 0E
ERROR 2025-09-02 07:57:46,822 user_management check_user 사용자를 찾을 수 없음: UID A4 CF BA 0E
ERROR 2025-09-02 07:57:49,973 user_management check_user 사용자를 찾을 수 없음: UID A4 CF BA 0E
ERROR 2025-09-02 07:58:08,140 user_management check_user 사용자를 찾을 수 없음: UID A4 CF BA 0E
ERROR 2025-09-02 07:58:11,288 user_management check_user 사용자를 찾을 수 없음: UID A4 CF BA 0E
ERROR 2025-09-02 07:58:14,441 user_management check_user 사용자를 찾을 수 없음: UID A4 CF BA 0E
ERROR 2025-09-02 07:58:17,593 user_management check_user 사용자를 찾을 수 없음: UID A4 CF BA 0E
ERROR 2025-09-02 07:58:20,743 user_management check_user 사용자를 찾을 수 없음: UID A4 CF BA 0E
ERROR 2025-09-02 08:18:07,566 user_management check_user 사용자를 찾을 수 없음: UID A4 CF BA 0E
ERROR 2025-09-02 08:18:10,713 user_management check_user 사용자를 찾을 수 없음: UID A4 CF BA 0E
ERROR 2025-09-02 10:09:43,742 weight update_weight 서버 오류 발생: 유효한 데이터가 수신되지 않았습니다.(저울) (Status Code: 484)
ERROR 2025-09-02 10:22:36,510 weight update_weight 서버 오류 발생: 유효한 데이터가 수신되지 않았습니다.(저울) (Status Code: 484)
